Workbook

Sheet Cover
B2: Marine Corps Basic Facility Requirement (BFR) Generator
B3: FC 2-000-05N · Series 100 — Operational & Training Facilities · MCIPAC · Okinawa, Japan
B5: Project Information
C6: Project Title
C7: Installation | D7: Camp Foster, Okinawa, JP
C8: Building No.
C9: Region / Command | D9: MCIPAC — 3d MLG / CLR-3
C10: Tenant Unit (Activity) | D10: CLB-4 (UIC M29110)
C11: UIC / RUC | D11: M29110 (CLB-4 — composite of M29111/12/13/14)
C12: Planner (Name / Office)
C13: Date Prepared
C14: FY (Program Year)
B17: How to Use This Workbook
B18: 1. Fill in Project Information above.
B19: 2. Go to the Personnel sheet and enter unit personnel loading (officers, enlisted, civilians, contractors). The Authorized Strength Report (ASR) / TFSD projection is the official source per FC 2-000-05N §61010-3.
B20: 3. Open the BFR Calculator. Each row references a Series 100 Category Code (CCN). Enter quantity drivers (e.g., # of vehicles by type, # of student stations, # of weapons). Required SF / SY / EA is computed automatically using the planning factors stored in the CCN Library.
B21: 4. Open the Inventory sheet and enter existing iNFADS assets for each CCN. Surplus / Deficit is computed automatically.
B22: 5. Open the Okinawa Adjustments sheet. Confirm the MILCON Area Cost Factor (Okinawa Navy ACF), ATFP setbacks (UFC 4-010-01), seismic/typhoon premiums, and any host-nation siting constraints.
B23: 6. Open the BFR Summary. This is the print-ready output: total requirements, deficits, programmed cost, and justification narrative for the DD Form 1391 attachment.
B24: 7. Cell colors: cream = INPUT (you fill in), light teal = CALCULATED, light green = OUTPUT / TOTAL.
B25: 8. Do not overwrite formula cells. To add a CCN that is not listed, copy a row in the BFR Calculator and add the CCN code from the CCN Library.
B26: DATA QUALITY: Treat all TFSMS / TO&E exports as DRAFT. Reconcile every UIC row on TFSMS_Loading against the current Authorized Strength Report (ASR) before relying on BFR outputs. Unreconciled rows are flagged on the Personnel sheet header.
B28: Cell Color Legend
D29: INPUT — user-editable
D30: CALCULATED — formula
D31: OUTPUT / TOTAL
D32: REVIEW REQUIRED
B34: Authoritative References
B35: • FC 2-000-05N — Facility Planning for Navy and Marine Corps Shore Installations (formerly NAVFAC P-80) — Series 100, dated 11 Feb 2026
B36: • MCO 11000.12 — Real Property Facilities Manual, Facilities Planning and Programming
B37: • MCO P11000.5x — Real Property Facilities Manual series
B38: • UFC 4-010-01 — DoD Minimum Antiterrorism Standards for Buildings
B39: • UFC 4-020-01 — DoD Security Engineering Facilities Planning Manual
B40: • UFS 3-701-01 — DoD Facilities Pricing Guide (ACFs in Table 4-1)
B41: • UFS 3-730-01 — Programming Cost Estimates for Military Construction
B42: • DoD Real Property Classification System (RPCS) / iNFADS CCN module

Sheet TFSMS_Loading
B2: TFSMS / TO&E Loading by Sub-Unit (UIC)
B3: Paste RecapMCC chargeable + non-chargeable counts. Roll-up populates the Personnel sheet automatically.
B5: DATA QUALITY NOTICE — TFSMS exports are 'Published Average' snapshots and may include stale T/O lines, mis-coded FAP/collateral billets, or units detached from the parent UIC. Reconcile every row against the current Authorized Strength Report (ASR) and on-hand strength before treating these numbers as authoritative for the BFR.
B6: Per-UIC Loading
D7: Marine Active | F7: Navy Active | H7: Other Service | J7: Reserve / FAP
D8: Off | E8: Enl | F8: Off | G8: Enl | H8: Off | I8: Enl | J8: Off | K8: Enl
B9: M29111 | C9: HQ Co CLB-4 / CLR-3 / 3d MLG | D9: 12 | E9: 60 | F9: 2 | G9: 11 | H9: 0 | I9: 0 | J9: 0 | K9: 0 | L9: 0 | M9: 0 | N9: 0 | O9: =SUM(D8:N8) | P9: 2026-02-25 | Q9: Pending | S9: TFSMS export 25 Feb 2026; HQ Co — verify Navy RP/Chaplain billets are still chargeable to CLB-4 vs. detached.
B10: M29112 | C10: CLC A CLB-4 / CLR-3 / 3d MLG | D10: 3 | E10: 55 | F10: 0 | G10: 0 | H10: 0 | I10: 0 | J10: 0 | K10: 0 | L10: 0 | M10: 0 | N10: 0 | O10: =SUM(D9:N9) | P10: 2026-02-25 | Q10: Pending | S10: TFSMS export 25 Feb 2026; CLC A — confirm operations chief billet (3537/0477) is filled per current ASR.
B11: M29113 | C11: CLC B CLB-4 / CLR-3 / 3d MLG | D11: 3 | E11: 55 | F11: 0 | G11: 0 | H11: 0 | I11: 0 | J11: 0 | K11: 0 | L11: 0 | M11: 0 | N11: 0 | O11: =SUM(D10:N10) | P11: 2026-02-25 | Q11: Pending | S11: TFSMS export 25 Feb 2026; CLC B — verify it is identical to CLC A as published; reconcile against on-hand.
B12: M29114 | C12: GS Co CLB-4 / CLR-3 / 3d MLG | D12: 4 | E12: 79 | F12: 6 | G12: 17 | H12: 0 | I12: 0 | J12: 0 | K12: 0 | L12: 0 | M12: 0 | N12: 3 | O12: =SUM(D11:N11) | P12: 2026-02-25 | Q12: Pending | S12: TFSMS export 25 Feb 2026; GS Co — confirm 3 collateral-duty enlisted (K15) are not double-counted in chargeable.
D13: 0 | E13: 0 | F13: 0 | G13: 0 | H13: 0 | I13: 0 | J13: 0 | K13: 0 | L13: 0 | M13: 0 | N13: 0 | O13: =SUM(D12:N12)
D14: 0 | E14: 0 | F14: 0 | G14: 0 | H14: 0 | I14: 0 | J14: 0 | K14: 0 | L14: 0 | M14: 0 | N14: 0 | O14: =SUM(D13:N13)
D15: 0 | E15: 0 | F15: 0 | G15: 0 | H15: 0 | I15: 0 | J15: 0 | K15: 0 | L15: 0 | M15: 0 | N15: 0 | O15: =SUM(D14:N14)
D16: 0 | E16: 0 | F16: 0 | G16: 0 | H16: 0 | I16: 0 | J16: 0 | K16: 0 | L16: 0 | M16: 0 | N16: 0 | O16: =SUM(D15:N15)
B17: UNIT TOTAL (e.g., CLB-4) | D17: =SUM(D8:D15) | E17: =SUM(E8:E15) | F17: =SUM(F8:F15) | G17: =SUM(G8:G15) | H17: =SUM(H8:H15) | I17: =SUM(I8:I15) | J17: =SUM(J8:J15) | K17: =SUM(K8:K15) | ... O17: =SUM(O8:O15)
B19: Reconciliation Gate
B20: How to Populate This Sheet

Sheet Personnel
B2: Unit Personnel Loading
B3: Per FC 2-000-05N §61010-3 — Personnel loading must come from an official source (ASR / TFSD).
B4: Loading Source | C4: TFSMS | D4: =IF(TFSMS_UNRECONCILED>0,"⚠ "&TFSMS_UNRECONCILED&" TFSMS rows are NOT yet reconciled against the ASR — review before treating BFR outputs as authoritative.","TFSMS data marked reconciled or not in use.")
B5: Personnel by Category
B6: Group | C6: Category | D6: Officers | E6: Enlisted | F6: Civilians | G6: Contractors | H6: Total
B7: Headquarters / Command Element | C7: 2 | D7: 12 | E7: 2 | F7: 1 | G7: =SUM(C7:F7)
B8: Operations (S-3) / Line Companies | C8: 4 | D8: 120 | E8: 0 | F8: 0 | G8: =SUM(C8:F8)
B9: Intelligence (S-2) | C9: 1 | D9: 8 | E9: 1 | F9: 0 | G9: =SUM(C9:F9)
B10: Logistics (S-4) / Supply | C10: 2 | D10: 24 | E10: 3 | F10: 2 | G10: =SUM(C10:F10)
B11: Communications (S-6) | C11: 1 | D11: 14 | E11: 1 | F11: 1 | G11: =SUM(C11:F11)
B12: Maintenance / Motor T | C12: 1 | D12: 18 | E12: 0 | F12: 4 | G12: =SUM(C12:F12)
B13: Medical / Dental Section | C13: 1 | D13: 6 | E13: 2 | F13: 0 | G13: =SUM(C13:F13)
B14: Other / Attached | C14: 0 | D14: 0 | E14: 0 | F14: 0 | G14: =SUM(C14:F14)
B15: TOTAL UNIT PERSONNEL | C15: =SUM(C7:C14) | D15: =SUM(D7:D14) | E15: =SUM(E7:E14) | F15: =SUM(F7:F14) | G15: =SUM(G7:G14)
B18: Derived Loading Metrics
B19: Total Military Strength (Off + Enl) | C19: =C15+D15
B20: Personnel Loading (PN) for BFR (FC §61010-3) | C20: =G15 | D20: All military, civilian, and other personnel associated with the organization.
B23: Loading Source & Notes
B24: Authoritative source for personnel loading per FC 2-000-05N §61010-3: Authorized Strength Report (ASR) validated by Total Force Structure Division (TFSD) per MCO 11000.12. Tenant loading reports must be provided as a separate attachment for project-level BFRs.
B27: Effective Loading (used by BFR formulas)
B28: Officers (effective) | C28: =IF($C$4="TFSMS",TFSMS_MAR_OFF+TFSMS_NAV_OFF+TFSMS_OS_OFF+TFSMS_RES_OFF,C15)
B29: Enlisted (effective) | C29: =IF($C$4="TFSMS",TFSMS_MAR_ENL+TFSMS_NAV_ENL+TFSMS_OS_ENL+TFSMS_RES_ENL,D15)
B30: Civilians (effective) | C30: =IF($C$4="TFSMS",TFSMS_CIV,E15)
B31: Contractors (effective) | C31: =IF($C$4="TFSMS",TFSMS_CTR,F15)
B32: Total PN (effective) | C32: =IF($C$4="TFSMS",TFSMS_TOTAL,G15)
B33: Military Strength (effective) | C33: =IF($C$4="TFSMS",TFSMS_MAR_OFF+TFSMS_MAR_ENL+TFSMS_NAV_OFF+TFSMS_NAV_ENL+TFSMS_OS_OFF+TFSMS_OS_ENL+TFSMS_RES_OFF+TFSMS_RES_ENL,C15+D15)
B36: Sub-Unit Snapshot (from TFSMS_Loading)
B37: UIC | C37: Sub-Unit | D37: Mar Off | E37: Mar Enl | F37: Navy Off | G37: Navy Enl | H37: Civ | I37: Total PN
B38: =TFSMS_Loading!B8 | C38: =TFSMS_Loading!C8 | D38: =TFSMS_Loading!D8 | E38: =TFSMS_Loading!E8 | F38: =TFSMS_Loading!F8 | G38: =TFSMS_Loading!G8 | H38: =TFSMS_Loading!L8
B39: =TFSMS_Loading!B9 | C39: =TFSMS_Loading!C9 | D39: =TFSMS_Loading!D9 | E39: =TFSMS_Loading!E9 | F39: =TFSMS_Loading!F9 | G39: =TFSMS_Loading!G9 | H39: =TFSMS_Loading!L9
B40: =TFSMS_Loading!B10 | C40: =TFSMS_Loading!C10 | D40: =TFSMS_Loading!D10 | E40: =TFSMS_Loading!E10 | F40: =TFSMS_Loading!F10 | G40: =TFSMS_Loading!G10 | H40: =TFSMS_Loading!L10
B41: =TFSMS_Loading!B11 | C41: =TFSMS_Loading!C11 | D41: =TFSMS_Loading!D11 | E41: =TFSMS_Loading!E11 | F41: =TFSMS_Loading!F11 | G41: =TFSMS_Loading!G11 | H41: =TFSMS_Loading!L11

Sheet BFR_Calculator
B2: BFR Calculator — Series 100
B3: Required = Driver × Planning Factor × NTG. Enter quantities in the cream cells.
B5: Per-CCN Requirements
B6: CCN | C6: Facility Name | D6: UM | E6: Driver Qty | F6: Factor | G6: NTG | H6: Required | I6: Total Required (UM) | J6: Justification / Notes
B7: 143 10 | C7: =IFERROR(VLOOKUP(B7,CCN_TABLE,2,FALSE()),"") | D7: =IFERROR(VLOOKUP(B7,CCN_TABLE,3,FALSE()),"") | E7: 0 | G7: 1 | H7: =IFERROR(E7*F7*G7,0) | J7: Emergency Vehicle Garage — engineering analysis required.
B8: 143 11 | C8: =IFERROR(VLOOKUP(B8,CCN_TABLE,2,FALSE()),"") | D8: =IFERROR(VLOOKUP(B8,CCN_TABLE,3,FALSE()),"") | E8: 1 | F8: =BFR_Calculator!G33 | G8: 1.2 | H8: =IFERROR(E8*F8*G8,0) | J8: Operational Vehicle Garage — sum of all type allowances + 250 SF mech room.
B9: 143 12 | C9: =IFERROR(VLOOKUP(B9,CCN_TABLE,2,FALSE()),"") | D9: =IFERROR(VLOOKUP(B9,CCN_TABLE,3,FALSE()),"") | E9: 1 | F9: =BFR_Calculator!H33 | G9: 1 | H9: =IFERROR(E9*F9*G9,0) | J9: Operational Vehicle Laydown Area (SY).
B10: 143 24 | C10: =IFERROR(VLOOKUP(B10,CCN_TABLE,2,FALSE()),"") | D10: =IFERROR(VLOOKUP(B10,CCN_TABLE,3,FALSE()),"") | E10: 1 | F10: 7204 | G10: 1 | H10: =IFERROR(E10*F10*G10,0) | J10: Marine Corps EOD Facility — 7,000 GSF EOD bldg + 204 GSF Haz/Flam.
B11: 143 45 | C11: =IFERROR(VLOOKUP(B11,CCN_TABLE,2,FALSE()),"") | D11: =IFERROR(VLOOKUP(B11,CCN_TABLE,3,FALSE()),"") | E11: =PN_MIL | G11: 1 | H11: =IFERROR(E11*F11*G11,0) | J11: Armory — sized via Table 14345-1; engineering analysis if outside scope.
B12: 143 46 | C12: =IFERROR(VLOOKUP(B12,CCN_TABLE,2,FALSE()),"") | D12: =IFERROR(VLOOKUP(B12,CCN_TABLE,3,FALSE()),"") | E12: 0 | G12: 1 | H12: =IFERROR(E12*F12*G12,0) | J12: Marine Barracks — only if barracking is required.
B13: 171 10 | C13: =IFERROR(VLOOKUP(B13,CCN_TABLE,2,FALSE()),"") | D13: =IFERROR(VLOOKUP(B13,CCN_TABLE,3,FALSE()),"") | E13: 0 | F13: 45 | G13: 1.33 | H13: =IFERROR(E13*F13*G13,0) | J13: Academic Instruction — # of student stations × 45 GSF.
B14: 171 20 | C14: =IFERROR(VLOOKUP(B14,CCN_TABLE,2,FALSE()),"") | D14: =IFERROR(VLOOKUP(B14,CCN_TABLE,3,FALSE()),"") | E14: 0 | F14: 150 | G14: 1.25 | H14: =IFERROR(E14*F14*G14,0) | J14: Applied Instruction — # of student stations × 150 GSF.
B15: 171 50 | C15: =IFERROR(VLOOKUP(B15,CCN_TABLE,2,FALSE()),"") | D15: =IFERROR(VLOOKUP(B15,CCN_TABLE,3,FALSE()),"") | E15: 0 | G15: 1 | H15: =IFERROR(E15*F15*G15,0) | J15: Indoor Small Arms Range — engineering analysis.
B16: 173 10 | C16: =IFERROR(VLOOKUP(B16,CCN_TABLE,2,FALSE()),"") | D16: =IFERROR(VLOOKUP(B16,CCN_TABLE,3,FALSE()),"") | E16: 0 | G16: 1 | H16: =IFERROR(E16*F16*G16,0) | J16: Range Operations Building — engineering analysis.
B17: 173 11 | C17: =IFERROR(VLOOKUP(B17,CCN_TABLE,2,FALSE()),"") | D17: =IFERROR(VLOOKUP(B17,CCN_TABLE,3,FALSE()),"") | E17: 0 | G17: 1 | H17: =IFERROR(E17*F17*G17,0) | J17: Range Support Building — engineering analysis.
B18: 179 60 | C18: =IFERROR(VLOOKUP(B18,CCN_TABLE,2,FALSE()),"") | D18: =IFERROR(VLOOKUP(B18,CCN_TABLE,3,FALSE()),"") | E18: =PN_TOTAL | F18: =1/125 | G18: 1 | H18: =IFERROR(E18*F18*G18,0) | J18: Parade & Drill Field — 1 AC per 125 personnel.
B19: 179 91 | C19: =IFERROR(VLOOKUP(B19,CCN_TABLE,2,FALSE()),"") | D19: =IFERROR(VLOOKUP(B19,CCN_TABLE,3,FALSE()),"") | E19: 0 | F19: 1 | G19: 1 | H19: =IFERROR(E19*F19*G19,0) | J19: Confidence Course — 1 EA per complete course.
B20: 179 92 | C20: =IFERROR(VLOOKUP(B20,CCN_TABLE,2,FALSE()),"") | D20: =IFERROR(VLOOKUP(B20,CCN_TABLE,3,FALSE()),"") | E20: 0 | G20: 1 | H20: =IFERROR(E20*F20*G20,0) | J20: Obstacle Course — case-by-case engineering analysis.
B24: Vehicle Sub-Schedule (drives 143 11 Garage SF and 143 12 Laydown SY)
B25: Type | C25: Description | D25: # Vehicles | E25: Garage NSF/EA | F25: Laydown GSY/EA | G25: Garage NSF | H25: Laydown GSY
B26: A | C26: Sedan / light truck | D26: 0 | E26: 108 | F26: 19 | G26: =D26*E26 | H26: =D26*F26
B27: B | C27: Pickup / 4-pass van | D27: 0 | E27: 180 | F27: 29 | G27: =D27*E27 | H27: =D27*F27
B28: C | C28: Cargo / shop van / 7-ton | D28: 0 | E28: 288 | F28: 42 | G28: =D28*E28 | H28: =D28*F28
B29: D | C29: Bus / box truck | D29: 0 | E29: 420 | F29: 57 | G29: =D29*E29 | H29: =D29*F29
B30: E | C30: Tractor + trailer / wrecker | D30: 0 | E30: 588 | F30: 71 | G30: =D30*E30 | H30: =D30*F30
B31: F | C31: HEMTT / heavy wrecker | D31: 0 | E31: 720 | F31: 85 | G31: =D31*E31 | H31: =D31*F31
B32: G | C32: Oversize / specialty | D32: 0 | E32: 888 | F32: 99 | G32: =D32*E32 | H32: =D32*F32
B33: TOTAL | E33: + 250 SF mech room (143 11) | G33: =IF(SUM(G26:G32)=0,0,SUM(G26:G32)+250) | H33: =SUM(H26:H32)

Sheet Inventory
B2: Existing Inventory & Deficit Analysis
B3: Compare iNFADS / RPI assets against the calculated BFR. Surplus (+) / Deficit (-).
B5: Inventory by CCN
B6: CCN | C6: Facility Name | D6: UM | E6: Required | F6: Existing (iNFADS) | G6: Adequate | H6: Inadequate | I6: Deficit (-) / Surplus (+) | J6: Recommended Action
B7: 143 10 | C7: =IFERROR(VLOOKUP(B7,CCN_TABLE,2,FALSE()),"") | D7: =IFERROR(VLOOKUP(B7,CCN_TABLE,3,FALSE()),"") | E7: =IF(BFR_Calculator!I7="",BFR_Calculator!H7,BFR_Calculator!I7) | F7: =G7+H7 | G7: 0 | H7: 0 | I7: =G7-E7 | J7: =IF(I7<0,"NEW or RENOVATE — deficit of "&TEXT(ABS(I7),"#,##0")&" "&D7,IF(H7>0,"REHAB — inadequate assets exist","NO ACTION — adequate"))
B8: 143 11 | C8: =IFERROR(VLOOKUP(B8,CCN_TABLE,2,FALSE()),"") | D8: =IFERROR(VLOOKUP(B8,CCN_TABLE,3,FALSE()),"") | E8: =IF(BFR_Calculator!I8="",BFR_Calculator!H8,BFR_Calculator!I8) | F8: =G8+H8 | G8: 0 | H8: 0 | I8: =G8-E8 | J8: =IF(I8<0,"NEW or RENOVATE — deficit of "&TEXT(ABS(I8),"#,##0")&" "&D8,IF(H8>0,"REHAB — inadequate assets exist","NO ACTION — adequate"))
B9: 143 12 | C9: =IFERROR(VLOOKUP(B9,CCN_TABLE,2,FALSE()),"") | D9: =IFERROR(VLOOKUP(B9,CCN_TABLE,3,FALSE()),"") | E9: =IF(BFR_Calculator!I9="",BFR_Calculator!H9,BFR_Calculator!I9) | F9: =G9+H9 | G9: 0 | H9: 0 | I9: =G9-E9 | J9: =IF(I9<0,"NEW or RENOVATE — deficit of "&TEXT(ABS(I9),"#,##0")&" "&D9,IF(H9>0,"REHAB — inadequate assets exist","NO ACTION — adequate"))
B10: 143 24 | C10: =IFERROR(VLOOKUP(B10,CCN_TABLE,2,FALSE()),"") | D10: =IFERROR(VLOOKUP(B10,CCN_TABLE,3,FALSE()),"") | E10: =IF(BFR_Calculator!I10="",BFR_Calculator!H10,BFR_Calculator!I10) | F10: =G10+H10 | G10: 0 | H10: 0 | I10: =G10-E10 | J10: =IF(I10<0,"NEW or RENOVATE — deficit of "&TEXT(ABS(I10),"#,##0")&" "&D10,IF(H10>0,"REHAB — inadequate assets exist","NO ACTION — adequate"))
B11: 143 45 | C11: =IFERROR(VLOOKUP(B11,CCN_TABLE,2,FALSE()),"") | D11: =IFERROR(VLOOKUP(B11,CCN_TABLE,3,FALSE()),"") | E11: =IF(BFR_Calculator!I11="",BFR_Calculator!H11,BFR_Calculator!I11) | F11: =G11+H11 | G11: 0 | H11: 0 | I11: =G11-E11 | J11: =IF(I11<0,"NEW or RENOVATE — deficit of "&TEXT(ABS(I11),"#,##0")&" "&D11,IF(H11>0,"REHAB — inadequate assets exist","NO ACTION — adequate"))
B12: 143 46 | C12: =IFERROR(VLOOKUP(B12,CCN_TABLE,2,FALSE()),"") | D12: =IFERROR(VLOOKUP(B12,CCN_TABLE,3,FALSE()),"") | E12: =IF(BFR_Calculator!I12="",BFR_Calculator!H12,BFR_Calculator!I12) | F12: =G12+H12 | G12: 0 | H12: 0 | I12: =G12-E12 | J12: =IF(I12<0,"NEW or RENOVATE — deficit of "&TEXT(ABS(I12),"#,##0")&" "&D12,IF(H12>0,"REHAB — inadequate assets exist","NO ACTION — adequate"))
B13: 171 10 | C13: =IFERROR(VLOOKUP(B13,CCN_TABLE,2,FALSE()),"") | D13: =IFERROR(VLOOKUP(B13,CCN_TABLE,3,FALSE()),"") | E13: =IF(BFR_Calculator!I13="",BFR_Calculator!H13,BFR_Calculator!I13) | F13: =G13+H13 | G13: 0 | H13: 0 | I13: =G13-E13 | J13: =IF(I13<0,"NEW or RENOVATE — deficit of "&TEXT(ABS(I13),"#,##0")&" "&D13,IF(H13>0,"REHAB — inadequate assets exist","NO ACTION — adequate"))
B14: 171 20 | C14: =IFERROR(VLOOKUP(B14,CCN_TABLE,2,FALSE()),"") | D14: =IFERROR(VLOOKUP(B14,CCN_TABLE,3,FALSE()),"") | E14: =IF(BFR_Calculator!I14="",BFR_Calculator!H14,BFR_Calculator!I14) | F14: =G14+H14 | G14: 0 | H14: 0 | I14: =G14-E14 | J14: =IF(I14<0,"NEW or RENOVATE — deficit of "&TEXT(ABS(I14),"#,##0")&" "&D14,IF(H14>0,"REHAB — inadequate assets exist","NO ACTION — adequate"))
B15: 171 50 | C15: =IFERROR(VLOOKUP(B15,CCN_TABLE,2,FALSE()),"") | D15: =IFERROR(VLOOKUP(B15,CCN_TABLE,3,FALSE()),"") | E15: =IF(BFR_Calculator!I15="",BFR_Calculator!H15,BFR_Calculator!I15) | F15: =G15+H15 | G15: 0 | H15: 0 | I15: =G15-E15 | J15: =IF(I15<0,"NEW or RENOVATE — deficit of "&TEXT(ABS(I15),"#,##0")&" "&D15,IF(H15>0,"REHAB — inadequate assets exist","NO ACTION — adequate"))
B16: 173 10 | C16: =IFERROR(VLOOKUP(B16,CCN_TABLE,2,FALSE()),"") | D16: =IFERROR(VLOOKUP(B16,CCN_TABLE,3,FALSE()),"") | E16: =IF(BFR_Calculator!I16="",BFR_Calculator!H16,BFR_Calculator!I16) | F16: =G16+H16 | G16: 0 | H16: 0 | I16: =G16-E16 | J16: =IF(I16<0,"NEW or RENOVATE — deficit of "&TEXT(ABS(I16),"#,##0")&" "&D16,IF(H16>0,"REHAB — inadequate assets exist","NO ACTION — adequate"))
B17: 173 11 | C17: =IFERROR(VLOOKUP(B17,CCN_TABLE,2,FALSE()),"") | D17: =IFERROR(VLOOKUP(B17,CCN_TABLE,3,FALSE()),"") | E17: =IF(BFR_Calculator!I17="",BFR_Calculator!H17,BFR_Calculator!I17) | F17: =G17+H17 | G17: 0 | H17: 0 | I17: =G17-E17 | J17: =IF(I17<0,"NEW or RENOVATE — deficit of "&TEXT(ABS(I17),"#,##0")&" "&D17,IF(H17>0,"REHAB — inadequate assets exist","NO ACTION — adequate"))
B18: 179 60 | C18: =IFERROR(VLOOKUP(B18,CCN_TABLE,2,FALSE()),"") | D18: =IFERROR(VLOOKUP(B18,CCN_TABLE,3,FALSE()),"") | E18: =IF(BFR_Calculator!I18="",BFR_Calculator!H18,BFR_Calculator!I18) | F18: =G18+H18 | G18: 0 | H18: 0 | I18: =G18-E18 | J18: =IF(I18<0,"NEW or RENOVATE — deficit of "&TEXT(ABS(I18),"#,##0")&" "&D18,IF(H18>0,"REHAB — inadequate assets exist","NO ACTION — adequate"))
... B20: 179 92 | C20: =IFERROR(VLOOKUP(B20,CCN_TABLE,2,FALSE()),"") | D20: =IFERROR(VLOOKUP(B20,CCN_TABLE,3,FALSE()),"") | E20: =IF(BFR_Calculator!I20="",BFR_Calculator!H20,BFR_Calculator!I20) | F20: =G20+H20 | G20: 0 | H20: 0 | I20: =G20-E20 | J20: =IF(I20<0,"NEW or RENOVATE — deficit of "&TEXT(ABS(I20),"#,##0")&" "&D20,IF(H20>0,"REHAB — inadequate assets exist","NO ACTION — adequate"))

Sheet Okinawa_Adj
B2: Okinawa / MCIPAC Adjustments
B3: Cost factors, ATFP, seismic/typhoon, and host-nation siting considerations.
B5: MILCON Cost Adjustment Factors (UFS 3-701-01 Table 4-1 / PAX Newsletter 3.2.1)
B6: Factor | C6: Value | D6: Notes
B7: MILCON Area Cost Factor (Okinawa, Navy) | C7: 2.34 | D7: PAX Newsletter 3.2.1; updated annually. Applies to MILCON construction cost.
B8: Sustainment Area Cost Factor (Okinawa) | C8: 2.1 | D8: Sustainment ACF — used for SR per UFS 3-701-01 §3-3.
B9: Programmed Escalation Factor | C9: 1 | D9: Set per program FY (UFS 3-730-01 Table 2). Update each FY.
B10: Contingency Factor | C10: 1.05 | D10: OCONUS contingency (UFS 3-730-01).
B11: SIOH (OCONUS — Japan) | C11: 1.065 | D11: Supervision, Inspection & Overhead.
B12: Planning & Design Factor | C12: 1.09 | D12: 1.09 standard / 1.13 medical (UFS 3-701-01 Eq 3-1).
B13: Historical / Cultural Factor | C13: 1 | D13: 1.05 if historic district.
B16: ATFP / Seismic / Siting Checklist
B17: Status | C17: Item | D17: Notes
B18: TBD | C18: UFC 4-010-01 minimum standoff distances met (controlled perimeter ≥18 ft; ≥12 ft within controlled perimeter).
B19: TBD | C19: UFC 4-020-01 Design Basis Threat (DBT) and Level Of Protection (LOP) determined for the project.
B20: TBD | C20: Mass notification system included (UFC 4-010-01 Standard 21).
B21: TBD | C21: Progressive collapse mitigation per UFC 4-023-03.
B22: TBD | C22: Seismic design: Japan-specific seismic premium applied (Okinawa is in a moderate seismic zone; coordinate w/ NAVFAC FEAD).
B23: TBD | C23: Typhoon / wind loading per ASCE 7 + Okinawa supplements (Vult ≈ 170 mph for design).
B24: TBD | C24: Host-nation FIP / Status of Forces Agreement coordination complete.
B25: TBD | C25: Encroachment Control Plan (ECP) and IMP land-use checked (MCO 11000.12).
B26: TBD | C26: Cultural / archaeological survey complete (NEPA + Japan PA).
B27: TBD | C27: Sustainability — LEED Silver minimum / DoD Federal High-Performance Sustainable Buildings.

Sheet BFR_Summary
B2: BFR Summary — Print-Ready
B3: Generated from Personnel + BFR Calculator + Inventory inputs.
B5: Project
B6: Project Title | C6: =PROJ_TITLE
B7: Installation | C7: =INSTALLATION
B8: Building No. | C8: =BLDG_NO
B9: Region / Command | C9: =REGION
B10: Tenant Unit | C10: =TENANT_UNIT
B11: UIC / RUC | C11: =UIC
B12: Planner | C12: =PLANNER
B13: Date Prepared | C13: =PROJ_DATE
B14: Program FY | C14: =PROG_FY
B17: Personnel Loading Summary
B18: Total Personnel (PN) | C18: =PN_TOTAL | F18: Officers | G18: =PN_OFF
B19: Enlisted | C19: =PN_ENL | F19: Civilians | G19: =PN_CIV
B20: Contractors | C20: =PN_CTR | F20: Military Strength | G20: =PN_MIL
B23: Requirements by CCN
B24: CCN | C24: Facility Name | D24: UM | E24: Required | F24: Existing | G24: Deficit | H24: Action | I24: Justification
B25: 143 10 | C25: =IFERROR(VLOOKUP(B25,CCN_TABLE,2,FALSE()),"") | D25: =IFERROR(VLOOKUP(B25,CCN_TABLE,3,FALSE()),"") | E25: =Inventory!E7 | F25: =Inventory!F7 | G25: =Inventory!I7 | H25: =Inventory!J7 | I25: =BFR_Calculator!J7
B26: 143 11 | C26: =IFERROR(VLOOKUP(B26,CCN_TABLE,2,FALSE()),"") | D26: =IFERROR(VLOOKUP(B26,CCN_TABLE,3,FALSE()),"") | E26: =Inventory!E8 | F26: =Inventory!F8 | G26: =Inventory!I8 | H26: =Inventory!J8 | I26: =BFR_Calculator!J8
B27: 143 12 | C27: =IFERROR(VLOOKUP(B27,CCN_TABLE,2,FALSE()),"") | D27: =IFERROR(VLOOKUP(B27,CCN_TABLE,3,FALSE()),"") | E27: =Inventory!E9 | F27: =Inventory!F9 | G27: =Inventory!I9 | H27: =Inventory!J9 | I27: =BFR_Calculator!J9
B28: 143 24 | C28: =IFERROR(VLOOKUP(B28,CCN_TABLE,2,FALSE()),"") | D28: =IFERROR(VLOOKUP(B28,CCN_TABLE,3,FALSE()),"") | E28: =Inventory!E10 | F28: =Inventory!F10 | G28: =Inventory!I10 | H28: =Inventory!J10 | I28: =BFR_Calculator!J10
B29: 143 45 | C29: =IFERROR(VLOOKUP(B29,CCN_TABLE,2,FALSE()),"") | D29: =IFERROR(VLOOKUP(B29,CCN_TABLE,3,FALSE()),"") | E29: =Inventory!E11 | F29: =Inventory!F11 | G29: =Inventory!I11 | H29: =Inventory!J11 | I29: =BFR_Calculator!J11
B30: 143 46 | C30: =IFERROR(VLOOKUP(B30,CCN_TABLE,2,FALSE()),"") | D30: =IFERROR(VLOOKUP(B30,CCN_TABLE,3,FALSE()),"") | E30: =Inventory!E12 | F30: =Inventory!F12 | G30: =Inventory!I12 | H30: =Inventory!J12 | I30: =BFR_Calculator!J12
B31: 171 10 | C31: =IFERROR(VLOOKUP(B31,CCN_TABLE,2,FALSE()),"") | D31: =IFERROR(VLOOKUP(B31,CCN_TABLE,3,FALSE()),"") | E31: =Inventory!E13 | F31: =Inventory!F13 | G31: =Inventory!I13 | H31: =Inventory!J13 | I31: =BFR_Calculator!J13
B32: 171 20 | C32: =IFERROR(VLOOKUP(B32,CCN_TABLE,2,FALSE()),"") | D32: =IFERROR(VLOOKUP(B32,CCN_TABLE,3,FALSE()),"") | E32: =Inventory!E14 | F32: =Inventory!F14 | G32: =Inventory!I14 | H32: =Inventory!J14 | I32: =BFR_Calculator!J14
B33: 171 50 | C33: =IFERROR(VLOOKUP(B33,CCN_TABLE,2,FALSE()),"") | D33: =IFERROR(VLOOKUP(B33,CCN_TABLE,3,FALSE()),"") | E33: =Inventory!E15 | F33: =Inventory!F15 | G33: =Inventory!I15 | H33: =Inventory!J15 | I33: =BFR_Calculator!J15
B34: 173 10 | C34: =IFERROR(VLOOKUP(B34,CCN_TABLE,2,FALSE()),"") | D34: =IFERROR(VLOOKUP(B34,CCN_TABLE,3,FALSE()),"") | E34: =Inventory!E16 | F34: =Inventory!F16 | G34: =Inventory!I16 | H34: =Inventory!J16 | I34: =BFR_Calculator!J16
B35: 173 11 | C35: =IFERROR(VLOOKUP(B35,CCN_TABLE,2,FALSE()),"") | D35: =IFERROR(VLOOKUP(B35,CCN_TABLE,3,FALSE()),"") | E35: =Inventory!E17 | F35: =Inventory!F17 | G35: =Inventory!I17 | H35: =Inventory!J17 | I35: =BFR_Calculator!J17
B36: 179 60 | C36: =IFERROR(VLOOKUP(B36,CCN_TABLE,2,FALSE()),"") | D36: =IFERROR(VLOOKUP(B36,CCN_TABLE,3,FALSE()),"") | E36: =Inventory!E18 | F36: =Inventory!F18 | G36: =Inventory!I18 | H36: =Inventory!J18 | I36: =BFR_Calculator!J18
... B38: 179 92 | C38: =IFERROR(VLOOKUP(B38,CCN_TABLE,2,FALSE()),"") | D38: =IFERROR(VLOOKUP(B38,CCN_TABLE,3,FALSE()),"") | E38: =Inventory!E20 | F38: =Inventory!F20 | G38: =Inventory!I20 | H38: =Inventory!J20 | I38: =BFR_Calculator!J20
B41: Cost Roll-up (Programming)
B42: CCN | C42: Facility Name | D42: UM | E42: Required | F42: Unit Cost ($/UM) | G42: Bare Cost | H42: ACF | I42: SIOH | J42: Programmed Cost
B43: 143 10 | C43: =IFERROR(VLOOKUP(B43,CCN_TABLE,2,FALSE()),"") | D43: =IFERROR(VLOOKUP(B43,CCN_TABLE,3,FALSE()),"") | E43: =MAX(Inventory!I7*-1,0) | F43: 425 | G43: =E43*F43 | H43: =Okinawa_Navy_ACF | I43: =SIOH | J43: =G43*H43*I43*Contingency*Esc_Factor*PD_Factor*HF
B44: 143 11 | C44: =IFERROR(VLOOKUP(B44,CCN_TABLE,2,FALSE()),"") | D44: =IFERROR(VLOOKUP(B44,CCN_TABLE,3,FALSE()),"") | E44: =MAX(Inventory!I8*-1,0) | F44: 425 | G44: =E44*F44 | H44: =Okinawa_Navy_ACF | I44: =SIOH | J44: =G44*H44*I44*Contingency*Esc_Factor*PD_Factor*HF
B45: 143 12 | C45: =IFERROR(VLOOKUP(B45,CCN_TABLE,2,FALSE()),"") | D45: =IFERROR(VLOOKUP(B45,CCN_TABLE,3,FALSE()),"") | E45: =MAX(Inventory!I9*-1,0) | F45: 110 | G45: =E45*F45 | H45: =Okinawa_Navy_ACF | I45: =SIOH | J45: =G45*H45*I45*Contingency*Esc_Factor*PD_Factor*HF
B46: 143 24 | C46: =IFERROR(VLOOKUP(B46,CCN_TABLE,2,FALSE()),"") | D46: =IFERROR(VLOOKUP(B46,CCN_TABLE,3,FALSE()),"") | E46: =MAX(Inventory!I10*-1,0) | F46: 525 | G46: =E46*F46 | H46: =Okinawa_Navy_ACF | I46: =SIOH | J46: =G46*H46*I46*Contingency*Esc_Factor*PD_Factor*HF
B47: 143 45 | C47: =IFERROR(VLOOKUP(B47,CCN_TABLE,2,FALSE()),"") | D47: =IFERROR(VLOOKUP(B47,CCN_TABLE,3,FALSE()),"") | E47: =MAX(Inventory!I11*-1,0) | F47: 525 | G47: =E47*F47 | H47: =Okinawa_Navy_ACF | I47: =SIOH | J47: =G47*H47*I47*Contingency*Esc_Factor*PD_Factor*HF
B48: 143 46 | C48: =IFERROR(VLOOKUP(B48,CCN_TABLE,2,FALSE()),"") | D48: =IFERROR(VLOOKUP(B48,CCN_TABLE,3,FALSE()),"") | E48: =MAX(Inventory!I12*-1,0) | F48: 380 | G48: =E48*F48 | H48: =Okinawa_Navy_ACF | I48: =SIOH | J48: =G48*H48*I48*Contingency*Esc_Factor*PD_Factor*HF
B49: 171 10 | C49: =IFERROR(VLOOKUP(B49,CCN_TABLE,2,FALSE()),"") | D49: =IFERROR(VLOOKUP(B49,CCN_TABLE,3,FALSE()),"") | E49: =MAX(Inventory!I13*-1,0) | F49: 510 | G49: =E49*F49 | H49: =Okinawa_Navy_ACF | I49: =SIOH | J49: =G49*H49*I49*Contingency*Esc_Factor*PD_Factor*HF
...

Sheet CCN_Library
B2: Series 100 Category Code Library
B3: FC 2-000-05N — Operational and Training Facilities (Marine Corps relevant CCNs).
C5: CCN | D5: Facility Name | E5: UM | F5: Default Factor | G5: Factor Notes / Formula | H5: NTG | I5: Driver Description
C6: 141 70 | D6: Air Traffic Control Tower | E6: SF | F6: 2956 | G6: Standard 6-floor tower & cab; add levels for height. | H6: 1.1 | I6: Each tower
C7: 143 10 | D7: Emergency Vehicle Garage | E7: SF | F7: see notes | G7: Vehicle area + 3 ft clearance/side × NTG 1.05. | H7: 1.05 | I7: Sum of vehicle plan-areas
C8: 143 11 | D8: Operational Vehicle Garage | E8: SF | F8: see notes | G8: Per Table 14311-1 (Type A 108 NSF … Type G 888 NSF) + 250 SF mech rm. | H8: 1.2 | I8: # of vehicles by Type A–G
C9: 143 12 | D9: Operational Vehicle Laydown Area | E9: SY | F9: see notes | G9: Per Table 14312-1 (Type A 19 GSY … Type G 99 GSY). | H9: 1 | I9: # of vehicles by Type A–G
C10: 143 13 | D10: Operational Vehicle/Equipment Canopy | E10: SF | F10: see notes | G10: Vehicle/equip area + circulation (drip line). | H10: 1 | I10: Sum of vehicle plan-areas
C11: 143 24 | D11: Marine Corps EOD Facility | E11: SF | F11: 7000 | G11: 7,000 GSF EOD bldg + 204 GSF Haz/Flam + magazines as required. | H11: 1 | I11: Each EOD facility
C12: 143 26 | D12: Marine Corps EOD Company Facility | E12: SF | F12: see notes | G12: NSF per function × NTG 1.40 (Admin 1,910 SF; classrooms via 171 10). | H12: 1.4 | I12: Engineering analysis per function
C13: 143 45 | D13: Armory | E13: SF | F13: see notes | G13: Per Table 14345-1 (1–2K strength: 576 GSF; >10K: +0.1 SF/PN). | H13: 1 | I13: Military strength + weapons
C14: 143 46 | D14: Marine Barracks - General Purpose | E14: SF | F14: see notes | G14: Per Table 14346-1 (1–50: 75 GSF/PN; 201+: +30 GSF/PN). | H14: 1 | I14: # of personnel barracked
C15: 143 47 | D15: Alert Force Building | E15: SF | F15: see notes | G15: Engineering analysis (barracks + messing + duty + weapons stg). | H15: 1 | I15: Alert force size
C16: 171 10 | D16: Academic Instruction Building | E16: SF | F16: 45 | G16: Per Table 17110-1 (broad: 45 GSF/student station, 75 GSF if modified). NTG 1.33. | H16: 1.33 | I16: # of student stations
C17: 171 15 | D17: Navy/Marine Corps Reserve Training | E17: SF | F17: see notes | G17: Via NOSC Space Program Spreadsheet (Tables 17115-1…9). | H17: 1.3 | I17: Reserve unit composition
C18: 171 20 | D18: Applied Instruction Building | E18: SF | F18: 150 | G18: 150 GSF/student station (broad); specialized (e.g., Flight Briefing 125 GSF). | H18: 1.25 | I18: # of student stations
C19: 171 30 | D19: Physical Education Facility | E19: SF | F19: see notes | G19: Engineering analysis required. | H19: 1 | I19: Engineering analysis
C20: 171 50 | D20: Small Arms Range — Indoor | E20: SF | F20: see notes | G20: Capacity = personnel trained ÷ (sessions × hrs/session × 180 days). | H20: 1 | I20: # of firing points
C21: 173 10 | D21: Range Operations Building | E21: SF | F21: see notes | G21: Case-by-case (admin, storage, maintenance). | H21: 1 | I21: Engineering analysis
C22: 173 11 | D22: Range Support Building | E22: SF | F22: see notes | G22: Case-by-case (billets, classrooms, AAR). | H22: 1 | I22: Engineering analysis
C23: 179 01 | D23: Bayonet Assault Course | E23: EA | F23: 1 | G23: 1 EA per prepared path/set of targets. | H23: 1 | I23: # of paths
C24: 179 17 | D24: Rappelling Training Area | E24: EA | F24: 1 | G24: Case-by-case (≥1 structure). | H24: 1 | I24: # of training areas
C25: 179 60 | D25: Parade and Drill Field | E25: AC | F25: see notes | G25: 1 AC per 125 personnel. | H25: 1 | I25: Personnel using field
C26: 179 81 | D26: Infiltration Course | E26: AC | F26: see notes | G26: 1 firing position per path/trail for 1 Marine. | H26: 1 | I26: # of firing positions
C27: 179 91 | D27: Confidence Course | E27: AC | F27: 1 | G27: 1 EA per complete course. | H27: 1 | I27: # of courses
C28: 179 92 | D28: Obstacle Course | E28: AC | F28: see notes | G28: Case-by-case. | H28: 1 | I28: # of courses
B31: Helper Table — CCN 143 11 / 143 12 Vehicle Type Factors
C32: Type | D32: Description | E32: Garage NSF (143 11) | F32: Laydown GSY (143 12)
C33: A | D33: Sedan / light truck | E33: 108 | F33: 19
C34: B | D34: Pickup / 4-pass van | E34: 180 | F34: 29
C35: C | D35: Cargo / shop van / 7-ton | E35: 288 | F35: 42
C36: D | D36: Bus / box truck | E36: 420 | F36: 57
C37: E | D37: Tractor + trailer / wrecker | E37: 588 | F37: 71
C38: F | D38: HEMTT / heavy wrecker | E38: 720 | F38: 85
C39: G | D39: Oversize / specialty | E39: 888 | F39: 99
