Workbook
Name d: #REF!
Name DDD: #REF!
Name delete1: #REF!
Name GDSGSDG: #REF!
Name ghhghg: #REF!
Name gsg: #REF!
Name Hello: #REF!
Name heloo: #REF!
Name new: #REF!
Name oc: #REF!
Name Ordnance: #REF!
Name te_table: #REF!
Name UIC_HQ: '14312'!$C$43
Name UIC_HS: '14312'!$C$89
Name x: #REF!
Name _17120Ne: #REF!
Name _17120new: #REF!
Name _17945: #REF!
Name _21451_UIC: #REF!
Name _21451New: #REF!
Name _21451NewTab: #REF!
Name _2145NEW: #REF!
Name _lAQUETTAaRMORY: #REF!
Name _MY: #REF!
Name a: #REF!
Name Amroy: #REF!
Name CostCode: #REF!
Name d: #REF!
Name dd: #REF!
Name DDD: #REF!
Name delete1: #REF!
Name GDSGSDG: #REF!
Name gfhgfhgf: #REF!
Name ghgghhg: #REF!
Name ghhghg: #REF!
Name gsg: #REF!
Name Hello: #REF!
Name HELLO1: #REF!
Name heloo: #REF!
Name IN_ins: #REF!
Name mt: #REF!
Name new: #REF!
Name oc: #REF!
Name Ordnance: #REF!
Name TE_2: #REF!
Name TE_3: #REF!
Name TE_orignial: #REF!
Name te_table: #REF!
Name UIC_HQ: '[2]14312'!$C$50
Name UIC_HS: '[2]14312'!$C$96
Name x: #REF!
Name d: #REF!
Name DDD: #REF!
Name delete1: #REF!
Name GDSGSDG: #REF!
Name ghhghg: #REF!
Name gsg: #REF!
Name Hello: #REF!
Name heloo: #REF!
Name M12301_: #N/A

Sheet UNIT_ROLLUP
A1: BASIC FACILITY REQUIREMENTS UNIT ROLLUP
A3: Installation: | F3: H&S BN MCIPAC MCB CP BUTLER JA | M3: Tenant: | R3: 3D MEDICAL BATTALION
A4: Installation UIC: | F4: M67400 | M4: Tenant UIC: | R4: M13020 | Y4: Planning Area: | AE4: FO
E7: Facilities measured in SF
E8: CCN | H8: Description | W8: Required Area
E9: 14345 | H9: Armory | W9: ='14345'!H40
E10: 17110 | H10: Academic Instruction Building | W10: ='17110'!H40
E11: 17120 | H11: Applied Instruction Building | W11: ='17120'!H40
E12: 44112 | H12: Storage of Air or Ground Organic Units - USMC | W12: ='44112'!H40
E13: 61072 | H13: Battalion /Squadron Headquarters, Marine Corps | W13: ='61072'!H40
E14: 61073 | H14: Company/Battery Headquarters, Marine Corps | W14: ='61073'!H40
E15: 14312 | H15: Operational Vehicle Laydown Area | W15: ='14312'!H36
E16: 21451 | H16: Automotive Organizational Shop | W16: ='21451'!H44
E17: 21710 | H17: Electronics/Communications Maintenance Shop | W17: ='21710'!H47
E18: 45110 | H18: Open Storage Area | W18: ='45110'!H50
R19: Total = | W19: =SUM(W9:AA18)
A40: TOTAL REQUIREMENT: | H40: =W15 | L40: GSF | AB40: Page | AD40: 1 | AE40: of | AF40: 1

Sheet MISSION STATEMENT
A1: *** UNCLASSIFIED // FOR OFFICIAL USE ONLY ***
B2: United States Marine Corps | R2: ='MISSION STATEMENT'!B6+'MISSION STATEMENT'!L200
B3: Total Force Structure Management System
B4: Unit TO&E Report
B6: H&S CO 3D MED BN 3D MLG
B7: UNIT 38445
B9: FPO, AP 963734500
B10: Country: JP
B11: UIC: M28261
A13: Source: | B13: Published
A14: Structure Data current as of: | B14: 02/27/2023
A15: Equipment Data Current as of: | B15: 45034.948
A18: Report Fiscal Year: | B18: 2029
A19: Manning Precedence Level: | B19: OPFOR
A20: Military Unit Level Code: | B20: HQS
A22: Unit Descriptor Code: | B22: T
A23: Unit Type Code: | B23: FWQAB
A24: SASSY AAC: | B24: SASSY M28260
B25: LONG TERM STORAGE -- DATA CONVERSION INITIAL ACCOUNT
A26: MEF Code: | B26: C
A27: Type Support Code: | B27: C
A30: MISSION STATEMENT
A31: SIGNED AS OF FEB 3, 2021 UNIT IDENTIFICATION CODE...SEE ENCL (1) HEADQUARTERS AND SERVICE COMPANY MEDICAL BATTALION SUBJ: MISSION STATEMENT 1. Promulgation Statement. This is the Headquarters and Service Company (H&S Co), Medical Battalion (Med Bn), Marine Logistics Group (MLG) Mission Statement. This Mission Statement defines the unit?s role and responsibilities in support of the MAGTF, the SE, and/or Joint Operations and prescribes the unit's organizational structure and capabilities in accordance with its tasks that manifests in the unit?s table of organization and equipment (T/O&E). 2. Organization Headquarters Command Staff Company Headquarters Section Combat Stress Platoon Pharmacy Platoon Surgical Platoon 1 Surgical Platoon 2 3. Mission and Tasks a. Mission. Provide general Role 2 health service support to the Marine Expeditionary Force (MEF) and command, control, and command support functions for Med Bn, MLG. b. Tasks (1) MCT 4.5.3 Conduct Casualty Treatment. (2) MCT 4.5.4 Conduct Temporary Casualty Holding. (3) MCT 4.5.5 Conduct Casualty Evacuation. (4) MCT 4.5.8 Conduct Medical Regulating. 4. Concept of Organization. The company is organized to plan, coordinate, and supervise the command support functions for the battalion, and to provide general Role 2 health services support to the MEF. It is structured to facilitate task organization for operations conducted by the battalion in support of the MEF or smaller Marine Air Ground Task Force (MAGTF). 5. Concept of Employment. The company is employed with the battalion to provide command and control, facilities administrative support, and health services support. Detachments from the company headquarters, sections, and platoons may be assigned to provide support and/or augment adjacent companies. a. Maneuver. Not applicable. b. Intelligence. Intelligence support and products are provided by MLG Headquarters. c. Fires. Organic firepower is limited to individual and crew-served weapons for personal security and for defense of medical health care services installations per applicable international law, which defines company personnel as personnel employed in the administration of health care treatment facilities. d. Logistics. The company provides health services support and serves as an emergency resupply source for medical health care services materiel for supported medical health care services units. e. Command and Control. The Company Commander directs and controls command support functions relating to operations, administration, and tactical logistics for the company. f. Force Protection. The company has limited organic security capability. 6. Administrative Capabilities. The company is capable of self-administration, to include personnel administration for all assigned personnel. 7. Logistics Capabilities a. Maintenance. The company is capable of organic field-level maintenance. Field-level maintenance for medical equipment beyond organic capability, to include maintaining the authorized medical allowance list, is provided by Medical Logistics Company, Supply Battalion, MLG. b. Supply. The company is capable of organic supply support. Medical Logistics Company, Supply Battalion, MLG, provides Class VIII supply support. c. Transportation. The company is capable of organic transportation support for command and administrative purposes. d. General Engineering. The company is capable of organic mobile electric power generation and distribution. Additional engineering support is provided by Engineer Support Battalion, MLG. e. Health Services. The company is capable of organic Role 1 and 2 health care capabilities. Dental health care services are provided by Dental Battalion, MLG. f. Services. Services support is provided by Service Company, CLR x7, MLG. Food service support is provided by Food Service Company, CLR x7, MLG. 8. Command and Signal a. Command Relationships. The Company Commander reports to the Med Bn Commander. b. Communications and Information Systems. Communications support is provided by Communications Company, CLR x7, MLG. 9. Supersession. This Mission Statement supersedes the previous Mission Statement of 20 June 2017 and is effective upon receipt. ERIC M. SMITH Deputy Commandant for Combat Development and Integration
A98: 45035
A101: *** UNCLASSIFIED // FOR OFFICIAL USE ONLY ***
B102: United States Marine Corps
B103: Total Force Structure Management System
B104: Unit TO&E Report
B106: SURG CO A 3D MED BN 3D MLG
B107: UNIT 38448
B109: FPO, AP 966048448
B110: Country: JP
B111: UIC: M28263
A113: Source: | B113: Published
A114: Structure Data current as of: | B114: 02/27/2023
A115: Equipment Data Current as of: | B115: 45034.948
A118: Report Fiscal Year: | B118: 2029
A119: Manning Precedence Level: | B119: OPFOR
A120: Military Unit Level Code: | B120: CO
A122: Unit Descriptor Code: | B122: T
...

Sheet CCN_Library
A1: CCN_Library: canonical facility names per FC 2-000-05N for the 10 CCNs this BFR uses
A3: CCN | B3: Facility Name | C3: Source | D3: Page
A4: 14312 | B4: OPERATIONAL VEHICLE LAYDOWN AREA | C4: fc_2_000_05n_100series_02_11_2026.pdf | D4: 189
A5: 14345 | B5: ARMORY | C5: fc_2_000_05n_100series_02_11_2026.pdf | D5: 205
A6: 17110 | B6: ACADEMIC INSTRUCTION BUILDING | C6: fc_2_000_05n_100series_02_11_2026.pdf | D6: 278
A7: 17120 | B7: APPLIED INSTRUCTION BUILDING | C7: fc_2_000_05n_100series_02_11_2026.pdf | D7: 298
A8: 21451 | B8: AUTOMOTIVE ORGANIZATIONAL SHOP | C8: fc_2_000_05n_200series_05_16_2025.pdf | D8: 188
A9: 21710 | B9: ELECTRONICS/COMMUNICATIONS MAINTENANCE SHOP | C9: fc_2_000_05n_200series_05_16_2025.pdf | D9: 195
A10: 44112 | B10: STORAGE OF AIR OR GROUND ORGANIC UNITS FOR MARINE CORPS | C10: fc_2_000_05n_400series_11_19_2025.pdf | D10: 46
A11: 45110 | B11: OPEN STORAGE AREA | C11: fc_2_000_05n_400series_11_19_2025.pdf | D11: 50
A12: 61072 | B12: BATTALION/SQUADRON HEADQUARTERS, MARINE CORPS | C12: fc_2_000_05n_600series_03_02_2023.pdf | D12: 39
A13: 61073 | B13: COMPANY/BATTERY HEADQUARTERS, MARINE CORPS | C13: fc_2_000_05n_600series_03_02_2023.pdf | D13: 39

Sheet TO
U1: CHARGEABLE | AD1: NON-CHARGEABLE
D2: Has a Desk? | U2: MC Act | W2: MC Res | Y2: Civ | Z2: Other Active | AB2: Other Reserve | AD2: MC Act | AF2: MC Res | AH2: Civ | AJ2: Other Active | AL2: Other Reserve | AN2: MT/MF | AO2: UIC
B3: LINE | C3: NOTE | D3: CCN | E3: CCN Decription | F3: UIC | G3: Rec CD | H3: BIC | I3: Billet Description | J3: Alpha Grade | K3: BMOS | L3: PMOS | M3: B R N | N3: T Y P | O3: S T A | P3: M P R | Q3: Res Typ | R3: S C | S3: W P N | T3: Billet SPN | U3: Off | V3: Enl | W3: Off | X3: Enl | Z3: Off | AA3: Enl | AB3: Off | AC3: Enl | AD3: Off | AE3: Enl | AF3: Off | AG3: Enl | AH3: NC | AI3: T/T | AJ3: Off | AK3: Enl | AL3: Off | AM3: Enl | AP3: A S R | AQ3: IH/CA | AR3: MCC | AS3: F T N
B4: 1 | C4: 61072o | D4: 61072 | F4: =LEFT(H4,6) | G4: C | H4: M2826101021 | I4: HEADQUARTERS COMMAND STAFF | U4: 0 | V4: 0 | W4: 0 | X4: 0 | Y4: 0 | Z4: 0 | AA4: 0 | AB4: 0 | AC4: 0 | AD4: 0 | AE4: 0 | AF4: 0 | AG4: 0 | AH4: 0 | AI4: 0 | AJ4: 0 | AK4: 0 | AL4: 0 | AM4: 0
B5: =B4+1 | C5: 61072o | D5: 61072 | E5: =IF(D5="","",IFERROR(VLOOKUP(D5,CCN_Library!$A$4:$B$13,2,FALSE),"NOT IN LIBRARY")) | F5: =LEFT(H5,6) | G5: E | H5: M2826101022 | I5: COMMANDING OFFICER | J5: CAPT | K5: 2300 | L5: 2300 | M5: N | N5: O | O5: A | P5: A | R5: U | S5: P | U5: 0 | V5: 0 | W5: 0 | X5: 0 | Y5: 0 | Z5: 1 | AA5: 0 | AB5: 0 | AC5: 0 | AD5: 0 | AE5: 0 | AF5: 0 | AG5: 0 | AH5: 0 | AI5: 0 | AJ5: 0 | AK5: 0 | AL5: 0 | AM5: 0 | AP5: 1 | AQ5: A-M510 | AR5: 1CP
B6: =B5+1 | C6: 61072o | D6: 61072 | E6: =IF(D6="","",IFERROR(VLOOKUP(D6,CCN_Library!$A$4:$B$13,2,FALSE),"NOT IN LIBRARY")) | F6: =LEFT(H6,6) | G6: E | H6: M2826101023 | I6: EXECUTIVE OFFICER | J6: CDR | K6: 2300 | L6: 2300 | M6: N | N6: O | O6: A | P6: A | R6: U | S6: P | U6: 0 | V6: 0 | W6: 0 | X6: 0 | Y6: 0 | Z6: 1 | AA6: 0 | AB6: 0 | AC6: 0 | AD6: 0 | AE6: 0 | AF6: 0 | AG6: 0 | AH6: 0 | AI6: 0 | AJ6: 0 | AK6: 0 | AL6: 0 | AM6: 0 | AP6: 1 | AQ6: A-M510 | AR6: 1CP
B7: =B6+1 | C7: 61072o | D7: 61072 | E7: =IF(D7="","",IFERROR(VLOOKUP(D7,CCN_Library!$A$4:$B$13,2,FALSE),"NOT IN LIBRARY")) | F7: =LEFT(H7,6) | G7: E | H7: M2826101531 | I7: SUPPLY OFFICER | J7: 1STLT | K7: 3002 | L7: 3002 | M7: M | N7: O | O7: A | P7: A | R7: U | S7: C | U7: 1 | V7: 0 | W7: 0 | X7: 0 | Y7: 0 | Z7: 0 | AA7: 0 | AB7: 0 | AC7: 0 | AD7: 0 | AE7: 0 | AF7: 0 | AG7: 0 | AH7: 0 | AI7: 0 | AJ7: 0 | AK7: 0 | AL7: 0 | AM7: 0 | AP7: 1 | AQ7: A-M510 | AR7: 1CP
B8: =B7+1 | C8: 61072o | D8: 61072 | E8: =IF(D8="","",IFERROR(VLOOKUP(D8,CCN_Library!$A$4:$B$13,2,FALSE),"NOT IN LIBRARY")) | F8: =LEFT(H8,6) | G8: E | H8: M2826101024 | I8: DIRECTOR HEALTH SERVICES/PROGRAM | J8: CAPT | K8: 2100 | L8: 2100 | M8: N | N8: O | O8: A | P8: A | R8: U | S8: P | U8: 0 | V8: 0 | W8: 0 | X8: 0 | Y8: 0 | Z8: 1 | AA8: 0 | AB8: 0 | AC8: 0 | AD8: 0 | AE8: 0 | AF8: 0 | AG8: 0 | AH8: 0 | AI8: 0 | AJ8: 0 | AK8: 0 | AL8: 0 | AM8: 0 | AP8: 1 | AQ8: A-M510 | AR8: 1CP | AS8: *
B9: =B8+1 | C9: 61072o | D9: 61072 | E9: =IF(D9="","",IFERROR(VLOOKUP(D9,CCN_Library!$A$4:$B$13,2,FALSE),"NOT IN LIBRARY")) | F9: =LEFT(H9,6) | G9: E | H9: M2826101025 | I9: COMMAND MASTER CHIEF | J9: CMDCM | K9: 8CMC | L9: 8CMC | M9: N | N9: E | O9: A | P9: A | R9: U | S9: P | U9: 0 | V9: 0 | W9: 0 | X9: 0 | Y9: 0 | Z9: 0 | AA9: 1 | AB9: 0 | AC9: 0 | AD9: 0 | AE9: 0 | AF9: 0 | AG9: 0 | AH9: 0 | AI9: 0 | AJ9: 0 | AK9: 0 | AL9: 0 | AM9: 0 | AP9: 1 | AQ9: A-M510 | AR9: 1CP
B10: =B9+1 | C10: 61072c | D10: 61072 | E10: =IF(D10="","",IFERROR(VLOOKUP(D10,CCN_Library!$A$4:$B$13,2,FALSE),"NOT IN LIBRARY")) | F10: =LEFT(H10,6) | G10: E | H10: M2826101026 | I10: FLD MED TECH | J10: HN | K10: L03A | L10: L03A | M10: N | N10: E | O10: A | P10: A | R10: U | S10: C | U10: 0 | V10: 0 | W10: 0 | X10: 0 | Y10: 0 | Z10: 0 | AA10: 1 | AB10: 0 | AC10: 0 | AD10: 0 | AE10: 0 | AF10: 0 | AG10: 0 | AH10: 0 | AI10: 0 | AJ10: 0 | AK10: 0 | AL10: 0 | AM10: 0 | AP10: 1 | AQ10: A-M510 | AR10: 1CP
B11: =B10+1 | C11: 61073o | D11: 61073 | F11: =LEFT(H11,6) | G11: C | H11: M2826101027 | I11: COMPANY HEADQUARTERS SECTION | U11: 0 | V11: 0 | W11: 0 | X11: 0 | Y11: 0 | Z11: 0 | AA11: 0 | AB11: 0 | AC11: 0 | AD11: 0 | AE11: 0 | AF11: 0 | AG11: 0 | AH11: 0 | AI11: 0 | AJ11: 0 | AK11: 0 | AL11: 0 | AM11: 0
B12: =B11+1 | C12: 61073o | D12: 61073 | E12: =IF(D12="","",IFERROR(VLOOKUP(D12,CCN_Library!$A$4:$B$13,2,FALSE),"NOT IN LIBRARY")) | F12: =LEFT(H12,6) | G12: E | H12: M2826101423 | I12: COMPANY COMMANDER | J12: CAPT | K12: 0402 | L12: 0402 | M12: M | N12: O | O12: A | P12: A | R12: U | S12: C | U12: 1 | V12: 0 | W12: 0 | X12: 0 | Y12: 0 | Z12: 0 | AA12: 0 | AB12: 0 | AC12: 0 | AD12: 0 | AE12: 0 | AF12: 0 | AG12: 0 | AH12: 0 | AI12: 0 | AJ12: 0 | AK12: 0 | AL12: 0 | AM12: 0 | AP12: 1 | AQ12: A-M510 | AR12: 1CP
B13: =B12+1 | C13: 61073c | D13: 61073 | E13: =IF(D13="","",IFERROR(VLOOKUP(D13,CCN_Library!$A$4:$B$13,2,FALSE),"NOT IN LIBRARY")) | F13: =LEFT(H13,6) | G13: E | H13: M2826101425 | I13: ADMIN CLERK | J13: LCPL | K13: 0111 | L13: 0111 | M13: M | N13: E | O13: A | P13: A | R13: U | S13: M | U13: 0 | V13: 1 | W13: 0 | X13: 0 | Y13: 0 | Z13: 0 | AA13: 0 | AB13: 0 | AC13: 0 | AD13: 0 | AE13: 0 | AF13: 0 | AG13: 0 | AH13: 0 | AI13: 0 | AJ13: 0 | AK13: 0 | AL13: 0 | AM13: 0 | AP13: 1 | AQ13: A-M510 | AR13: 1CP
B14: =B13+1 | C14: 61073o | D14: 61073 | E14: =IF(D14="","",IFERROR(VLOOKUP(D14,CCN_Library!$A$4:$B$13,2,FALSE),"NOT IN LIBRARY")) | F14: =LEFT(H14,6) | G14: E | H14: M2826101491 | I14: FLD MED TECH | J14: HMCS | K14: L03A | L14: L03A | M14: N | N14: E | O14: A | P14: A | R14: U | S14: P | U14: 0 | V14: 0 | W14: 0 | X14: 0 | Y14: 0 | Z14: 0 | AA14: 1 | AB14: 0 | AC14: 0 | AD14: 0 | AE14: 0 | AF14: 0 | AG14: 0 | AH14: 0 | AI14: 0 | AJ14: 0 | AK14: 0 | AL14: 0 | AM14: 0 | AP14: 1 | AQ14: A-M510 | AR14: 1CP
B15: =B14+1 | C15: 61073c | D15: 61073 | E15: =IF(D15="","",IFERROR(VLOOKUP(D15,CCN_Library!$A$4:$B$13,2,FALSE),"NOT IN LIBRARY")) | F15: =LEFT(H15,6) | G15: E | H15: M2826101029 | I15: FLD MED TECH | J15: HM3 | K15: L03A | L15: L03A | M15: N | N15: E | O15: A | P15: A | R15: U | S15: C | U15: 0 | V15: 0 | W15: 0 | X15: 0 | Y15: 0 | Z15: 0 | AA15: 1 | AB15: 0 | AC15: 0 | AD15: 0 | AE15: 0 | AF15: 0 | AG15: 0 | AH15: 0 | AI15: 0 | AJ15: 0 | AK15: 0 | AL15: 0 | AM15: 0 | AP15: 1 | AQ15: A-M510 | AR15: 1CP
B16: =B15+1 | C16: 61072o | D16: 61072 | F16: =LEFT(H16,6) | G16: D | H16: M2826101030 | I16: S-1 | U16: 0 | V16: 0 | W16: 0 | X16: 0 | Y16: 0 | Z16: 0 | AA16: 0 | AB16: 0 | AC16: 0 | AD16: 0 | AE16: 0 | AF16: 0 | AG16: 0 | AH16: 0 | AI16: 0 | AJ16: 0 | AK16: 0 | AL16: 0 | AM16: 0
B17: =B16+1 | C17: 61072o | D17: 61072 | E17: =IF(D17="","",IFERROR(VLOOKUP(D17,CCN_Library!$A$4:$B$13,2,FALSE),"NOT IN LIBRARY")) | F17: =LEFT(H17,6) | G17: E | H17: M2826101031 | I17: S-1 OFFICER | J17: LT | K17: 2300 | L17: 2300 | M17: N | N17: O | O17: A | P17: A | R17: U | S17: P | U17: 0 | V17: 0 | W17: 0 | X17: 0 | Y17: 0 | Z17: 1 | AA17: 0 | AB17: 0 | AC17: 0 | AD17: 0 | AE17: 0 | AF17: 0 | AG17: 0 | AH17: 0 | AI17: 0 | AJ17: 0 | AK17: 0 | AL17: 0 | AM17: 0 | AP17: 1 | AQ17: A-M510 | AR17: 1CP
B18: =B17+1 | C18: 61072o | D18: 61072 | E18: =IF(D18="","",IFERROR(VLOOKUP(D18,CCN_Library!$A$4:$B$13,2,FALSE),"NOT IN LIBRARY")) | F18: =LEFT(H18,6) | G18: E | H18: M2826101032 | I18: ADJUTANT/LEGAL OFFICER | J18: LTJG | K18: 2300 | L18: 2300 | M18: N | N18: O | O18: A | P18: A | R18: U | S18: P | U18: 0 | V18: 0 | W18: 0 | X18: 0 | Y18: 0 | Z18: 1 | AA18: 0 | AB18: 0 | AC18: 0 | AD18: 0 | AE18: 0 | AF18: 0 | AG18: 0 | AH18: 0 | AI18: 0 | AJ18: 0 | AK18: 0 | AL18: 0 | AM18: 0 | AP18: 1 | AQ18: A-M510 | AR18: 1CP
B19: =B18+1 | C19: 61072o | D19: 61072 | E19: =IF(D19="","",IFERROR(VLOOKUP(D19,CCN_Library!$A$4:$B$13,2,FALSE),"NOT IN LIBRARY")) | F19: =LEFT(H19,6) | G19: E | H19: M2826101033 | I19: FLD MED TECH | J19: HMC | K19: L03A | L19: L03A | M19: N | N19: E | O19: A | P19: A | R19: U | S19: P | U19: 0 | V19: 0 | W19: 0 | X19: 0 | Y19: 0 | Z19: 0 | AA19: 1 | AB19: 0 | AC19: 0 | AD19: 0 | AE19: 0 | AF19: 0 | AG19: 0 | AH19: 0 | AI19: 0 | AJ19: 0 | AK19: 0 | AL19: 0 | AM19: 0 | AP19: 1 | AQ19: A-M510 | AR19: 1CP
B20: =B19+1 | C20: 61072o | D20: 61072 | E20: =IF(D20="","",IFERROR(VLOOKUP(D20,CCN_Library!$A$4:$B$13,2,FALSE),"NOT IN LIBRARY")) | F20: =LEFT(H20,6) | G20: E | H20: M2826101034 | I20: FLD MED TECH | J20: HM1 | K20: L03A | L20: L03A | M20: N | N20: E | O20: A | P20: A | R20: U | S20: P | U20: 0 | V20: 0 | W20: 0 | X20: 0 | Y20: 0 | Z20: 0 | AA20: 1 | AB20: 0 | AC20: 0 | AD20: 0 | AE20: 0 | AF20: 0 | AG20: 0 | AH20: 0 | AI20: 0 | AJ20: 0 | AK20: 0 | AL20: 0 | AM20: 0 | AP20: 1 | AQ20: A-M510 | AR20: 1CP
B21: =B20+1 | C21: 61072c | D21: 61072 | E21: =IF(D21="","",IFERROR(VLOOKUP(D21,CCN_Library!$A$4:$B$13,2,FALSE),"NOT IN LIBRARY")) | F21: =LEFT(H21,6) | G21: E | H21: M2826101035 | I21: FLD MED TECH | J21: HM2 | K21: L03A | L21: L03A | M21: N | N21: E | O21: A | P21: A | R21: U | S21: C | U21: 0 | V21: 0 | W21: 0 | X21: 0 | Y21: 0 | Z21: 0 | AA21: 1 | AB21: 0 | AC21: 0 | AD21: 0 | AE21: 0 | AF21: 0 | AG21: 0 | AH21: 0 | AI21: 0 | AJ21: 0 | AK21: 0 | AL21: 0 | AM21: 0 | AP21: 1 | AQ21: A-M510 | AR21: 1CP
B22: =B21+1 | C22: 61072c | D22: 61072 | E22: =IF(D22="","",IFERROR(VLOOKUP(D22,CCN_Library!$A$4:$B$13,2,FALSE),"NOT IN LIBRARY")) | F22: =LEFT(H22,6) | G22: E | H22: M2826101036 | I22: FLD MED TECH | J22: HM3 | K22: L03A | L22: L03A | M22: N | N22: E | O22: A | P22: A | R22: U | S22: C | U22: 0 | V22: 0 | W22: 0 | X22: 0 | Y22: 0 | Z22: 0 | AA22: 1 | AB22: 0 | AC22: 0 | AD22: 0 | AE22: 0 | AF22: 0 | AG22: 0 | AH22: 0 | AI22: 0 | AJ22: 0 | AK22: 0 | AL22: 0 | AM22: 0 | AP22: 1 | AQ22: A-M510 | AR22: 1CP
B23: =B22+1 | C23: 61072c | D23: 61072 | E23: =IF(D23="","",IFERROR(VLOOKUP(D23,CCN_Library!$A$4:$B$13,2,FALSE),"NOT IN LIBRARY")) | F23: =LEFT(H23,6) | G23: E | H23: M2826101037 | I23: FLD MED TECH | J23: HM3 | K23: L03A | L23: L03A | M23: N | N23: E | O23: A | P23: A | R23: U | S23: C | U23: 0 | V23: 0 | W23: 0 | X23: 0 | Y23: 0 | Z23: 0 | AA23: 1 | AB23: 0 | AC23: 0 | AD23: 0 | AE23: 0 | AF23: 0 | AG23: 0 | AH23: 0 | AI23: 0 | AJ23: 0 | AK23: 0 | AL23: 0 | AM23: 0 | AP23: 1 | AQ23: A-M510 | AR23: 1CP
B24: =B23+1 | C24: 61072o | D24: 61072 | E24: =IF(D24="","",IFERROR(VLOOKUP(D24,CCN_Library!$A$4:$B$13,2,FALSE),"NOT IN LIBRARY")) | F24: =LEFT(H24,6) | G24: E | H24: M2826101038 | I24: PERS SPEC | J24: PS1 | K24: 0000 | L24: 0000 | M24: N | N24: E | O24: A | P24: A | R24: U | S24: P | U24: 0 | V24: 0 | W24: 0 | X24: 0 | Y24: 0 | Z24: 0 | AA24: 1 | AB24: 0 | AC24: 0 | AD24: 0 | AE24: 0 | AF24: 0 | AG24: 0 | AH24: 0 | AI24: 0 | AJ24: 0 | AK24: 0 | AL24: 0 | AM24: 0 | AP24: 1 | AQ24: A-M510 | AR24: 1CP
B25: =B24+1 | C25: 61072c | D25: 61072 | E25: =IF(D25="","",IFERROR(VLOOKUP(D25,CCN_Library!$A$4:$B$13,2,FALSE),"NOT IN LIBRARY")) | F25: =LEFT(H25,6) | G25: E | H25: M2826101039 | I25: PERS SPEC | J25: PS2 | K25: 0000 | L25: 0000 | M25: N | N25: E | O25: A | P25: A | R25: U | S25: C | U25: 0 | V25: 0 | W25: 0 | X25: 0 | Y25: 0 | Z25: 0 | AA25: 1 | AB25: 0 | AC25: 0 | AD25: 0 | AE25: 0 | AF25: 0 | AG25: 0 | AH25: 0 | AI25: 0 | AJ25: 0 | AK25: 0 | AL25: 0 | AM25: 0 | AP25: 1 | AQ25: A-M510 | AR25: 1CP
B26: =B25+1 | C26: 61072c | D26: 61072 | E26: =IF(D26="","",IFERROR(VLOOKUP(D26,CCN_Library!$A$4:$B$13,2,FALSE),"NOT IN LIBRARY")) | F26: =LEFT(H26,6) | G26: E | H26: M2826101613 | I26: YEOMAN | J26: YN2 | K26: 0000 | L26: 0000 | M26: N | N26: E | O26: A | P26: A | R26: U | S26: C | U26: 0 | V26: 0 | W26: 0 | X26: 0 | Y26: 0 | Z26: 0 | AA26: 1 | AB26: 0 | AC26: 0 | AD26: 0 | AE26: 0 | AF26: 0 | AG26: 0 | AH26: 0 | AI26: 0 | AJ26: 0 | AK26: 0 | AL26: 0 | AM26: 0 | AP26: 1 | AQ26: A-M510 | AR26: 1CP
B27: =B26+1 | C27: 61072c | D27: 61072 | E27: =IF(D27="","",IFERROR(VLOOKUP(D27,CCN_Library!$A$4:$B$13,2,FALSE),"NOT IN LIBRARY")) | F27: =LEFT(H27,6) | G27: E | H27: M2826101614 | I27: PERS SPEC | J27: PS3 | K27: 0000 | L27: 0000 | M27: N | N27: E | O27: A | P27: A | R27: U | S27: C | U27: 0 | V27: 0 | W27: 0 | X27: 0 | Y27: 0 | Z27: 0 | AA27: 1 | AB27: 0 | AC27: 0 | AD27: 0 | AE27: 0 | AF27: 0 | AG27: 0 | AH27: 0 | AI27: 0 | AJ27: 0 | AK27: 0 | AL27: 0 | AM27: 0 | AP27: 1 | AQ27: A-M510 | AR27: 1CP
B28: =B27+1 | C28: 61072c | D28: 61072 | E28: =IF(D28="","",IFERROR(VLOOKUP(D28,CCN_Library!$A$4:$B$13,2,FALSE),"NOT IN LIBRARY")) | F28: =LEFT(H28,6) | G28: E | H28: M2826101426 | I28: CASUALTY REPORTING COORDINATOR | J28: LCPL | K28: 0111 | L28: 0111 | M28: M | N28: E | O28: A | P28: A | R28: U | S28: M | U28: 0 | V28: 1 | W28: 0 | X28: 0 | Y28: 0 | Z28: 0 | AA28: 0 | AB28: 0 | AC28: 0 | AD28: 0 | AE28: 0 | AF28: 0 | AG28: 0 | AH28: 0 | AI28: 0 | AJ28: 0 | AK28: 0 | AL28: 0 | AM28: 0 | AP28: 1 | AQ28: A-M510 | AR28: 1CP
B29: =B28+1 | C29: 61072o | D29: 61072 | F29: =LEFT(H29,6) | G29: D | H29: M2826101040 | I29: S-2/S-3 | U29: 0 | V29: 0 | W29: 0 | X29: 0 | Y29: 0 | Z29: 0 | AA29: 0 | AB29: 0 | AC29: 0 | AD29: 0 | AE29: 0 | AF29: 0 | AG29: 0 | AH29: 0 | AI29: 0 | AJ29: 0 | AK29: 0 | AL29: 0 | AM29: 0
B30: =B29+1 | C30: 61072o | D30: 61072 | E30: =IF(D30="","",IFERROR(VLOOKUP(D30,CCN_Library!$A$4:$B$13,2,FALSE),"NOT IN LIBRARY")) | F30: =LEFT(H30,6) | G30: E | H30: M2826101597 | I30: S-2/3 OFFICER | J30: LCDR | K30: 2300 | L30: 2300 | M30: N | N30: O | O30: A | P30: A | R30: U | S30: P | U30: 0 | V30: 0 | W30: 0 | X30: 0 | Y30: 0 | Z30: 1 | AA30: 0 | AB30: 0 | AC30: 0 | AD30: 0 | AE30: 0 | AF30: 0 | AG30: 0 | AH30: 0 | AI30: 0 | AJ30: 0 | AK30: 0 | AL30: 0 | AM30: 0 | AP30: 1 | AQ30: A-M510 | AR30: 1CP
B31: =B30+1 | C31: 61072o | D31: 61072 | E31: =IF(D31="","",IFERROR(VLOOKUP(D31,CCN_Library!$A$4:$B$13,2,FALSE),"NOT IN LIBRARY")) | F31: =LEFT(H31,6) | G31: E | H31: M2826101042 | I31: FLD MED TECH | J31: HMC | K31: L03A | L31: L03A | M31: N | N31: E | O31: A | P31: A | R31: U | S31: P | U31: 0 | V31: 0 | W31: 0 | X31: 0 | Y31: 0 | Z31: 0 | AA31: 1 | AB31: 0 | AC31: 0 | AD31: 0 | AE31: 0 | AF31: 0 | AG31: 0 | AH31: 0 | AI31: 0 | AJ31: 0 | AK31: 0 | AL31: 0 | AM31: 0 | AP31: 1 | AQ31: A-M510 | AR31: 1CP
B32: =B31+1 | C32: 61072o | D32: 61072 | E32: =IF(D32="","",IFERROR(VLOOKUP(D32,CCN_Library!$A$4:$B$13,2,FALSE),"NOT IN LIBRARY")) | F32: =LEFT(H32,6) | G32: E | H32: M2826101043 | I32: FLD MED TECH | J32: HM1 | K32: L03A | L32: L03A | M32: N | N32: E | O32: A | P32: A | R32: U | S32: P | U32: 0 | V32: 0 | W32: 0 | X32: 0 | Y32: 0 | Z32: 0 | AA32: 1 | AB32: 0 | AC32: 0 | AD32: 0 | AE32: 0 | AF32: 0 | AG32: 0 | AH32: 0 | AI32: 0 | AJ32: 0 | AK32: 0 | AL32: 0 | AM32: 0 | AP32: 1 | AQ32: A-M510 | AR32: 1CP
B33: =B32+1 | C33: 61072o | D33: 61072 | E33: =IF(D33="","",IFERROR(VLOOKUP(D33,CCN_Library!$A$4:$B$13,2,FALSE),"NOT IN LIBRARY")) | F33: =LEFT(H33,6) | G33: E | H33: M2826101044 | I33: ASSISTANT S-3/OPERATIONS OFFICER | J33: LT | K33: 2300 | L33: 2300 | M33: N | N33: O | O33: A | P33: A | R33: U | S33: P | U33: 0 | V33: 0 | W33: 0 | X33: 0 | Y33: 0 | Z33: 1 | AA33: 0 | AB33: 0 | AC33: 0 | AD33: 0 | AE33: 0 | AF33: 0 | AG33: 0 | AH33: 0 | AI33: 0 | AJ33: 0 | AK33: 0 | AL33: 0 | AM33: 0 | AP33: 1 | AQ33: A-M510 | AR33: 1CP
B34: =B33+1 | C34: 61072o | D34: 61072 | E34: =IF(D34="","",IFERROR(VLOOKUP(D34,CCN_Library!$A$4:$B$13,2,FALSE),"NOT IN LIBRARY")) | F34: =LEFT(H34,6) | G34: E | H34: M2826101045 | I34: FLD MED TECH | J34: HMC | K34: L03A | L34: L03A | M34: N | N34: E | O34: A | P34: A | R34: U | S34: P | U34: 0 | V34: 0 | W34: 0 | X34: 0 | Y34: 0 | Z34: 0 | AA34: 1 | AB34: 0 | AC34: 0 | AD34: 0 | AE34: 0 | AF34: 0 | AG34: 0 | AH34: 0 | AI34: 0 | AJ34: 0 | AK34: 0 | AL34: 0 | AM34: 0 | AP34: 1 | AQ34: A-M510 | AR34: 1CP
B35: =B34+1 | C35: 61072c | D35: 61072 | E35: =IF(D35="","",IFERROR(VLOOKUP(D35,CCN_Library!$A$4:$B$13,2,FALSE),"NOT IN LIBRARY")) | F35: =LEFT(H35,6) | G35: E | H35: M2826101046 | I35: FLD MED TECH | J35: HM2 | K35: L03A | L35: L03A | M35: N | N35: E | O35: A | P35: A | R35: U | S35: C | U35: 0 | V35: 0 | W35: 0 | X35: 0 | Y35: 0 | Z35: 0 | AA35: 1 | AB35: 0 | AC35: 0 | AD35: 0 | AE35: 0 | AF35: 0 | AG35: 0 | AH35: 0 | AI35: 0 | AJ35: 0 | AK35: 0 | AL35: 0 | AM35: 0 | AP35: 1 | AQ35: A-M510 | AR35: 1CP
B36: =B35+1 | C36: 61072c | D36: 61072 | E36: =IF(D36="","",IFERROR(VLOOKUP(D36,CCN_Library!$A$4:$B$13,2,FALSE),"NOT IN LIBRARY")) | F36: =LEFT(H36,6) | G36: E | H36: M2826101047 | I36: FLD MED TECH | J36: HM2 | K36: L03A | L36: L03A | M36: N | N36: E | O36: A | P36: A | R36: U | S36: C | U36: 0 | V36: 0 | W36: 0 | X36: 0 | Y36: 0 | Z36: 0 | AA36: 1 | AB36: 0 | AC36: 0 | AD36: 0 | AE36: 0 | AF36: 0 | AG36: 0 | AH36: 0 | AI36: 0 | AJ36: 0 | AK36: 0 | AL36: 0 | AM36: 0 | AP36: 1 | AQ36: A-M510 | AR36: 1CP
B37: =B36+1 | C37: 61072o | D37: 61072 | E37: =IF(D37="","",IFERROR(VLOOKUP(D37,CCN_Library!$A$4:$B$13,2,FALSE),"NOT IN LIBRARY")) | F37: =LEFT(H37,6) | G37: E | H37: M2826101598 | I37: MED DPT STF | J37: LT | K37: 2300 | L37: 2300 | M37: N | N37: O | O37: A | P37: A | R37: U | S37: P | U37: 0 | V37: 0 | W37: 0 | X37: 0 | Y37: 0 | Z37: 1 | AA37: 0 | AB37: 0 | AC37: 0 | AD37: 0 | AE37: 0 | AF37: 0 | AG37: 0 | AH37: 0 | AI37: 0 | AJ37: 0 | AK37: 0 | AL37: 0 | AM37: 0 | AP37: 1 | AQ37: A-M510 | AR37: 1CP
B38: =B37+1 | C38: 61072o | D38: 61072 | E38: =IF(D38="","",IFERROR(VLOOKUP(D38,CCN_Library!$A$4:$B$13,2,FALSE),"NOT IN LIBRARY")) | F38: =LEFT(H38,6) | G38: E | H38: M2826101049 | I38: CHIEF NURSING OFFICER | J38: CDR | K38: 2900 | L38: 2900 | M38: N | N38: O | O38: A | P38: A | R38: U | S38: P | U38: 0 | V38: 0 | W38: 0 | X38: 0 | Y38: 0 | Z38: 1 | AA38: 0 | AB38: 0 | AC38: 0 | AD38: 0 | AE38: 0 | AF38: 0 | AG38: 0 | AH38: 0 | AI38: 0 | AJ38: 0 | AK38: 0 | AL38: 0 | AM38: 0 | AP38: 1 | AQ38: A-M510 | AR38: 1CP
B39: =B38+1 | C39: 61072o | D39: 61072 | E39: =IF(D39="","",IFERROR(VLOOKUP(D39,CCN_Library!$A$4:$B$13,2,FALSE),"NOT IN LIBRARY")) | F39: =LEFT(H39,6) | G39: E | H39: M2826101050 | I39: EVACUATION CONTROL OFFICER | J39: LT | K39: 2900 | L39: 2900 | M39: N | N39: O | O39: A | P39: A | R39: U | S39: P | U39: 0 | V39: 0 | W39: 0 | X39: 0 | Y39: 0 | Z39: 1 | AA39: 0 | AB39: 0 | AC39: 0 | AD39: 0 | AE39: 0 | AF39: 0 | AG39: 0 | AH39: 0 | AI39: 0 | AJ39: 0 | AK39: 0 | AL39: 0 | AM39: 0 | AP39: 1 | AQ39: A-M510 | AR39: 1CP
B40: =B39+1 | C40: 61072o | D40: 61072 | E40: =IF(D40="","",IFERROR(VLOOKUP(D40,CCN_Library!$A$4:$B$13,2,FALSE),"NOT IN LIBRARY")) | F40: =LEFT(H40,6) | G40: E | H40: M2826101051 | I40: FLD MED TECH | J40: HMC | K40: L03A | L40: L03A | M40: N | N40: E | O40: A | P40: A | R40: U | S40: P | U40: 0 | V40: 0 | W40: 0 | X40: 0 | Y40: 0 | Z40: 0 | AA40: 1 | AB40: 0 | AC40: 0 | AD40: 0 | AE40: 0 | AF40: 0 | AG40: 0 | AH40: 0 | AI40: 0 | AJ40: 0 | AK40: 0 | AL40: 0 | AM40: 0 | AP40: 1 | AQ40: A-M510 | AR40: 1CP
...

Sheet TE
B1: ROW | C1: NOTE | D1: CCN | E1: CCN Description | F1: CCN 21451 Equipment Type (if applicable) | G1: UIC | H1: TAMCN Short | I1: TAMCN | J1: Nomenclature (Name - Model) | K1: TAM Stat | L1: U/I | M1: Rdy | N1: Ind Qty | O1: Org Qty | P1: Unit T/E | Q1: L, Ft | R1: W, Ft | S1: H, Ft | T1: Volume Ea, ft3 | U1: Volume Total, ft3
B2: 3 | C2: 14345 | D2: 14345 | E2: =IF(D2="","",IFERROR(VLOOKUP(D2,CCN_Library!$A$4:$B$13,2,FALSE),"NOT IN LIBRARY")) | G2: M28261 | H2: =LEFT(I2,5) | I2: E00302M | J2: PISTOL,9 MILLIMETER-M18 | K2: IS | L2: EA | M2: N | N2: 99 | O2: 12 | P2: 111 | Q2: 0.6 | R2: 0.13 | S2: 0.13 | T2: =Q2*R2*S2 | U2: =T2*P2
B3: 4 | C3: 44112 | D3: 44112 | E3: =IF(D3="","",IFERROR(VLOOKUP(D3,CCN_Library!$A$4:$B$13,2,FALSE),"NOT IN LIBRARY")) | G3: M28261 | H3: =LEFT(I3,5) | I3: K00012B | J3: CHARGER,BATTERY-PCWV+ | K3: IS | L3: EA | M3: N | N3: 0 | O3: 2 | P3: 2 | Q3: 0.96 | R3: 0.85 | S3: 0.58 | T3: =Q3*R3*S3 | U3: =T3*P3
B4: 5 | C4: 21710 | D4: 21710 | E4: =IF(D4="","",IFERROR(VLOOKUP(D4,CCN_Library!$A$4:$B$13,2,FALSE),"NOT IN LIBRARY")) | G4: M28261 | H4: =LEFT(I4,5) | I4: A20427G | J4: RADIO SET-AN/PRC-150 (C) | K4: DP | L4: EA | M4: N | N4: 0 | O4: 3 | P4: 3 | Q4: 1.12 | R4: 0.87 | S4: 0.25 | T4: =Q4*R4*S4 | U4: =T4*P4
B5: 11 | C5: 44112 | D5: 44112 | E5: =IF(D5="","",IFERROR(VLOOKUP(D5,CCN_Library!$A$4:$B$13,2,FALSE),"NOT IN LIBRARY")) | G5: M28261 | H5: =LEFT(I5,5) | I5: C30202E | J5: INSERTS,ENHANCED SM- CO/PD 04-10 | K5: IS | L5: EA | M5: N | N5: 610 | O5: 0 | P5: 610 | Q5: 1.17 | R5: 1.17 | S5: 0.08 | T5: =Q5*R5*S5 | U5: =T5*P5
B6: 12 | C6: 44112 | D6: 44112 | E6: =IF(D6="","",IFERROR(VLOOKUP(D6,CCN_Library!$A$4:$B$13,2,FALSE),"NOT IN LIBRARY")) | G6: M28261 | H6: =LEFT(I6,5) | I6: C34232E | J6: STAND,CANTEEN CUP-MIL-S-44221 | K6: IS | L6: EA | M6: N | N6: 305 | O6: 0 | P6: 305 | Q6: 0.17 | R6: 0.33 | S6: 0.25 | T6: =Q6*R6*S6 | U6: =T6*P6
B7: 16 | C7: 14345 | D7: 14345 | E7: =IF(D7="","",IFERROR(VLOOKUP(D7,CCN_Library!$A$4:$B$13,2,FALSE),"NOT IN LIBRARY")) | G7: M28261 | H7: =LEFT(I7,5) | I7: E01902M | J7: CARBINE,5.56 MILLIM-M4A1 | K7: IS | L7: EA | M7: N | N7: 0 | O7: 0 | P7: 0 | Q7: 2.75 | R7: 0.17 | S7: 0.75 | T7: =Q7*R7*S7 | U7: =T7*P7
B8: 19 | C8: 14345 | D8: 14345 | E8: =IF(D8="","",IFERROR(VLOOKUP(D8,CCN_Library!$A$4:$B$13,2,FALSE),"NOT IN LIBRARY")) | G8: M28261 | H8: =LEFT(I8,5) | I8: E28292E | J8: TOOL KIT,ORGANIZATI- | K8: IS | L8: EA | M8: N | N8: 0 | O8: 1 | P8: 1 | Q8: 1 | R8: 0.5 | S8: 0.58 | T8: =Q8*R8*S8 | U8: =T8*P8
B9: 20 | C9: 44112 | D9: 44112 | E9: =IF(D9="","",IFERROR(VLOOKUP(D9,CCN_Library!$A$4:$B$13,2,FALSE),"NOT IN LIBRARY")) | G9: M28261 | H9: =LEFT(I9,5) | I9: K41282E | J9: CAN,MILITARY- | K9: IS | L9: EA | M9: N | N9: 0 | O9: 52 | P9: 52 | Q9: 0 | R9: 0 | S9: 0 | T9: =Q9*R9*S9 | U9: =T9*P9
B10: 21 | C10: 44112 | D10: 44112 | E10: =IF(D10="","",IFERROR(VLOOKUP(D10,CCN_Library!$A$4:$B$13,2,FALSE),"NOT IN LIBRARY")) | G10: M28261 | H10: =LEFT(I10,5) | I10: K42362E | J10: COT,FOLDING-2-5-72 | K10: IS | L10: EA | M10: N | N10: 0 | O10: 168 | P10: 168 | Q10: 2 | R10: 0.5 | S10: 0.33 | T10: =Q10*R10*S10 | U10: =T10*P10
B11: 23 | C11: 44112 | D11: 44112 | E11: =IF(D11="","",IFERROR(VLOOKUP(D11,CCN_Library!$A$4:$B$13,2,FALSE),"NOT IN LIBRARY")) | G11: M28261 | H11: =LEFT(I11,5) | I11: K49592E | J11: TABLE,FOLDING LEGS- MILT3338 | K11: IS | L11: EA | M11: N | N11: 0 | O11: 12 | P11: 12 | Q11: 5.83 | R11: 3 | S11: 0.33 | T11: =Q11*R11*S11 | U11: =T11*P11
B12: 30 | C12: 44112 | D12: 44112 | E12: =IF(D12="","",IFERROR(VLOOKUP(D12,CCN_Library!$A$4:$B$13,2,FALSE),"NOT IN LIBRARY")) | G12: M28261 | H12: =LEFT(I12,5) | I12: C79112B | J12: SHOP EQUIPMENT,UTIL-USMC24-1000 | K12: IS | L12: EA | M12: N | N12: 0 | O12: 1 | P12: 1 | Q12: 4.83 | R12: 2.75 | S12: 5.41 | T12: =Q12*R12*S12 | U12: =T12*P12
B13: 34 | C13: 44112 | D13: 44112 | E13: =IF(D13="","",IFERROR(VLOOKUP(D13,CCN_Library!$A$4:$B$13,2,FALSE),"NOT IN LIBRARY")) | G13: M28261 | H13: =LEFT(I13,5) | I13: C11202F | J13: GLOVE INSERTS,COLD-70113 | K13: IS | L13: PR | M13: N | N13: 610 | O13: 540 | P13: 1150 | Q13: 1 | R13: 0.5 | S13: 0.08 | T13: =Q13*R13*S13 | U13: =T13*P13
... B23: 58 | C23: 21710 | D23: 21710 | E23: =IF(D23="","",IFERROR(VLOOKUP(D23,CCN_Library!$A$4:$B$13,2,FALSE),"NOT IN LIBRARY")) | G23: M28261 | H23: =LEFT(I23,5) | I23: A01357G | J23: RADIO SET-AN/VRC-112 | K23: DP | L23: EA | M23: N | N23: 0 | O23: 26 | P23: 26 | Q23: 0.89 | R23: 0.62 | S23: 0.89 | T23: =Q23*R23*S23 | U23: =T23*P23
B24: 63 | C24: 21710 | D24: 21710 | E24: =IF(D24="","",IFERROR(VLOOKUP(D24,CCN_Library!$A$4:$B$13,2,FALSE),"NOT IN LIBRARY")) | G24: M28261 | H24: =LEFT(I24,5) | I24: A80017GA | J24: ENCRYPTION-DECRYPTI-KGV-72 | K24: IS | L24: EA | N24: 0 | O24: 30 | P24: 30 | Q24: 0.67 | R24: 0.25 | S24: 0.42 | T24: =Q24*R24*S24 | U24: =T24*P24
B25: 65 | C25: 21710 | D25: 21710 | E25: =IF(D25="","",IFERROR(VLOOKUP(D25,CCN_Library!$A$4:$B$13,2,FALSE),"NOT IN LIBRARY")) | G25: M28261 | H25: =LEFT(I25,5) | I25: A00227G | J25: COMPUTER SYSTEM,DIG-16007A0000 | K25: IS | L25: EA | M25: N | N25: 0 | O25: 30 | P25: 30 | Q25: 1.75 | R25: 1.42 | S25: 1.42 | T25: =Q25*R25*S25 | U25: =T25*P25
B26: 70 | C26: 21451 | D26: 21451 | E26: =IF(D26="","",IFERROR(VLOOKUP(D26,CCN_Library!$A$4:$B$13,2,FALSE),"NOT IN LIBRARY")) | G26: M28261 | H26: =LEFT(I26,5) | I26: D00062B | J26: SPECIAL TOOL KIT,FI-4406836 | K26: IS | M26: N | N26: 0 | O26: 1 | P26: 1 | S26: 0 | T26: =Q26*R26*S26 | U26: =T26*P26
B27: 74 | C27: 14345 | D27: 14345 | E27: =IF(D27="","",IFERROR(VLOOKUP(D27,CCN_Library!$A$4:$B$13,2,FALSE),"NOT IN LIBRARY")) | G27: M28261 | H27: =LEFT(I27,5) | I27: E02022B | J27: TELESCOPE,STRAIGHT-M317 | K27: IS | L27: EA | M27: R | N27: 0 | O27: 0 | P27: 0 | S27: 0 | T27: =Q27*R27*S27 | U27: =T27*P27
B28: 76 | C28: 14312 | D28: 14312 | E28: =IF(D28="","",IFERROR(VLOOKUP(D28,CCN_Library!$A$4:$B$13,2,FALSE),"NOT IN LIBRARY")) | G28: M28261 | H28: =LEFT(I28,5) | I28: B07307B | J28: GENERATOR SET,DIESE-MEP831A | K28: IS | L28: EA | M28: M | N28: 0 | O28: 21 | P28: 21 | Q28: 2.9 | R28: 2.32 | S28: 2.21 | T28: =Q28*R28*S28 | U28: =T28*P28
B29: 77 | C29: 14345 | D29: 14345 | E29: =IF(D29="","",IFERROR(VLOOKUP(D29,CCN_Library!$A$4:$B$13,2,FALSE),"NOT IN LIBRARY")) | G29: M28261 | H29: =LEFT(I29,5) | I29: E00172B | J29: SIGHT,BORE,OPTICAL-M7 | K29: IS | L29: EA | M29: N | N29: 143 | O29: 0 | P29: 143 | Q29: 0.5 | R29: 0.17 | S29: 0.08 | T29: =Q29*R29*S29 | U29: =T29*P29
B30: 79 | C30: 44112 | D30: 44112 | E30: =IF(D30="","",IFERROR(VLOOKUP(D30,CCN_Library!$A$4:$B$13,2,FALSE),"NOT IN LIBRARY")) | G30: M28261 | H30: =LEFT(I30,5) | I30: C30602E | J30: CANTEEN,WATER-MIL-C-43103 | K30: IS | L30: EA | M30: N | N30: 610 | O30: 0 | P30: 610 | Q30: 0.08 | R30: 0.25 | S30: 0.42 | T30: =Q30*R30*S30 | U30: =T30*P30
B31: 85 | C31: 14345 | D31: 14345 | E31: =IF(D31="","",IFERROR(VLOOKUP(D31,CCN_Library!$A$4:$B$13,2,FALSE),"NOT IN LIBRARY")) | G31: M28261 | H31: =LEFT(I31,5) | I31: C32502E | J31: KNIFE,COMBAT-MIL-K-20277 | K31: IS | L31: EA | M31: N | N31: 0 | O31: 0 | P31: 0 | Q31: 0.75 | R31: 0.17 | S31: 0.08 | T31: =Q31*R31*S31 | U31: =T31*P31
B32: 87 | C32: 21451 | D32: 21451 | E32: =IF(D32="","",IFERROR(VLOOKUP(D32,CCN_Library!$A$4:$B$13,2,FALSE),"NOT IN LIBRARY")) | G32: M28261 | H32: =LEFT(I32,5) | I32: D00012BA | J32: ACCESSORY KIT,VEHIC-57K8831 | K32: PL | L32: EA | N32: 0 | O32: 4 | P32: 4 | S32: 0 | T32: =Q32*R32*S32 | U32: =T32*P32
B33: 88 | C33: 44112 | D33: 44112 | E33: =IF(D33="","",IFERROR(VLOOKUP(D33,CCN_Library!$A$4:$B$13,2,FALSE),"NOT IN LIBRARY")) | G33: M28261 | H33: =LEFT(I33,5) | I33: C86148A | J33: X-RAY EQUIP AMAL627-W | K33: IS | M33: N | N33: 0 | O33: 2 | P33: 2 | Q33: 5.58 | R33: 2.42 | S33: 2.33 | T33: =Q33*R33*S33 | U33: =T33*P33
B34: 89 | C34: 44112 | D34: 44112 | E34: =IF(D34="","",IFERROR(VLOOKUP(D34,CCN_Library!$A$4:$B$13,2,FALSE),"NOT IN LIBRARY")) | G34: M28261 | H34: =LEFT(I34,5) | I34: C86248A | J34: AMAL 631 SURGICAL T-AMAL 631 | K34: IS | M34: R | N34: 0 | O34: 2 | P34: 2 | Q34: 8 | R34: 4.58 | S34: 5 | T34: =Q34*R34*S34 | U34: =T34*P34
B35: 97 | C35: 44112 | D35: 44112 | E35: =IF(D35="","",IFERROR(VLOOKUP(D35,CCN_Library!$A$4:$B$13,2,FALSE),"NOT IN LIBRARY")) | G35: M28261 | H35: =LEFT(I35,5) | I35: K49572E | J35: -34" | K35: IS | M35: N | N35: 0 | O35: 13 | P35: 13 | Q35: 2.83 | R35: 0.33 | S35: 0.17 | T35: =Q35*R35*S35 | U35: =T35*P35
B36: 101 | C36: 44112 | D36: 44112 | E36: =IF(D36="","",IFERROR(VLOOKUP(D36,CCN_Library!$A$4:$B$13,2,FALSE),"NOT IN LIBRARY")) | G36: M28261 | H36: =LEFT(I36,5) | I36: B00277B | J36: PANEL,POWER DISTRIB-5KW INDOOR | K36: IS | L36: EA | M36: R | N36: 0 | O36: 6 | P36: 6 | Q36: 1.58 | R36: 1.5 | S36: 1.17 | T36: =Q36*R36*S36 | U36: =T36*P36
B37: 105 | C37: 44112 | D37: 44112 | E37: =IF(D37="","",IFERROR(VLOOKUP(D37,CCN_Library!$A$4:$B$13,2,FALSE),"NOT IN LIBRARY")) | G37: M28261 | H37: =LEFT(I37,5) | I37: C21502F | J37: GLOVE INSERTS,NUCLE-DSSPM330-01 | K37: IS | L37: PR | M37: N | N37: 610 | O37: 0 | P37: 610 | Q37: 1.67 | R37: 0.67 | S37: 0.17 | T37: =Q37*R37*S37 | U37: =T37*P37
B38: 106 | C38: 21451 | D38: 21451 | E38: =IF(D38="","",IFERROR(VLOOKUP(D38,CCN_Library!$A$4:$B$13,2,FALSE),"NOT IN LIBRARY")) | G38: M28261 | H38: =LEFT(I38,5) | I38: D00037K | J38: TRUCK,ARMORED,CARGO-AMK23A1 | K38: IS | L38: EA | M38: R | N38: 0 | O38: 4 | P38: 4 | Q38: 26.24 | R38: 8.16 | S38: 8.16 | T38: =Q38*R38*S38 | U38: =T38*P38
B39: 107 | C39: 44112 | D39: 44112 | E39: =IF(D39="","",IFERROR(VLOOKUP(D39,CCN_Library!$A$4:$B$13,2,FALSE),"NOT IN LIBRARY")) | G39: M28261 | H39: =LEFT(I39,5) | I39: C21702E | J39: SPECTACLES,INDUSTRI- | K39: IS | L39: EA | M39: N | N39: 305 | O39: 0 | P39: 305 | Q39: 0.58 | R39: 0.33 | S39: 0.25 | T39: =Q39*R39*S39 | U39: =T39*P39
B40: 116 | C40: 44112 | D40: 44112 | E40: =IF(D40="","",IFERROR(VLOOKUP(D40,CCN_Library!$A$4:$B$13,2,FALSE),"NOT IN LIBRARY")) | G40: M28261 | H40: =LEFT(I40,5) | I40: B00087B | J40: AIR CONDITIONER-GL0583ZAADWYX11 | K40: IS | L40: EA | M40: R | N40: 0 | O40: 2 | P40: 2 | Q40: 3.97 | R40: 3.08 | S40: 3.95 | T40: =Q40*R40*S40 | U40: =T40*P40
B41: 118 | C41: 14345 | D41: 14345 | E41: =IF(D41="","",IFERROR(VLOOKUP(D41,CCN_Library!$A$4:$B$13,2,FALSE),"NOT IN LIBRARY")) | G41: M28261 | H41: =LEFT(I41,5) | I41: K42222E | J41: COMPASS,MAGNETIC,UN-S AND Y 183 | K41: IS | L41: EA | M41: N | N41: 0 | O41: 8 | P41: 8 | Q41: 0.25 | R41: 0.25 | S41: 0.08 | T41: =Q41*R41*S41 | U41: =T41*P41
B42: 123 | C42: 44112 | D42: 44112 | E42: =IF(D42="","",IFERROR(VLOOKUP(D42,CCN_Library!$A$4:$B$13,2,FALSE),"NOT IN LIBRARY")) | G42: M28261 | H42: =LEFT(I42,5) | I42: C01692F | J42: MAT,SLEEPING-ISM | K42: IS | L42: EA | M42: N | N42: 305 | O42: 0 | P42: 305 | Q42: 0 | R42: 0 | S42: 0 | T42: =Q42*R42*S42 | U42: =T42*P42
B43: 124 | C43: 14345 | D43: 14345 | E43: =IF(D43="","",IFERROR(VLOOKUP(D43,CCN_Library!$A$4:$B$13,2,FALSE),"NOT IN LIBRARY")) | G43: M28261 | H43: =LEFT(I43,5) | I43: E79007B | J43: TOOL KIT,SMALL ARMS-TK-2111A | K43: IS | L43: KT | M43: N | N43: 0 | O43: 2 | P43: 2 | Q43: 2.08 | R43: 1.67 | S43: 1 | T43: =Q43*R43*S43 | U43: =T43*P43
B44: 125 | C44: 44112 | D44: 44112 | E44: =IF(D44="","",IFERROR(VLOOKUP(D44,CCN_Library!$A$4:$B$13,2,FALSE),"NOT IN LIBRARY")) | G44: M28261 | H44: =LEFT(I44,5) | I44: C54402F | J44: FIELD PACK-F190186393 | K44: IS | L44: EA | M44: N | N44: 305 | O44: 0 | P44: 305 | Q44: 1.33 | R44: 0.67 | S44: 1 | T44: =Q44*R44*S44 | U44: =T44*P44
B45: 126 | C45: 21451 | D45: 21451 | E45: =IF(D45="","",IFERROR(VLOOKUP(D45,CCN_Library!$A$4:$B$13,2,FALSE),"NOT IN LIBRARY")) | G45: M28261 | H45: =LEFT(I45,5) | I45: D00457K | J45: TRUCK,UTILITY-M1280A1 | K45: IS | L45: EA | M45: R | N45: 0 | O45: 4 | P45: 4 | S45: 0 | T45: =Q45*R45*S45 | U45: =T45*P45
B46: 128 | C46: 44112 | D46: 44112 | E46: =IF(D46="","",IFERROR(VLOOKUP(D46,CCN_Library!$A$4:$B$13,2,FALSE),"NOT IN LIBRARY")) | G46: M28261 | H46: =LEFT(I46,5) | I46: C44312E | J46: BOX,SHIPPING-102440 | K46: IS | L46: EA | M46: N | N46: 0 | O46: 100 | P46: 100 | Q46: 4 | R46: 3.33 | S46: 4 | T46: =Q46*R46*S46 | U46: =T46*P46
B47: 132 | C47: 44112 | D47: 44112 | E47: =IF(D47="","",IFERROR(VLOOKUP(D47,CCN_Library!$A$4:$B$13,2,FALSE),"NOT IN LIBRARY")) | G47: M28261 | H47: =LEFT(I47,5) | I47: A90157G | J47: THEATER MEDICAL INF-EVO73AV | K47: IS | L47: EA | M47: N | N47: 0 | O47: 17 | P47: 17 | Q47: 1.11 | R47: 1.11 | S47: 0.08 | T47: =Q47*R47*S47 | U47: =T47*P47
B48: 133 | C48: 21710 | D48: 21710 | E48: =IF(D48="","",IFERROR(VLOOKUP(D48,CCN_Library!$A$4:$B$13,2,FALSE),"NOT IN LIBRARY")) | G48: M28261 | H48: =LEFT(I48,5) | I48: A01187G | J48: RADIO SET-AN/PRC-153(V)1 | K48: DP | L48: EA | M48: N | N48: 0 | O48: 60 | P48: 60 | Q48: 0.57 | R48: 0.22 | S48: 0.57 | T48: =Q48*R48*S48 | U48: =T48*P48
B49: 135 | C49: 14345 | D49: 14345 | E49: =IF(D49="","",IFERROR(VLOOKUP(D49,CCN_Library!$A$4:$B$13,2,FALSE),"NOT IN LIBRARY")) | G49: M28261 | H49: =LEFT(I49,5) | I49: E01877B | J49: SIGHT,NIGHT VISION-1019765-101 | K49: IS | L49: KT | M49: R | N49: 0 | O49: 0 | P49: 0 | Q49: 0.8 | R49: 0.32 | S49: 0.37 | T49: =Q49*R49*S49 | U49: =T49*P49
...

Sheet 14312
A1: BASIC FACILITY REQUIREMENTS WORKSHEET
A3: Installation: | F3: MCB Camp Butler | M3: Tenant: | R3: 3D MED BN
A4: Installation UIC: | F4: M67400 | M4: Tenant UIC: | R4: M13020 | Y4: Planning Area: | AE4: FO
A5: CCN: | C5: 14312 | M5: Nomenclature: | R5: Operational Vehicle Laydown Area
A6: LOADING ANALYSIS / JUSTIFICATION OF REQUIREMENT
A7: Description:
B8: Mission: Provide health service support to the Marine expeditionary force (MEF). CCN: An operational vehicle parking and/or laydown area consists of an asphalt or concrete paved area large enough to store and provide circulation for the vehicles and equipment for which the command is responsible. Justification: An Operational Vehicle Laydown Area is required to store and provide circulation for the vehicles and equipment for which the command is responsible.
A14: Planning Criteria:
B15: UFC 2-000-05N
A16: Loading:
B17: FY2025 Table of Organization
B18: FY2025 Table of Equipment
A19: Analysis:
B20: Subordinate Unit | M20: Area1
B21: M28261 | E21: H&S CO | M21: =AB218
B22: M28263 | E22: SURGICAL CO A | M22: =AB402
B23: M28262 | E23: SURGICAL CO B | M23: =AB586
M24: =AB770
B25: Totals = | M25: =SUM(M21:P24)
B28: SEE THE ATTACHED PAGES FOR CALCULATIONS
B30: 1All vehicles are assigned a type code (A through E) based on its length, per guidelines from UFC 2-000-05N, Table 14312-1. A vehicle's type code determines its space allowance and net-to-gross factor. The total space requirement is the sum of the gross areas of all vehicles and equipment for which the command is responsible.
A36: TOTAL REQUIREMENT: | H36: =M25 | L36: SY
A37: CCN: | C37: =$C$5 | M37: Nomenclature: | R37: =$R$5
C39: Operational Vehicle Laydown Area per UFC 2-000-05N Table 14312-1
C40: =B21 | F40: =E21
C41: TAMCN | F41: Description | U41: L (FT) | W41: Qty | Y41: Area (NSY) | AA41: NTG | AC41: GSY
C43: A00477B | F43: =IFERROR(VLOOKUP(C43,TE!$H:$Y,2,FALSE),"(Not on TE)") | U43: =IFERROR(VLOOKUP(C43,TE!$H:$Y,9,FALSE),"0") | W43: =SUMIFS(TE!$O:$O,TE!$G:$G,$C$40,TE!$I:$I,C43,TE!$D:$D,$C$5) | Y43: =IFERROR(VLOOKUP(C43,TE!$H:$Y,16,FALSE),"0") | AA43: =IFERROR(VLOOKUP(C43,TE!$H:$Y,17,FALSE),"0") | AC43: =IFERROR((W43*Y43*AA43),"")
C44: A00557G | F44: =IFERROR(VLOOKUP(C44,TE!$H:$Y,2,FALSE),"(Not on TE)") | U44: =IFERROR(VLOOKUP(C44,TE!$H:$Y,9,FALSE),"0") | W44: =SUMIFS(TE!$O:$O,TE!$G:$G,$C$40,TE!$I:$I,C44,TE!$D:$D,$C$5) | Y44: =IFERROR(VLOOKUP(C44,TE!$H:$Y,16,FALSE),"0") | AA44: =IFERROR(VLOOKUP(C44,TE!$H:$Y,17,FALSE),"0") | AC44: =IFERROR((W44*Y44*AA44),"")
C45: A00617G | F45: =IFERROR(VLOOKUP(C45,TE!$H:$Y,2,FALSE),"(Not on TE)") | U45: =IFERROR(VLOOKUP(C45,TE!$H:$Y,9,FALSE),"0") | W45: =SUMIFS(TE!$O:$O,TE!$G:$G,$C$40,TE!$I:$I,C45,TE!$D:$D,$C$5) | Y45: =IFERROR(VLOOKUP(C45,TE!$H:$Y,16,FALSE),"0") | AA45: =IFERROR(VLOOKUP(C45,TE!$H:$Y,17,FALSE),"0") | AC45: =IFERROR((W45*Y45*AA45),"")
C46: A02427G | F46: =IFERROR(VLOOKUP(C46,TE!$H:$Y,2,FALSE),"(Not on TE)") | U46: =IFERROR(VLOOKUP(C46,TE!$H:$Y,9,FALSE),"0") | W46: =SUMIFS(TE!$O:$O,TE!$G:$G,$C$40,TE!$I:$I,C46,TE!$D:$D,$C$5) | Y46: =IFERROR(VLOOKUP(C46,TE!$H:$Y,16,FALSE),"0") | AA46: =IFERROR(VLOOKUP(C46,TE!$H:$Y,17,FALSE),"0") | AC46: =IFERROR((W46*Y46*AA46),"")
C47: A03877G | F47: =IFERROR(VLOOKUP(C47,TE!$H:$Y,2,FALSE),"(Not on TE)") | U47: =IFERROR(VLOOKUP(C47,TE!$H:$Y,9,FALSE),"0") | W47: =SUMIFS(TE!$O:$O,TE!$G:$G,$C$40,TE!$I:$I,C47,TE!$D:$D,$C$5) | Y47: =IFERROR(VLOOKUP(C47,TE!$H:$Y,16,FALSE),"0") | AA47: =IFERROR(VLOOKUP(C47,TE!$H:$Y,17,FALSE),"0") | AC47: =IFERROR((W47*Y47*AA47),"")
C48: A03887G | F48: =IFERROR(VLOOKUP(C48,TE!$H:$Y,2,FALSE),"(Not on TE)") | U48: =IFERROR(VLOOKUP(C48,TE!$H:$Y,9,FALSE),"0") | W48: =SUMIFS(TE!$O:$O,TE!$G:$G,$C$40,TE!$I:$I,C48,TE!$D:$D,$C$5) | Y48: =IFERROR(VLOOKUP(C48,TE!$H:$Y,16,FALSE),"0") | AA48: =IFERROR(VLOOKUP(C48,TE!$H:$Y,17,FALSE),"0") | AC48: =IFERROR((W48*Y48*AA48),"")
C49: A04037G | F49: =IFERROR(VLOOKUP(C49,TE!$H:$Y,2,FALSE),"(Not on TE)") | U49: =IFERROR(VLOOKUP(C49,TE!$H:$Y,9,FALSE),"0") | W49: =SUMIFS(TE!$O:$O,TE!$G:$G,$C$40,TE!$I:$I,C49,TE!$D:$D,$C$5) | Y49: =IFERROR(VLOOKUP(C49,TE!$H:$Y,16,FALSE),"0") | AA49: =IFERROR(VLOOKUP(C49,TE!$H:$Y,17,FALSE),"0") | AC49: =IFERROR((W49*Y49*AA49),"")
C50: A04577G | F50: =IFERROR(VLOOKUP(C50,TE!$H:$Y,2,FALSE),"(Not on TE)") | U50: =IFERROR(VLOOKUP(C50,TE!$H:$Y,9,FALSE),"0") | W50: =SUMIFS(TE!$O:$O,TE!$G:$G,$C$40,TE!$I:$I,C50,TE!$D:$D,$C$5) | Y50: =IFERROR(VLOOKUP(C50,TE!$H:$Y,16,FALSE),"0") | AA50: =IFERROR(VLOOKUP(C50,TE!$H:$Y,17,FALSE),"0") | AC50: =IFERROR((W50*Y50*AA50),"")
C51: A04587G | F51: =IFERROR(VLOOKUP(C51,TE!$H:$Y,2,FALSE),"(Not on TE)") | U51: =IFERROR(VLOOKUP(C51,TE!$H:$Y,9,FALSE),"0") | W51: =SUMIFS(TE!$O:$O,TE!$G:$G,$C$40,TE!$I:$I,C51,TE!$D:$D,$C$5) | Y51: =IFERROR(VLOOKUP(C51,TE!$H:$Y,16,FALSE),"0") | AA51: =IFERROR(VLOOKUP(C51,TE!$H:$Y,17,FALSE),"0") | AC51: =IFERROR((W51*Y51*AA51),"")
C52: A19577G | F52: =IFERROR(VLOOKUP(C52,TE!$H:$Y,2,FALSE),"(Not on TE)") | U52: =IFERROR(VLOOKUP(C52,TE!$H:$Y,9,FALSE),"0") | W52: =SUMIFS(TE!$O:$O,TE!$G:$G,$C$40,TE!$I:$I,C52,TE!$D:$D,$C$5) | Y52: =IFERROR(VLOOKUP(C52,TE!$H:$Y,16,FALSE),"0") | AA52: =IFERROR(VLOOKUP(C52,TE!$H:$Y,17,FALSE),"0") | AC52: =IFERROR((W52*Y52*AA52),"")
C53: A21797G | F53: =IFERROR(VLOOKUP(C53,TE!$H:$Y,2,FALSE),"(Not on TE)") | U53: =IFERROR(VLOOKUP(C53,TE!$H:$Y,9,FALSE),"0") | W53: =SUMIFS(TE!$O:$O,TE!$G:$G,$C$40,TE!$I:$I,C53,TE!$D:$D,$C$5) | Y53: =IFERROR(VLOOKUP(C53,TE!$H:$Y,16,FALSE),"0") | AA53: =IFERROR(VLOOKUP(C53,TE!$H:$Y,17,FALSE),"0") | AC53: =IFERROR((W53*Y53*AA53),"")
C54: A23352B | F54: =IFERROR(VLOOKUP(C54,TE!$H:$Y,2,FALSE),"(Not on TE)") | U54: =IFERROR(VLOOKUP(C54,TE!$H:$Y,9,FALSE),"0") | W54: =SUMIFS(TE!$O:$O,TE!$G:$G,$C$40,TE!$I:$I,C54,TE!$D:$D,$C$5) | Y54: =IFERROR(VLOOKUP(C54,TE!$H:$Y,16,FALSE),"0") | AA54: =IFERROR(VLOOKUP(C54,TE!$H:$Y,17,FALSE),"0") | AC54: =IFERROR((W54*Y54*AA54),"")
... C79: B02157BA | F79: =IFERROR(VLOOKUP(C79,TE!$H:$Y,2,FALSE),"(Not on TE)") | U79: =IFERROR(VLOOKUP(C79,TE!$H:$Y,9,FALSE),"0") | W79: =SUMIFS(TE!$O:$O,TE!$G:$G,$C$40,TE!$I:$I,C79,TE!$D:$D,$C$5) | Y79: =IFERROR(VLOOKUP(C79,TE!$H:$Y,16,FALSE),"0") | AA79: =IFERROR(VLOOKUP(C79,TE!$H:$Y,17,FALSE),"0") | AC79: =IFERROR((W79*Y79*AA79),"")
AA80: Continued Below
...

Sheet 14345
A1: BASIC FACILITY REQUIREMENTS WORKSHEET
A3: Installation: | G3: =UNIT_ROLLUP!F3 | M3: Tenant: | R3: =UNIT_ROLLUP!R3
A4: Installation UIC: | G4: =UNIT_ROLLUP!F4 | M4: Tenant UIC: | R4: =UNIT_ROLLUP!R4 | Y4: Planning Area: | AE4: =UNIT_ROLLUP!AE4
A5: CCN: | C5: 14345 | M5: Nomenclature: | R5: Armory
A6: LOADING ANALYSIS / JUSTIFICATION OF REQUIREMENT
A7: Description:
B8: Mission: Provide health service support to the III Marine expeditionary force (IIIMEF). CCN: Provides space for storage and routine maintenance of small arms. Justification: Armory space is required for the maintenance and storage of weapons and serialized equipment for which the command is responsible.
A14: Planning Criteria:
B15: FC 2-000-05N
B16: NAVFAC Infrastructure Reset BFR Consistency Guide
A18: Loading:
B19: FY2029 Table of Organization & Equipment (attached)
B20: M28262 Surgical Co B per CG MCIPAC endorsement 30 Apr 2026 relocating to MCB Camp Butler; included in this BFR Calculation.
B21: Interview walkthrough with 3D Medical Battalion, S-4 Logistics OIC on October 30, 2024.
A22: Analysis:
B23: Total Space Requirement Armory storage is managed at the battalion level.
B24: Storage1,2 | G24: Largest Co. | K24: Cleaning Area3 | P24: Total
B25: =Q32 | G25: =COUNTIFS(TO!G:G,"E",TO!F:F,"M28261") | K25: =G25*10 | P25: =B25+K25
B27: Storage See the attached UFC standard 143-45_MC_Armory.xls spreadsheet. Modified to include add'l TAMCNs
B28: Subordinate Unit | M28: Weapon Storage (NSF) | Q28: Gross SF
Q29: 1.28
B30: M28261 | E30: H&S CO | M30: =Z420 | Q30: =M30*$Q$29
B31: M28263 | E31: SURGICAL CO A | M31: =Z803 | Q31: =M31*$Q$29
P32: Total = | Q32: =SUM(Q30:T31)
B34: 1 Accounts for storage of weapons and related items, stored on racks and shelves in cages. See attached TE for item description. 2 Per the standard armory worksheet, each battalion requires a separate maintenance area, including desk/work space for armorers. Armory officers and chiefs, listed as 14345o on the TO, are afforded 120 GSF of office space. All other armorers, listed as 14345a on the TO, receive 105 GSF of space. See attached TO for billet breakdown. A standardized 134.2 GSF is added to accommodate personal weapon storage, locker storage, a hazmat locker and a safe. 3 Each battalion owns exterior, unenclosed, covered space for a weapons cleaning area, calculated as 10GSF/per PN for the largest company in the standard armory spreadsheet. Therefore, the space is calculated as 10GSF *252 PN (M28261).
A40: TOTAL REQUIREMENT: | H40: 576 | L40: GSF | AC40: Page | AD40: 1 | AE40: of | AF40: 27
A41: CCN: | C41: 14345 | M41: Nomenclature: | R41: Armory
A42: Spreadsheet derived from the UFC standard 143-45_MC_Armory.xls spreadsheet
A43: =B30 | D43: =E30
A44: TAM # | D44: DESCRIPTION | M44: No. | O44: No. per Unit | Q44: STORAGE UNITS | S44: SF PER UNIT | U44: Total (NSF) | W44: STORAGE TYPE | Y44: METHOD OF STORAGE (RACK, CABINET, SHELF, ETC.)
A47: A0152 | D47: Viewer, Night Vision-Recon M18 SWIR | M47: =SUMIFS(TE!P:P,TE!G:G,$A$43,TE!H:H,A47) | O47: 12 | Q47: =M47/O47 | S47: 13.4 | U47: =Q47*S47 | W47: A1A | Y47: Stored on Configurable Shelf
A48: C0004 | D48: Night Hunter Flashlight | M48: =SUMIFS(TE!P:P,TE!G:G,$A$43,TE!H:H,A48) | O48: 50 | Q48: =M48/O48 | S48: 13.4 | U48: =Q48*S48 | W48: A1A | Y48: Stored on Configurable Shelf
A49: C3115 | D49: CASE, AMMO, SML ARMS, 30 RD, F/RIFLE, M16 | M49: =SUMIFS(TE!P:P,TE!G:G,$A$43,TE!H:H,A49) | O49: 90 | Q49: =M49/O49 | S49: 13.4 | U49: =Q49*S49 | W49: A1A | Y49: Stored on Configurable Shelf
A50: C3250 | D50: Knife, Combat, K-Bar | M50: =SUMIFS(TE!P:P,TE!G:G,$A$43,TE!H:H,A50) | O50: n/a | Q50: n/a | S50: n/a | U50: n/a | W50: Z1A | Y50: Most knives are hung on the gun rack, therefore the space is included in gun rack floor area.
A51: C4310 | D51: Carrier, Rocket, Lincloe, Pack Adapter | M51: =SUMIFS(TE!P:P,TE!G:G,$A$43,TE!H:H,A51) | O51: 16 | Q51: =M51/O51 | S51: 13.4 | U51: =Q51*S51 | W51: A1A | Y51: Stored on Configurable Shelf
A52: E0001 | D52: SIGHT,THERMAL - AN/PAS-25 | M52: =SUMIFS(TE!P:P,TE!G:G,$A$43,TE!H:H,A52) | O52: 12 | Q52: =M52/O52 | S52: 13.4 | U52: =Q52*S52 | W52: A1A | Y52: Stored on Configurable Shelf
A53: E0005 | D53: BINOCULAR NIGHT VISION SYSTEM | M53: =SUMIFS(TE!P:P,TE!G:G,$A$43,TE!H:H,A53) | O53: 2 | Q53: =M53/O53 | S53: 13.4 | U53: =Q53*S53 | W53: A1A | Y53: Stored on Configurable Shelf
A54: E0006 | D54: Integrated Pointer, Illum, Designator (IZLID) | M54: =SUMIFS(TE!P:P,TE!G:G,$A$43,TE!H:H,A54) | O54: 112 | Q54: =M54/O54 | S54: 13.4 | U54: =Q54*S54 | W54: A1A | Y54: Stored on Configurable Shelf
A55: E0008 | D55: Individual Weapon, Night Sight I2 (IWNS I2) | M55: =SUMIFS(TE!P:P,TE!G:G,$A$43,TE!H:H,A55) | O55: 112 | Q55: =M55/O55 | S55: 13.4 | U55: =Q55*S55 | W55: A1A | Y55: Design still not determined. Will be stored in Configurable Shelf
A56: E0012 | D56: Thermal Imager, Medium Range (MRTB) | M56: =SUMIFS(TE!P:P,TE!G:G,$A$43,TE!H:H,A56) | O56: 112 | Q56: =M56/O56 | S56: 13.4 | U56: =Q56*S56 | W56: A1A | Y56: Design still not determined. Will be stored in Configurable Shelf
...

Sheet 17110
A1: BASIC FACILITY REQUIREMENTS WORKSHEET
A3: Installation: | G3: =UNIT_ROLLUP!F3 | M3: Tenant: | R3: =UNIT_ROLLUP!R3
A4: Installation UIC: | G4: =UNIT_ROLLUP!F4 | M4: Tenant UIC: | R4: =UNIT_ROLLUP!R4 | Y4: Planning Area: | AE4: =UNIT_ROLLUP!AE4
A5: CCN: | C5: 17110 | M5: Nomenclature: | R5: Academic Instruction Building
A11: Please see CCN 17120 BFR calculation. The space requirement for a CCN 17110 Academic Instruction Building has been rolled up to the CCN 17120 Applied Instruction Building.
A40: TOTAL REQUIREMENT: | H40: 0 | L40: SF | AC40: Page | AD40: 1 | AE40: of | AF40: 1

Sheet 17120
A1: BASIC FACILITY REQUIREMENTS WORKSHEET
A3: Installation: | G3: =UNIT_ROLLUP!F3 | M3: Tenant: | R3: =UNIT_ROLLUP!R3
A4: Installation UIC: | G4: =UNIT_ROLLUP!F4 | M4: Tenant UIC: | R4: =UNIT_ROLLUP!R4 | Y4: Planning Area: | AE4: =UNIT_ROLLUP!AE4
A5: CCN: | C5: 17120 | M5: Nomenclature: | R5: Applied Instruction Building
A6: LOADING ANALYSIS / JUSTIFICATION OF REQUIREMENT
A7: Description:
B8: Mission: Provide health service support to the III Marine expeditionary force (IIIMEF). CCN: Provides for training personnel through the applied use of technical equipment and tools; including complete functional systems such as weapons delivery systems, fire control systems, etc. Justification: 3D MED BN requires applied instruction spaces to support H&S Company's Preventative Medicine Unit's mission and courses are not USMC-wide academic requirements. This space supports the training of combat medics using anatomical dummies.
A16: Planning Criteria:
B17: FC 2-000-05N (P-80) 171 & 441 series
B18: NAVFAC Infrastructure Reset BFR Consistency Guide
A19: Loading:
B20: FY2029 Table of Organization & Equipment (attached)
B21: Interview walkthrough with 3D Medical Battalion, S-4 Logistics OIC and Medical Simulation Training Center (MSTC) POC on October 30, 2024.
A23: Analysis:
B24: Unit UIC/ Name | M24: Classroom Space | Q24: Support Space | U24: Total Gross SF
B26: M13020 | E26: 3D Medical Battalion | M26: =Z48 | Q26: =U67 | U26: =M26+Q26
Q27: =AA59 | U27: =$U$26*(M27+Q27)
Q28: Total = | U28: =SUM(U26:X27)
A40: TOTAL REQUIREMENT: | H40: =U28 | L40: SF | AC40: Page | AD40: 1 | AE40: of | AF40: 2
A41: CCN: | C41: =$C$5 | M41: Nomenclature: | R41: =$R$5
B44: Classroom Space
B45: Type of Space | H45: No. of Seats | L45: No. of Student Station | R45: Allowance | V45: 3Net-To-Gross | Z45: Total
B46: 1General Academic | H46: 30 | L46: - | R46: 21 | V46: 1.33 | Z46: =H46*R46*V46
B47: 2Hands-On Mockup | H47: - | L47: 4 | R47: 150 | Z47: =L47*R47
V48: Subtotal = | Z48: =SUM(Z46:AC47)
B50: 1 Per MSTC POC, it is ideal to have 30 seats at a time in a General Academic Classroom. Per Table 17110-1 Space Criteria for General Academic Classrooms, an allowance of 21 NSF per seat is given.
B52: 2 Per MSTC POC, there are 4 different stations at a time to conduct training personnel through use of technical equipment/tools such as an anatomical dummy/mannequin. Per CCN 17120, an allowance of 150 GSF per student station can be applied to compute gross area.
B54: 3 Per Table 171-1 Space Allowances for Intruction Facilities, multiply NSF by. 133 for Net to Gross conversion.
B58: Support Space Space
B59: Type of Space | H59: Qty. | L59: Allowance | Q59: Net-To-Gross | U59: Total
B60: Instructor's Work Space | H60: 1 | L60: 60 | Q60: 1.33 | U60: =H60*L60*Q60
B61: Instructor's Lounge | H61: - | L61: 450 | U61: =L61*Q60
B62: Student Break Area | H62: 30 | L62: 6 | U62: =H62*L62*Q60
B63: Training Aid Storage | H63: 30 | L63: 1.5 | U63: =H63*L63*Q60
B64: 1Additional Training Work Space | H64: - | L64: 400 | U64: =L64
B66: 2Additional Storage Space | H66: - | L66: =28*(22+(3/12)) | U66: =L66
Q67: Subtotal = | U67: =SUM(U60:Y65)
B69: 1 Per facility walkthrough and engineering evaluation, an additional training work space is required to prepare anatomical dummies to mimic real life situations such as painting them to be used for training.
B71: 2 Per facility walkthrough and engineering evaluation, an additional storage is required to store all training aid materials in addition to the Training Aid Storage provided with 1.5 NSF per student.
AC88: Page | AD88: 2 | AE88: of | AF88: 2

Sheet 21451
A1: BASIC FACILITY REQUIREMENTS WORKSHEET
A3: Installation: | F3: MCB Camp Butler | O3: Tenant: | S3: 3d MED BN
A4: Installation UIC: | F4: M67400 | O4: Tenant UIC: | S4: M13020
A5: CCN: | C5: 21451 | M5: Nomenclature: | R5: Automotive Organizational Shop
A6: LOADING ANALYSIS / JUSTIFICATION OF REQUIREMENT
A7: Description:
B8: Mission: Provide health service support to the Marine expeditionary force (MEF). CCN: Provides work areas for units to perform maintenance on items of organizational equipment. The shop space includes administrative and dispatching areas as well as storage for OEM equipment, tools, and parts. Justification: An Automotive Organizational Shop is required to perform maintenance on automotive and engineer equipment.
A14: Planning Criteria:
B15: UFC 2-000-05N - modified CCN 21420 to allow odd numbered bay counts
B16: NAVFAC Infrastructure Reset BFR Consistency Guide
A18: Loading:
B19: FY2025 Table of Organization & Equipment (attached)
A21: Analysis:
B22: Total Space Requirement1
B23: Maint Bays | F23: Admin Sppt2 | J23: Direct Sppt2 | N23: Total
B24: =Q32 | F24: =414*M33^0.854 | J24: =IF(M33<=14,347*M33+1129,22*M33+5706) | N24: =SUM(B24:M24)
B26: Maintenance Bays
B27: Subordinate Unit | M27: Bays | Q27: Area4 | V27: SL3 Storage3 | Z27: =Z28*Z29/2
B28: M28261 | E28: H&S CO | M28: =AB173 | Q28: Rounded at the BN level.5 | V28: Bay Length4 | Z28: 34
B29: M28263 | E29: SURGICAL COMPANY A | M29: =AB304 | V29: Bay Width4 | Z29: 16
B30: M28262 | E30: SURGICAL COMPANY B | M30: =AB435 | V30: Bay NTG | Z30: 1.33
M31: =AB566
L32: Total = | M32: =SUM(M28:P31) | Q32: =M33*((Z28*Z29)+Z27)*Z30
L33: Rounded Total5 = | M33: =ROUNDUP(M32,0)
B35: 1 Maintenance Bay calculations based on repair bay factor per vehicle, as determined by UFC 2-000-05N, Tables 21420-1, 2 & 3. 2 Support space requirements based on UFC 2-000-05N, Table 21420-4 (Space Requirements for Automotive Vehicle Maintenance Facility) and these equations were used to determine the admin and direct support spaces. 3 The 21420 criteria is intended for civilian motor transportation shops. The criteria does not account for component equipment (SL3) that must be removed, stored, and secured from operational unit vehicles. It was assumed that an extra half-bay is required for every calculated repair bay. 4 Maintenance Bay size based on size of largest vehicle on TE (26.24x8 FT). A standard 30x16 FT bay is not large enough to accommodate this vehicle. A 4 FT clearance was added to both the front and the rear to accommodate for personnel access. 5 Repair bays are rounded up to the closest whole number.
D43: REFER TO THE FOLLOWING PAGES FOR INDIVIDUAL SUBORDINATE UNIT BAY CALCULATIONS
A44: TOTAL REQUIREMENT: | H44: TBD | L44: GSF
A45: CCN: | C45: =$C$5 | M45: Nomenclature: | R45: =$R$5
B47: Maintenance Bay Calculations - per UFC 2-000-05N, Tables 21420-1, 2, & 3
B48: =B28 | E48: =INDEX($E$28:$E$32,MATCH(B48,$B$28:$B$32,0))
B49: TAMCN | E49: Description | N49: Cost Code | T49: Quantity | X49: Space Factor | AB49: Repair Bays
B51: A00557G | E51: =IFERROR(VLOOKUP(B51,TE!$H$1:$Y$749,2,FALSE),"(Not on TE)") | N51: =IFERROR(VLOOKUP(B51,TE!$H$1:$Y$749,18,FALSE),"") | T51: =IFERROR(SUMIFS(TE!$O:$O,TE!$G:$G,$B$48,TE!$I:$I,B51,TE!$D:$D,$C$5),"") | X51: =IFERROR(VLOOKUP(B51,TE!$H$1:$Y$630,14,FALSE),"0") | AB51: =T51*X51
