Workbook
Name a: #REF!
Name a: #REF!
Name a: #REF!
Name Comment: #REF!
Name Comment: #REF!
Name Comment: #REF!
Name Comment: #REF!
Name CostCode: #REF!
Name CostCode: #REF!
Name CostCode: #REF!
Name CostCode: #REF!
Name CostCode: #REF!
Name CostCode: #REF!
Name d: #REF!
Name d: #REF!
Name d: #REF!
Name d: #REF!
Name d: #REF!
Name d: #REF!
Name d: #REF!
Name d: #REF!
Name d: #REF!
Name d: #REF!
Name d: #REF!
Name DDD: #REF!
Name DDD: #REF!
Name DDD: #REF!
Name DDD: #REF!
Name DDD: #REF!
Name DDD: #REF!
Name DDD: #REF!
Name delete1: #REF!
Name delete1: #REF!
Name delete1: #REF!
Name delete1: #REF!
Name delete1: #REF!
Name delete1: #REF!
Name delete1: #REF!
Name delete1: #REF!
Name delete1: #REF!
Name delete1: #REF!
Name delete1: #REF!
Name EWC: "M00873"
Name GDSGSDG: #REF!
Name GDSGSDG: #REF!
Name GDSGSDG: #REF!
Name GDSGSDG: #REF!
Name GDSGSDG: #REF!
Name GDSGSDG: #REF!
Name GDSGSDG: #REF!
Name GDSGSDG: #REF!
Name GDSGSDG: #REF!
Name GDSGSDG: #REF!
Name ghhghg: #REF!
Name ghhghg: #REF!
Name ghhghg: #REF!
Name ghhghg: #REF!
Name ghhghg: #REF!
Name ghhghg: #REF!
Name ghhghg: #REF!

Sheet Header 
A1: Installation UIC | B1: Installation Name
A2: M67400 | B2: MCB Camp Butler
A3: Tenant UIC | B3: Tenant Name
A4: M29030 | B4: CLB 4
A5: Subordinate UIC 1 | B5: Subordinate Unit 1 Name
A6: =A4 -> M29030 | B6: =B4 -> CLB 4

Sheet UNIT_ROLLUP
A1: BASIC FACILITY REQUIREMENTS UNIT ROLLUP
A3: Installation: | F3: H&S BN MCIPAC MCB CP BUTLER JA | M3: Tenant: | R3: CLB 4
A4: Installation UIC: | F4: M67400 | M4: Tenant UIC: | R4: M29030 | Y4: Planning Area: | AE4: SW
C8: Facilities measured in SF
C9: CCN | F9: Description | U9: Required Area
C10: 14345 | F10: ARMORY | U10: 413
C11: 21451 | F11: AUTO ORGANIZATION SHOP | U11: 2315
C12: 21455 | F12: VEHICLE WASH PLATFORM | U12: 3192
C13: 61072 | F13: BATTALION SQUADRON HEADQUARTERS, MARINE CORPS | U13: 8379
P15: Total = | U15: =SUM(U10:U13) -> 14299
A17: CLB-4 (M29030) has relocated from Camp Foster to Camp Schwab. This BFR consolidates space requirements for CLB-4 and its four subordinate units: Headquarters Company (M29111), Combat Logistics Company Alpha (M29112), Combat Logistics Company Bravo (M29113), and General Support Company (M29114). All four companies are collocated at Camp Schwab under Planning Area SW. Facility requirements are calculated from the FY2026 Table of Organization and Equipment (TO/E) dated 02 February 2026, reflecting 310 total assigned billets. CCNs cover armory storage, automotive organizational maintenance, vehicle wash, and battalion headquarters administrative space.
AF33: 1
