Workbook

Sheet UNIT_ROLLUP
A1: BASIC FACILITY REQUIREMENTS UNIT ROLLUP
A3: Installation: | F3: MCB CAMP BUTLER | M3: Tenant: | R3: CLB 4
A4: Installation UIC: | F4: M67400 | M4: Tenant UIC: | R4: M29030 | Y4: Planning Area: SW
B8: CCN | C8: Description | D8: UM | E8: Total
B9: 143 45 | C9: ARMORY | D9: GSF | E9: ='14345'!H37
B10: 214 51 | C10: AUTO ORGANIZATIONAL SHOP | D10: GSF | E10: ='21451'!H37
B11: 214 55 | C11: VEHICLE WASH PLATFORM | D11: GSF | E11: ='21455'!H37
B12: 610 72 | C12: BATTLN SQUADRN HQ (MARCOR) | D12: GSF | E12: ='61072'!H37
B13: 143 12 | C13: OPRTNL VEHICLE LAYDWN AREA | D13: GSY | E13: ='14312'!H37
B14: 143 26 | C14: MARINE CORPS EOD PLATOON | D14: GSF | E14: ='14326'!H37
B15: 217 10 | C15: ELECNX/COMMS MAINT SHOP | D15: GSF | E15: ='21710'!H37
B16: 217 30 | C16: FLD MAINT SHOP(ELEC/COMMS) | D16: GSF | E16: ='21730'!H37
B17: 441 12 | C17: STG AIR/GRD ORG UTS MARCOR | D17: GSF | E17: ='44112'!H37
B18: 451 10 | C18: OPEN STORAGE AREA | D18: GSY | E18: ='45110'!H37
B19: 530 10 | C19: DISP & OUT PATIENT CLINIC | D19: GSF | E19: ='53010'!H37
B20: 852 10 | C20: PARKING AREA | D20: GSY | E20: ='85210'!H37
B21: 851 22 | C21: VEHICLE STAGING AREA | D21: GSY | E21: ='85122'!H37
B22: 851 21 | C22: VEH. PARK, UNSURFACED | D22: GSY | E22: ='85121'!H37
B23: 872 10 | C23: SECURTY/PERIMTR FENCE/WALL | D23: LF | E23: ='87210'!H37
B24: 872 50 | C24: ENTRY GATE | D24: LF | E24: ='87250'!H37
B25: 872 30 | C25: MECH SEC BARRICADE | D25: EA | E25: ='87230'!H37
B26: 831 43 | C26: HAZ WASTE BLDG | D26: GSF | E26: ='83143'!H37
B27: 831 41 | C27: HAZARD WSTE STOR & TRANSFR | D27: GSF | E27: ='83141'!H37
B28: 811 60 | C28: STANDBY GENERATOR PLANT | D28: KW | E28: ='81160'!H37
B29: 880 10 | C29: FIRE ALARM COMM LINES | D29: MI | E29: ='88010'!H37
B30: 852 35 | C30: OTHER PAVED AREA | D30: GSY | E30: ='85235'!H37
B31: 852 40 | C31: MISC OPEN STRG/LAYDOWN | D31: GSY | E31: ='85240'!H37
B33: GRAND TOTAL | E33: =SUM(E9:E31)

Sheet TO
B6: LINE | C6: NOTE | D6: CCN | E6: CCN Description | F6: UIC | G6: Rec CD | H6: BIC | I6: Billet Description | J6: Alpha Grade | K6: BMOS | L6: PMOS
B7: 1 | C7: 61072o | D7: 61072 | F7: M29111 | H7: M2911100002 | I7: COMMANDING OFFICER | J7: LTCOL | K7: 0402 | L7: 0402
B8: 2 | C8: 61072o | D8: 61072 | F8: M29111 | H8: M2911100003 | I8: EXECUTIVE OFFICER | J8: MAJ | K8: 1302 | L8: 1302
B9: 3 | C9: 61072o | D9: 61072 | F9: M29111 | H9: M2911100004 | I9: COMMAND SENIOR ENLISTED LEADER | J9: SGTMAJ | K9: 8999 | L9: 8999
B10: 4 | C10: 61072o | D10: 61072 | F10: M29111 | H10: M2911100005 | I10: TAC CHAPLAIN | J10: LT | K10: 4100 | L10: 4100
B11: 5 | C11: 61072c | D11: 61072 | F11: M29111 | H11: M2911100006 | I11: RP SPECIALIST | J11: RP3 | K11: A17A | L11: A17A
B12: 6 | C12: 61072o | D12: 61072 | F12: M29111 | H12: M2911100008 | I12: MANPOWER OFFICER | J12: 1STLT | K12: 0102 | L12: 0102
B13: 7 | C13: 61072o | D13: 61072 | F13: M29111 | H13: M2911100009 | I13: ADMIN CHIEF | J13: SSGT | K13: 0111 | L13: 0111
B14: 8 | C14: 61072c | D14: 61072 | F14: M29111 | H14: M2911100010 | I14: ADMIN SPECIALIST | J14: CPL | K14: 0111 | L14: 0111
B15: 9 | C15: 61072c | D15: 61072 | F15: M29111 | H15: M2911100011 | I15: ADMIN SPECIALIST | J15: LCPL | K15: 0111 | L15: 0111
B16: 10 | C16: 61072o | D16: 61072 | F16: M29111 | H16: M2911100013 | I16: INTELLIGENCE OFFICER | J16: 1STLT | K16: 0234 | L16: 0202
B17: 11 | C17: 61072o | D17: 61072 | F17: M29111 | H17: M2911100014 | I17: INTELLIGENCE CHIEF | J17: GYSGT | K17: 0231 | L17: 0231
B18: 12 | C18: 61072c | D18: 61072 | F18: M29111 | H18: M2911100015 | I18: INTELLIGENCE SPECIALIST | J18: SGT | K18: 0231 | L18: 0231
... B27: 21 | C27: 14326 | D27: 14326 | F27: M29111 | H27: M2911100027 | I27: SECTION CHIEF | J27: MSGT | K27: 2336 | L27: 2336
B28: 22 | F28: M29111 | H28: M2911100028 | I28: ASSISTANT SECTION CHIEF | J28: GYSGT | K28: 8023 | L28: 2336
B29: 23 | C29: 14326 | D29: 14326 | F29: M29111 | H29: M2911100029 | I29: ASSISTANT SECTION CHIEF | J29: GYSGT | K29: 2336 | L29: 2336
B30: 24 | F30: M29111 | H30: M2911100030 | I30: EOD TECHNICIAN | J30: SSGT | K30: 8023 | L30: 2336
B31: 25 | C31: 14326 | D31: 14326 | F31: M29111 | H31: M2911100031 | I31: EOD TECHNICIAN | J31: SSGT | K31: 2336 | L31: 2336
B32: 26 | F32: M29111 | H32: M2911100032 | I32: EOD TECHNICIAN | J32: SSGT | K32: 8023 | L32: 2336
B33: 27 | F33: M29111 | H33: M2911100033 | I33: EOD TECHNICIAN | J33: SGT | K33: 8023 | L33: 2336
B34: 28 | C34: 14326 | D34: 14326 | F34: M29111 | H34: M2911100034 | I34: EOD TECHNICIAN | J34: SGT | K34: 2336 | L34: 2336
B35: 29 | C35: 14326 | D35: 14326 | F35: M29111 | H35: M2911100035 | I35: EOD TECHNICIAN | J35: SGT | K35: 2336 | L35: 2336
B36: 30 | C36: 14326 | D36: 14326 | F36: M29111 | H36: M2911100036 | I36: EOD TECHNICIAN | J36: SGT | K36: 2336 | L36: 2336
B37: 31 | C37: 14326 | D37: 14326 | F37: M29111 | H37: M2911100037 | I37: EOD TECHNICIAN | J37: SGT | K37: 2336 | L37: 2336
B38: 32 | C38: 14326 | D38: 14326 | F38: M29111 | H38: M2911100038 | I38: EOD TECHNICIAN | J38: SGT | K38: 2336 | L38: 2336
B39: 33 | C39: 44112w | D39: 44112 | F39: M29111 | H39: M2911100040 | I39: LOGISTICS OFFICER | J39: CAPT | K39: 0402 | L39: 0402
B40: 34 | C40: 44112w | D40: 44112 | F40: M29111 | H40: M2911100041 | I40: LOGISTICS CHIEF | J40: GYSGT | K40: 0491 | L40: 0491
B41: 35 | C41: 44112w | D41: 44112 | F41: M29111 | H41: M2911100042 | I41: LOGISTICS SPECIALIST | J41: CPL | K41: 0441 | L41: 0441
B42: 36 | C42: 44112w | D42: 44112 | F42: M29111 | H42: M2911100043 | I42: MOBILITY OFFICER | J42: CWO2 | K42: 0430 | L42: 0430
B43: 37 | C43: 44112w | D43: 44112 | F43: M29111 | H43: M2911100044 | I43: LOGISTICS SPECIALIST | J43: SSGT | K43: 0441 | L43: 0441
B44: 38 | C44: 44112w | D44: 44112 | F44: M29111 | H44: M2911100045 | I44: LOGISTICS SPECIALIST | J44: CPL | K44: 0441 | L44: 0441
B45: 39 | C45: 44112w | D45: 44112 | F45: M29111 | H45: M2911100071 | I45: MAINTENANCE MANAGEMENT SPECIALIST | J45: SGT | K45: 0411 | L45: 0411
... B81: 75 | C81: 14326 | D81: 14326 | F81: M29111 | H81: M2911100056 | I81: PHYSICIAN ASST | J81: LT | K81: 2300 | L81: 2300
B82: 76 | F82: M29111 | H82: M2911100057 | I82: SURFACE IDC | J82: HM1 | K82: L10A | L82: L03A
B83: 77 | F83: M29111 | H83: M2911100058 | I83: FLD MED TECH | J83: HMC | K83: L03A | L83: L03A
B84: 78 | F84: M29111 | H84: M2911100059 | I84: FLD MED TECH | J84: HM2 | K84: L03A | L84: L03A
B85: 79 | F85: M29111 | H85: M2911100060 | I85: FLD MED TECH | J85: HM3 | K85: L03A | L85: L03A
B86: 80 | F86: M29111 | H86: M2911100061 | I86: FLD MED TECH | J86: HM3 | K86: L03A | L86: L03A
B87: 81 | F87: M29111 | H87: M2911100062 | I87: FLD MED TECH | J87: HM3 | K87: L03A | L87: L03A
B88: 82 | F88: M29111 | H88: M2911100063 | I88: FLD MED TECH | J88: HM3 | K88: L03A | L88: L03A
...

Sheet TE
B4: ROW | C4: NOTE | D4: CCN | E4: CCN Description | F4: CCN 21451 Equipment Type | G4: UIC | H4: TAMCN Short | I4: TAMCN | J4: Nomenclature | K4: TAM Stat | L4: U/I | M4: Rdy | N4: Ind Qty | O4: Org Qty | P4: Unit T/E | Q4: L, Ft | R4: W, Ft | S4: H, Ft | T4: Volume Ea | U4: Volume Total
B5: 1 | C5: 21710 | D5: 21710 | G5: M29111 | H5: A0135 | I5: A01357G | J5: RADIO SET - AN/VRC-112 | K5: DP | L5: EA | M5: N | N5: 0 | O5: 0 | P5: 0
B6: 2 | C6: 21710 | D6: 21710 | G6: M29111 | H6: A0176 | I6: A01767G | J6: SWITCHING GROUP,DIG - ON-704B/TYC | K6: IS | L6: EA | M6: R | N6: 0 | O6: 2 | P6: 2
B7: 3 | C7: 21710 | D7: 21710 | G7: M29111 | H7: A0210 | I7: A02107G | J7: ANTENNA GROUP - OE-4703/G | K7: IS | L7: EA | M7: N | N7: 0 | O7: 6 | P7: 6
B8: 4 | C8: 21710 | D8: 21710 | G8: M29111 | H8: A0211 | I8: A02117G | J8: ANTENNA GROUP - OE-4702/G | K8: IS | L8: EA | M8: N | N8: 0 | O8: 6 | P8: 6
B9: 5 | C9: 21710 | D9: 21710 | G9: M29111 | H9: A0234 | I9: A02347G | J9: SATELLITE COMMUNICA - AN/TSC-186A | K9: IS | L9: EA | M9: M | N9: 0 | O9: 1 | P9: 1
B10: 6 | C10: 21710 | D10: 21710 | G10: M29111 | H10: A0270 | I10: A02707G | J10: MODEM,COMMUNICATION - OW-118 | K10: PL | L10: EA | M10: N | N10: 0 | O10: 2 | P10: 2
B11: 7 | C11: 21710 | D11: 21710 | G11: M29111 | H11: A0280 | I11: A02807G | J11: DECODER-RECEIVER - 18007B0000 | K11: IS | L11: EA | M11: N | N11: 0 | O11: 1 | P11: 1
B12: 8 | C12: 21710 | D12: 21710 | G12: M29111 | H12: A0312 | I12: A03127G | J12: INTERFACE UNIT,COMM - J-6884A/TYQ | K12: IS | L12: EA | M12: R | N12: 0 | O12: 2 | P12: 2
B13: 9 | C13: 21710 | D13: 21710 | G13: M29111 | H13: A0336 | I13: A03367G | J13: RADIO SET - AN/PRC-117G(V)2 | K13: IS | L13: EA | M13: R | N13: 0 | O13: 12 | P13: 12
B14: 10 | C14: 21710 | D14: 21710 | G14: M29111 | H14: A0371 | I14: A03717G | J14: COUNTERMEASURES SET - AN/PLQ-14 | K14: IS | L14: SE | M14: N | N14: 0 | O14: 4 | P14: 4
B15: 11 | C15: 21710 | D15: 21710 | G15: M29111 | H15: A0460 | I15: A04607G | J15: COMPUTER SYSTEM,DIG - AN/PLC-1 | K15: IS | L15: EA | M15: N | N15: 0 | O15: 1 | P15: 1
B16: 12 | C16: 21710 | D16: 21710 | G16: M29111 | H16: A0465 | I16: A04657G | J16: RUGGEDIZED SERVER R - AN/PYC-100 | K16: IS | L16: EA | M16: R | N16: 0 | O16: 1 | P16: 1
... B28: 24 | C28: 44112 | D28: 44112 | G28: M29111 | H28: C0029 | I28: C00292F | J28: DRAWERS,COLD WEATHE - FRGFDR | K28: IS | L28: PR | M28: N | N28: 85 | O28: 0 | P28: 85
B29: 25 | C29: 44112 | D29: 44112 | G29: M29111 | H29: C0040 | I29: C00402E | J29: PAD,KNEE - MEDIUM | K29: IS | M29: N | N29: 21 | O29: 0 | P29: 21
B30: 26 | C30: 44112 | D30: 44112 | G30: M29111 | H30: C0041 | I30: C00412E | J30: ELBOW PADS,EXTERNAL - SMALL | K30: IS | M30: N | N30: 21 | O30: 0 | P30: 21
B31: 27 | C31: 44112 | D31: 44112 | G31: M29111 | H31: C0042 | I31: C00427B | J31: RECONNAISSANCE SYST - 969-003 | K31: IS | L31: EA | M31: R | N31: 0 | O31: 1 | P31: 1
B32: 28 | C32: 44112 | D32: 44112 | G32: M29111 | H32: C0061 | I32: C00612F | J32: CARRIER,SMALL ARMS - PC GEN II | K32: IS | L32: EA | M32: N | N32: 85 | O32: 0 | P32: 85
B33: 29 | C33: 44112 | D33: 44112 | G33: M29111 | H33: C0062 | I33: C00622F | J33: COAT,CHEMICAL PROTE - UNIVERSAL COAT | K33: IS | L33: EA | M33: N | N33: 170 | O33: 0 | P33: 170
B34: 30 | C34: 44112 | D34: 44112 | G34: M29111 | H34: C0063 | I34: C00632F | J34: TROUSERS,CHEMICAL P - UNIVERSAL TROU | K34: IS | L34: PR | M34: N | N34: 170 | O34: 0 | P34: 170
B35: 31 | C35: 44112 | D35: 44112 | G35: M29111 | H35: C0074 | I35: C00742E | J35: FLASHLIGHT - 14032 | K35: IS | L35: EA | M35: N | N35: 85 | O35: 0 | P35: 85
B36: 32 | C36: 44112 | D36: 44112 | G36: M29111 | H36: C0077 | I36: C00772E | J36: COLLAPSIBLE JMIC 3. - TAN | K36: IS | L36: EA | M36: N | N36: 0 | O36: 25 | P36: 25
B37: 33 | C37: 44112 | D37: 44112 | G37: M29111 | H37: C0083 | I37: C00832E | J37: STRAP CUTTER,RESCUE - 1431 | K37: IS | L37: EA | M37: N | N37: 85 | O37: 0 | P37: 85
B38: 34 | C38: 44112 | D38: 44112 | G38: M29111 | H38: C0114 | I38: C01142F | J38: HEADSET,ELECTRICAL - MT20H682FB-09 CY | K38: IS | L38: EA | M38: N | N38: 0 | O38: 13 | P38: 13
B39: 35 | C39: 44112 | D39: 44112 | G39: M29111 | H39: C0115 | I39: C01152F | J39: DRAWERS,COLD WEATHE - FRDRCW | K39: IS | L39: PR | M39: N | N39: 170 | O39: 0 | P39: 170
B40: 36 | C40: 44112 | D40: 44112 | G40: M29111 | H40: C0116 | I40: C01162F | J40: UNDERSHIRT,COLD WEA - FRUSHCW | K40: IS | L40: EA | M40: N | N40: 170 | O40: 0 | P40: 170
B41: 37 | C41: 44112 | D41: 44112 | G41: M29111 | H41: C0117 | I41: C01172F | J41: SHIRT,COLD WEATHER - FRGFP07 | K41: IS | L41: EA | M41: N | N41: 85 | O41: 0 | P41: 85
B42: 38 | C42: 44112 | D42: 44112 | G42: M29111 | H42: C0120 | I42: C01202E | J42: HELMET,GROUND TROOP - ECH | K42: IS | L42: EA | M42: N | N42: 85 | O42: 0 | P42: 85
... B50: 46 | C50: 44112 | D50: 44112 | G50: M29111 | H50: C0187 | I50: C01877B | J50: SHIPPING AND STORAG - CMCI377 | K50: IS | L50: EA | M50: N | N50: 0 | O50: 2 | P50: 2
B51: 47 | C51: 44112 | D51: 44112 | G51: M29111 | H51: C0188 | I51: C01882F | J51: No Item Name Availa - N/A | K51: IS | M51: N | N51: 0 | O51: 0 | P51: 0
B52: 48 | C52: 44112 | D52: 44112 | G52: M29111 | H52: C0189 | I52: C01892F | J52: POUCH,MONOCULAR NIG - N/A | K52: IS | L52: EA | M52: N | N52: 44 | O52: 0 | P52: 44
B53: 49 | C53: 44112 | D53: 44112 | G53: M29111 | H53: C0190 | I53: C01902F | J53: POUCH,TACTICAL HAND - N/A | K53: IS | L53: EA | M53: N | N53: 0 | O53: 0 | P53: 0
B54: 50 | C54: 44112 | D54: 44112 | G54: M29111 | H54: C0191 | I54: C01912F | J54: CANTEEN,GENERAL PUR - 4015CB | K54: IS | L54: EA | M54: N | N54: 170 | O54: 0 | P54: 170
B55: 51 | C55: 44112 | D55: 44112 | G55: M29111 | H55: C0218 | I55: C02182B | J55: DECONTAMINATION KIT - 10038819 | K55: IS | L55: BX | M55: N | N55: 2 | O55: 0 | P55: 2
B56: 52 | C56: 44112 | D56: 44112 | G56: M29111 | H56: C0222 | I56: C02222F | J56: HELMET,GROUND TROOP - HC ECH | K56: IS | L56: EA | M56: N | N56: 13 | O56: 0 | P56: 13
B57: 53 | C57: 44112 | D57: 44112 | G57: M29111 | H57: C0247 | I57: C02472Z | J57: JOINT SERVICE GENERAL PURPOSE MASK, FIELD (M50) - M50 | K57: PL | M57: N | N57: 85 | O57: 0 | P57: 85
B58: 54 | C58: 44112 | D58: 44112 | G58: M29111 | H58: C0260 | I58: C02602F | J58: GAITER,NECK - A-A-55247 | K58: IS | L58: EA | M58: N | N58: 85 | O58: 0 | P58: 85
B59: 55 | C59: 44112 | D59: 44112 | G59: M29111 | H59: C1000 | I59: C10002E | J59: No Item Name Availa - 11-04 | K59: IS | M59: N | N59: 0 | O59: 1 | P59: 1
B60: 56 | C60: 44112 | D60: 44112 | G60: M29111 | H60: C1023 | I60: C10232F | J60: HOOD,COMBAT VEHICLE - MIL-H-44265 | K60: IS | M60: N | N60: 0 | O60: 0 | P60: 0
B61: 57 | C61: 44112 | D61: 44112 | G61: M29111 | H61: C1055 | I61: C10552F | J61: CAP,COLD WEATHER - CR/PD01-09 | K61: IS | L61: EA | M61: N | N61: 85 | O61: 0 | P61: 85
...

Sheet 14345
A1: BASIC FACILITY REQUIREMENTS WORKSHEET
A3: Installation: | F3: MCB CAMP BUTLER | M3: Tenant: | R3: CLB 4
A4: Installation UIC: | F4: M67400 | M4: Tenant UIC: | R4: M29030 | Y4: Planning Area: SW
A5: CCN: | C5: 143 45 | M5: Nomenclature: | R5: ARMORY
A6: SPACE REQUIREMENT ANALYSIS , CCN 143 45 , FC 2-000-05N (Series 100, 11 Feb 2026)
A7: Sensitive Item Category (Primary Items, all four companies) | V7: GSF / Item | Y7: Count | AB7: GSF
A8: Night Vision Devices (AN/PVS-14, AN/PVS-31D) | V8: 1.25 | Y8: 237 | AB8: =V8*Y8
A9: Machine Guns (M240B, MK19 MOD 3) | V9: 1.25 | Y9: 14 | AB9: =V9*Y9
A10: Rifles, Carbines, and Shotguns | V10: 1.25 | Y10: 19 | AB10: =V10*Y10
A11: Grenade Launchers (M320A1) | V11: 1.25 | Y11: 4 | AB11: =V11*Y11
A12: Thermal Sights (AN/PAS-13D) | V12: 1.25 | Y12: 4 | AB12: =V12*Y12
A13: Other Sensitive Items (Optics, Accessories, Spares) | V13: 1.25 | Y13: 52 | AB13: =V13*Y13
A15: Total Sensitive Items, Total NSF | AB15: =SUM(AB8:AB13)
A16: Required GSF = ROUNDUP(Total NSF, 0) | AB16: =ROUNDUP(AB15,0)
A37: TOTAL REQUIREMENT: | H37: =AB16 | O37: GSF
B40: FC 2-000-05N Citation (Apex Omega Sec.5.5)
B41: FC 2-000-05N 100 Series; version date 2026-02-11
B42: Source PDF: fc_2_000_05n_100series_02_11_2026.pdf
B43: Pages: [205]
B44: Table 14345-1 (Armory); loading driver: Installation Military Strength
B45: up to 2,000 | 576
B46: 2,001 - 4,000 | 880
B47: 4,001 - 7,500 | 1,200
B48: 7,501 - 10,000 | 1,508
B49: Over 10,000 | Add 0.1 sq ft per person

Sheet 21451
A1: BASIC FACILITY REQUIREMENTS WORKSHEET
A3: Installation: | F3: MCB CAMP BUTLER | M3: Tenant: | R3: CLB 4
A4: Installation UIC: | F4: M67400 | M4: Tenant UIC: | R4: M29030 | Y4: Planning Area: SW
A5: CCN: | C5: 214 51 | M5: Nomenclature: | R5: AUTO ORGANIZATIONAL SHOP
A6: SPACE REQUIREMENT ANALYSIS , CCN 214 51 , FC 2-000-05N (Series 100, 11 Feb 2026)
A7: SECTION 1 - ADMINISTRATIVE SPACE
A8: Personnel Category | V8: SF / Person | Y8: Count | AB8: NSF
A9: Officers, Private Offices (Platoon Commanders) | V9: 120 | Y9: 2 | AB9: =V9*Y9
A10: SNCOs and Staff, Cubicles | V10: 60 | Y10: 11 | AB10: =V10*Y10
A11: Administrative Subtotal | AB11: =SUM(AB9:AB10)
A13: SECTION 2 - MAINTENANCE BAYS
A14: Vehicle Category | V14: SF / Bay | Y14: Qty | AB14: NSF
A15: Light Utility Vehicles (JLTV-class M1280, M1279) | V15: 420 | Y15: 33
A16: Medium / Heavy Cargo (AMK23A1, AMK27A1) | V16: 420 | Y16: 23
A17: Wrecker / Recovery (AMK36) | V17: 420 | Y17: 3
A18: Total Self-Propelled Vehicles | CEILING(total / 30) bays | Y18: =SUM(Y15:Y17)
A19: Maintenance Bays (CEILING bays per 30 vehicles) | V19: 420 | Y19: =CEILING(Y18/30,1) | AB19: =V19*Y19
A20: Maintenance Bays Subtotal | AB20: =AB19
A22: TOTAL SPACE REQUIREMENT
A23: Total NSF (Administrative + Maintenance Bays) | AB23: =AB11+AB20
A24: NTG Factor = 1.33, Required GSF = ROUNDUP(NSF * NTG, 0) | V24: 1.33 | AB24: =ROUNDUP(AB23*V24,0)
A37: TOTAL REQUIREMENT: | H37: =AB24 | O37: GSF
B40: FC 2-000-05N Citation (Apex Omega Sec.5.5)
B41: FC 2-000-05N 200 Series; version date 2025-05-16
B42: Source PDF: fc_2_000_05n_200series_05_16_2025.pdf
B43: Pages: [188]
B44: Engineering-study CCN per NAVFAC doctrine; 3 narrative section(s) captured
B45: e.g. 21451-1: This facility provides work areas for Fleet Marine Force (FMF) units to

Sheet 21455
A1: BASIC FACILITY REQUIREMENTS WORKSHEET
A3: Installation: | F3: MCB CAMP BUTLER | M3: Tenant: | R3: CLB 4
A4: Installation UIC: | F4: M67400 | M4: Tenant UIC: | R4: M29030 | Y4: Planning Area: SW
A5: CCN: | C5: 214 55 | M5: Nomenclature: | R5: VEHICLE WASH PLATFORM
A6: SPACE REQUIREMENT ANALYSIS , CCN 214 55 , FC 2-000-05N (Series 100, 11 Feb 2026)
A7: VEHICLE WASH PLATFORM (Loading driver: Vehicle wash spaces) | V7: Factor | Y7: Count | AB7: GSF
A8: Primary loading row | V8: 1 | Y8: 84 | AB8: =V8*Y8*1.0
AB9: =V9*Y9*1.0
AB10: =V10*Y10*1.0
AB11: =V11*Y11*1.0
AB12: =V12*Y12*1.0
AB13: =V13*Y13*1.0
A15: Subtotal NSF | AB15: =SUM(AB8:AF13)
A16: Net to Gross multiplier (NTG = 1.0) | AB16: =AB15*1
A37: TOTAL REQUIREMENT: | H37: =AB16 | O37: GSF
B40: FC 2-000-05N Citation (Apex Omega Sec.5.5)
B41: FC 2-000-05N 200 Series; version date 2025-05-16
B42: Source PDF: fc_2_000_05n_200series_05_16_2025.pdf
B43: Pages: [188]
B44: Engineering-study CCN per NAVFAC doctrine; 1 narrative section(s) captured
B45: e.g. 21455-1: REQUIREMENTS. Vehicle wash platforms equipped with hose

Sheet 61072
A1: BASIC FACILITY REQUIREMENTS WORKSHEET
A3: Installation: | F3: MCB CAMP BUTLER | M3: Tenant: | R3: CLB 4
A4: Installation UIC: | F4: M67400 | M4: Tenant UIC: | R4: M29030 | Y4: Planning Area: SW
A5: CCN: | C5: 610 72 | M5: Nomenclature: | R5: BATTLN SQUADRN HQ (MARCOR)
A6: SPACE REQUIREMENT ANALYSIS , CCN 610 72 , FC 2-000-05N (Series 100, 11 Feb 2026)
A7: BILLETS EXCLUDED FROM THIS CCN (require separate facility CCNs)
A8: Medical / BAS billets (34), medical facility CCN required
A9: EOD Section billets (13), EOD facility CCN required
A10: Specialist shop billets (99), maintenance shop CCN(s) required
A11: Ordnance repair billets (10), ordnance shop CCN required
A13: ADMINISTRATIVE SPACE CALCULATION
A14: Space Type | V14: SF / Person | Y14: Count | AB14: NSF
A15: Private Offices (CO, XO, CSE, Chaplain, S-Staff Officers) | V15: 120 | Y15: 21 | AB15: =V15*Y15
A16: Cubicles (S-Staff NCOs, Company Admin, Supply, Ops) | V16: 60 | Y16: 63 | AB16: =V16*Y16
A17: Total NSF | AB17: =SUM(AB15:AB16)
A19: TOTAL SPACE REQUIREMENT
A20: NTG Factor = 1.33, Required GSF = ROUNDUP(NSF * NTG, 0) | V20: 1.33 | AB20: =ROUNDUP(AB17*V20,0)
A37: TOTAL REQUIREMENT: | H37: =AB20 | O37: GSF
B40: FC 2-000-05N Citation (Apex Omega Sec.5.5)
B41: FC 2-000-05N 600 Series; version date 2023-03-02
B42: Source PDF: fc_2_000_05n_600series_03_02_2023.pdf
B43: Pages: [39]
B44: Engineering-study CCN per NAVFAC doctrine; 1 narrative section(s) captured
B45: e.g. 61072-1: This category code is for a Fleet Marine Force (FMF) facility and provides

Sheet 14312
A1: BASIC FACILITY REQUIREMENTS WORKSHEET
A3: Installation: | F3: MCB CAMP BUTLER | M3: Tenant: | R3: CLB 4
A4: Installation UIC: | F4: M67400 | M4: Tenant UIC: | R4: M29030 | Y4: Planning Area: SW
A5: CCN: | C5: 143 12 | M5: Nomenclature: | R5: OPRTNL VEHICLE LAYDWN AREA
A6: SPACE REQUIREMENT ANALYSIS , CCN 143 12 , FC 2-000-05N (Series 100, 11 Feb 2026)
A7: OPRTNL VEHICLE LAYDWN AREA (Loading driver: Vehicle laydown areas) | V7: Factor | Y7: Count | AB7: GSY
A8: Primary loading row | V8: 1 | Y8: 84 | AB8: =V8*Y8*1.0
AB9: =V9*Y9*1.0
AB10: =V10*Y10*1.0
AB11: =V11*Y11*1.0
AB12: =V12*Y12*1.0
AB13: =V13*Y13*1.0
A15: Subtotal NSF | AB15: =SUM(AB8:AF13)
A16: Net to Gross multiplier (NTG = 1.0) | AB16: =AB15*1
A37: TOTAL REQUIREMENT: | H37: =AB16 | O37: GSY
B40: FC 2-000-05N Citation (Apex Omega Sec.5.5)
B41: FC 2-000-05N 100 Series; version date 2026-02-11
B42: Source PDF: fc_2_000_05n_100series_02_11_2026.pdf
B43: Pages: [189, 190]
B44: page_190_table_1 (); loading driver: TBD
B45: Non-mechanized CESE and SABAR (ex: Small (<10FT) Fuel Water SIXCON, Motors, Pumps, A 19 168 1.50 Generators, TRICONS)
B46: Vehicles and non-mechanized CESE and Medium (10FT- SABAR (ex: Passenger Vehicles, B 32 288 1.75 20FT) HMMWV, Light Plant, Fork Lifts, Small Zodiac Boats)
B47: Large CESE and SABAR (ex: MTVR, Fuel Large (20FT-30FT) C 46 408 1.75 Trucks, Boats < 30FT)
B48: Extra Large CESE and SABAR (ex: Boats Extra Large (30FT- > 30FT, Scrapers, Water Well, Semi D 59 528 2.00 40FT) Trailers)
B49: Extra Large CESE and SABAR (ex: Boats Extra Large (40FT- > 40FT, Scrapers, Water Well, Semi E 72 648 2.00 50FT) Trailers)
B50: Extra Large (50FT- Extra Large CESE and SABAR (ex: Boats F 86 768 2.25 60FT) > 50 FT, Semi Trailers, lowboy 55T)
B51: Extra Large CESE and SABAR (ex: 11M Extra Large (60FT- Rib with Prime Mover; 40PB with Prime G 99 888 2.25 70FT) Mover)
... B61: F | 60

Sheet 14326
A1: BASIC FACILITY REQUIREMENTS WORKSHEET
A3: Installation: | F3: MCB CAMP BUTLER | M3: Tenant: | R3: CLB 4
A4: Installation UIC: | F4: M67400 | M4: Tenant UIC: | R4: M29030 | Y4: Planning Area: SW
A5: CCN: | C5: 143 26 | M5: Nomenclature: | R5: MARINE CORPS EOD PLATOON
A6: SPACE REQUIREMENT ANALYSIS , CCN 143 26 , FC 2-000-05N (Series 100, 11 Feb 2026)
A7: ADMINISTRATIVE SPACE CALCULATION
A8: EOD Personnel Space | V8: SF / Person | Y8: Count | AB8: NSF
A9: EOD Officers, Private Offices | V9: 120 | Y9: 2 | AB9: =V9*Y9
A10: EOD Enlisted, Workspace | V10: 60 | Y10: 11 | AB10: =V10*Y10
A11: Total NSF | AB11: =SUM(AB9:AB10)
A13: TOTAL SPACE REQUIREMENT
A14: NTG Factor = 1.33, Required GSF = ROUNDUP(NSF * NTG, 0) | V14: 1.33 | AB14: =ROUNDUP(AB11*V14,0)
A37: TOTAL REQUIREMENT: | H37: =AB14 | O37: GSF
B40: FC 2-000-05N Citation (Apex Omega Sec.5.5)
B41: FC 2-000-05N 100 Series; version date 2026-02-11
B42: Source PDF: fc_2_000_05n_100series_02_11_2026.pdf
B43: Pages: [200, 201, 202, 203]
B44: Engineering-study CCN per NAVFAC doctrine; 24 narrative section(s) captured
B45: e.g. 14326-1: This facility is necessary for manning, equipping, and training for EOD
B46: UoM source: CCN_VOCABULARY.json (Appendix A 2019-06-27); Series PDF heading omitted UoM, ratifier should verify against current Series text

Sheet 21710
A1: BASIC FACILITY REQUIREMENTS WORKSHEET
A3: Installation: | F3: MCB CAMP BUTLER | M3: Tenant: | R3: CLB 4
A4: Installation UIC: | F4: M67400 | M4: Tenant UIC: | R4: M29030 | Y4: Planning Area: SW
A5: CCN: | C5: 217 10 | M5: Nomenclature: | R5: ELECNX/COMMS MAINT SHOP
A6: SPACE REQUIREMENT ANALYSIS , CCN 217 10 , FC 2-000-05N (Series 100, 11 Feb 2026)
A7: SECTION 1 - ADMINISTRATIVE SPACE
A8: Personnel Category | V8: SF / Person | Y8: Count | AB8: NSF
A9: Comm Maint Officers | V9: 120 | Y9: 2 | AB9: =V9*Y9
A10: Comm Maint Enlisted | V10: 60 | Y10: 30 | AB10: =V10*Y10
A11: Administrative Subtotal | AB11: =SUM(AB9:AB10)
A13: SECTION 2 - MAINTENANCE BAYS
A14: Vehicle Category | V14: SF / Bay | Y14: Qty | AB14: NSF
A15: Comm vehicles (radio shelters) | V15: 420 | Y15: 12
Y16: 0
Y17: 0
A18: Total Self-Propelled Vehicles | CEILING(total / 15) bays | Y18: =SUM(Y15:Y17)
A19: Maintenance Bays (CEILING bays per 15 vehicles) | V19: 420 | Y19: =CEILING(Y18/15,1) | AB19: =V19*Y19
A20: Maintenance Bays Subtotal | AB20: =AB19
A22: TOTAL SPACE REQUIREMENT
A23: Total NSF (Administrative + Maintenance Bays) | AB23: =AB11+AB20
A24: NTG Factor = 1.33, Required GSF = ROUNDUP(NSF * NTG, 0) | V24: 1.33 | AB24: =ROUNDUP(AB23*V24,0)
A37: TOTAL REQUIREMENT: | H37: =AB24 | O37: GSF
B40: FC 2-000-05N Citation (Apex Omega Sec.5.5)
B41: FC 2-000-05N 200 Series; version date 2025-05-16
B42: Source PDF: fc_2_000_05n_200series_05_16_2025.pdf
B43: Pages: [195]
B44: Engineering-study CCN per NAVFAC doctrine; 1 narrative section(s) captured
B45: e.g. 21710-1: Electronics maintenance shops at Naval and Marine Corps activities

Sheet 21730
A1: BASIC FACILITY REQUIREMENTS WORKSHEET
A3: Installation: | F3: MCB CAMP BUTLER | M3: Tenant: | R3: CLB 4
A4: Installation UIC: | F4: M67400 | M4: Tenant UIC: | R4: M29030 | Y4: Planning Area: SW
A5: CCN: | C5: 217 30 | M5: Nomenclature: | R5: FLD MAINT SHOP(ELEC/COMMS)
A6: SPACE REQUIREMENT ANALYSIS , CCN 217 30 , FC 2-000-05N (Series 100, 11 Feb 2026)
A7: SECTION 1 - ADMINISTRATIVE SPACE
A8: Personnel Category | V8: SF / Person | Y8: Count | AB8: NSF
A9: Field Maint Officers | V9: 120 | Y9: 2 | AB9: =V9*Y9
A10: Field Maint Enlisted | V10: 60 | Y10: 33 | AB10: =V10*Y10
A11: Administrative Subtotal | AB11: =SUM(AB9:AB10)
A13: SECTION 2 - MAINTENANCE BAYS
A14: Vehicle Category | V14: SF / Bay | Y14: Qty | AB14: NSF
A15: Field maintenance vehicles | V15: 420 | Y15: 18
Y16: 0
Y17: 0
A18: Total Self-Propelled Vehicles | CEILING(total / 15) bays | Y18: =SUM(Y15:Y17)
A19: Maintenance Bays (CEILING bays per 15 vehicles) | V19: 420 | Y19: =CEILING(Y18/15,1) | AB19: =V19*Y19
A20: Maintenance Bays Subtotal | AB20: =AB19
A22: TOTAL SPACE REQUIREMENT
A23: Total NSF (Administrative + Maintenance Bays) | AB23: =AB11+AB20
A24: NTG Factor = 1.33, Required GSF = ROUNDUP(NSF * NTG, 0) | V24: 1.33 | AB24: =ROUNDUP(AB23*V24,0)
A37: TOTAL REQUIREMENT: | H37: =AB24 | O37: GSF
B40: FC 2-000-05N Citation (Apex Omega Sec.5.5)
B41: FC 2-000-05N 200 Series; version date 2025-05-16
B42: Source PDF: fc_2_000_05n_200series_05_16_2025.pdf
B43: Pages: [196]
B44: Engineering-study CCN per NAVFAC doctrine; 1 narrative section(s) captured
B45: e.g. 21730-1: This field maintenance shop provides specialized work areas for
B46: UoM source: CCN_VOCABULARY.json (Appendix A 2019-06-27); Series PDF heading omitted UoM, ratifier should verify against current Series text

Sheet 44112
A1: BASIC FACILITY REQUIREMENTS WORKSHEET
A3: Installation: | F3: MCB CAMP BUTLER | M3: Tenant: | R3: CLB 4
A4: Installation UIC: | F4: M67400 | M4: Tenant UIC: | R4: M29030 | Y4: Planning Area: SW
A5: CCN: | C5: 441 12 | M5: Nomenclature: | R5: STG AIR/GRD ORG UTS MARCOR
A6: SPACE REQUIREMENT ANALYSIS , CCN 441 12 , FC 2-000-05N (Series 100, 11 Feb 2026)
A7: STG AIR/GRD ORG UTS MARCOR (Loading driver: Storage personnel) | V7: Factor | Y7: Count | AB7: GSF
A8: Primary loading row | V8: 60 | Y8: 84 | AB8: =V8*Y8*1.33
AB9: =V9*Y9*1.33
AB10: =V10*Y10*1.33
AB11: =V11*Y11*1.33
AB12: =V12*Y12*1.33
AB13: =V13*Y13*1.33
A15: Subtotal NSF | AB15: =SUM(AB8:AF13)
A16: Net to Gross multiplier (NTG = 1.33) | AB16: =AB15*1
A37: TOTAL REQUIREMENT: | H37: =AB16 | O37: GSF
B40: FC 2-000-05N Citation (Apex Omega Sec.5.5)
B41: FC 2-000-05N 400 Series; version date 2025-11-19
B42: Source PDF: fc_2_000_05n_400series_11_19_2025.pdf
B43: Pages: [46]
B44: Engineering-study CCN per NAVFAC doctrine; 1 narrative section(s) captured
B45: e.g. 44112-1: DESCRIPTION. This category code includes general purpose storage

Sheet 45110
A1: BASIC FACILITY REQUIREMENTS WORKSHEET
A3: Installation: | F3: MCB CAMP BUTLER | M3: Tenant: | R3: CLB 4
A4: Installation UIC: | F4: M67400 | M4: Tenant UIC: | R4: M29030 | Y4: Planning Area: SW
A5: CCN: | C5: 451 10 | M5: Nomenclature: | R5: OPEN STORAGE AREA
A6: SPACE REQUIREMENT ANALYSIS , CCN 451 10 , FC 2-000-05N (Series 100, 11 Feb 2026)
A7: OPEN STORAGE AREA (Loading driver: Open storage area) | V7: Factor | Y7: Count | AB7: GSY
A8: Primary loading row | V8: 1 | Y8: 84 | AB8: =V8*Y8*1.0
AB9: =V9*Y9*1.0
AB10: =V10*Y10*1.0
AB11: =V11*Y11*1.0
AB12: =V12*Y12*1.0
AB13: =V13*Y13*1.0
A15: Subtotal NSF | AB15: =SUM(AB8:AF13)
A16: Net to Gross multiplier (NTG = 1.0) | AB16: =AB15*1
A37: TOTAL REQUIREMENT: | H37: =AB16 | O37: GSY
B40: FC 2-000-05N Citation (Apex Omega Sec.5.5)
B41: FC 2-000-05N 400 Series; version date 2025-11-19
B42: Source PDF: fc_2_000_05n_400series_11_19_2025.pdf
B43: Pages: [50, 51]
B44: Engineering-study CCN per NAVFAC doctrine; 2 narrative section(s) captured
B45: e.g. 45110-1: DESCRIPTION. This category group consists of non-covered storage

Sheet 53010
A1: BASIC FACILITY REQUIREMENTS WORKSHEET
A3: Installation: | F3: MCB CAMP BUTLER | M3: Tenant: | R3: CLB 4
A4: Installation UIC: | F4: M67400 | M4: Tenant UIC: | R4: M29030 | Y4: Planning Area: SW
A5: CCN: | C5: 530 10 | M5: Nomenclature: | R5: DISP & OUT PATIENT CLINIC
A6: SPACE REQUIREMENT ANALYSIS , CCN 530 10 , FC 2-000-05N (Series 100, 11 Feb 2026)
A7: ADMINISTRATIVE SPACE CALCULATION
A8: BAS Personnel Space | V8: SF / Person | Y8: Count | AB8: NSF
A9: BAS Medical Officers / IDC | V9: 120 | Y9: 4 | AB9: =V9*Y9
A10: Hospital Corpsmen / Field Med Tech / Dental Asst | V10: 60 | Y10: 30 | AB10: =V10*Y10
A11: Total NSF | AB11: =SUM(AB9:AB10)
A13: TOTAL SPACE REQUIREMENT
A14: NTG Factor = 1.33, Required GSF = ROUNDUP(NSF * NTG, 0) | V14: 1.33 | AB14: =ROUNDUP(AB11*V14,0)
A37: TOTAL REQUIREMENT: | H37: =AB14 | O37: GSF
B40: FC 2-000-05N Citation (Apex Omega Sec.5.5)
B41: FC 2-000-05N 500 Series; version date 2023-03-17
B42: Source PDF: fc_2_000_05n_500series_03_17_2023.pdf
B43: Pages: [8]
B44: Engineering-study CCN per NAVFAC doctrine; 1 narrative section(s) captured
B45: e.g. 53010-1: GENERAL. Free Standing Clinic, outpatient clinic, which occupies a

Sheet 85210
A1: BASIC FACILITY REQUIREMENTS WORKSHEET
A3: Installation: | F3: MCB CAMP BUTLER | M3: Tenant: | R3: CLB 4
A4: Installation UIC: | F4: M67400 | M4: Tenant UIC: | R4: M29030 | Y4: Planning Area: SW
A5: CCN: | C5: 852 10 | M5: Nomenclature: | R5: PARKING AREA
A6: SPACE REQUIREMENT ANALYSIS , CCN 852 10 , FC 2-000-05N (Series 100, 11 Feb 2026)
A7: PARKING AREA (Loading driver: Organizational Vehicle Parking (count of CLB-4 motor pool vehicles); FAC 8521; cited factor 75 SY/vehicle for FMF Ground Units (50 SY/vehicle if >50% are <=18ft x 6.5ft); UoM=SY; user-supplied spec 2026-04-30 pending FC 2-000-05N Series 800 cross-check) | V7: Factor | Y7: Count | AB7: GSY
A8: Primary loading row | V8: 75 | Y8: 100 | AB8: =V8*Y8*1.0
AB9: =V9*Y9*1.0
AB10: =V10*Y10*1.0
AB11: =V11*Y11*1.0
AB12: =V12*Y12*1.0
AB13: =V13*Y13*1.0
A15: Subtotal NSF | AB15: =SUM(AB8:AF13)
A16: Net to Gross multiplier (NTG = 1.0) | AB16: =AB15*1
A37: TOTAL REQUIREMENT: | H37: =AB16 | O37: GSY
B40: FC 2-000-05N Citation (Apex Omega Sec.5.5)
B41: FC 2-000-05N 800 Series; version date 2025-03-31
B42: Source PDF: fc_2_000_05n_800series_03_31_2025.pdf
B43: Pages: [60, 61, 62, 63]
B44: Table 85210-1 (); loading driver: Personnel
B45: Bank and Credit Union, when not included in a Community Shopping | 2% of customers served
B46: Cafeteria, Civilian, when not included in a Community Shopping Center | 15% of seating capacity
B47: Central Food Preparation Facilities | 38% of employees
B48: Chapels | 30% of seating capacity
B49: Child Development Centers (Patron Parking) | 10% of children served
B50: Child Development Centers (Staff Parking) | 80% of staff
B51: Commissary Stores, Food Sales, when not included in a Community Shopping Center | Contact DeCA for parking requirements.
... B72: Warehouses | 40% of employees

Sheet 85122
A1: BASIC FACILITY REQUIREMENTS WORKSHEET
A3: Installation: | F3: MCB CAMP BUTLER | M3: Tenant: | R3: CLB 4
A4: Installation UIC: | F4: M67400 | M4: Tenant UIC: | R4: M29030 | Y4: Planning Area: SW
A5: CCN: | C5: 851 22 | M5: Nomenclature: | R5: VEHICLE STAGING AREA
A6: SPACE REQUIREMENT ANALYSIS , CCN 851 22 , FC 2-000-05N (Series 100, 11 Feb 2026)
A7: VEHICLE STAGING AREA (Loading driver: Vehicle Staging Area for mount-out operations (SY); FAC 8523; sized by mission scale not by parked-vehicle count; CLB-4 placeholder 5000 SY pending unit doctrine input) | V7: Factor | Y7: Count | AB7: GSY
A8: Primary loading row | V8: 1 | Y8: 5000 | AB8: =V8*Y8*1.0
AB9: =V9*Y9*1.0
AB10: =V10*Y10*1.0
AB11: =V11*Y11*1.0
AB12: =V12*Y12*1.0
AB13: =V13*Y13*1.0
A15: Subtotal NSF | AB15: =SUM(AB8:AF13)
A16: Net to Gross multiplier (NTG = 1.0) | AB16: =AB15*1
A37: TOTAL REQUIREMENT: | H37: =AB16 | O37: GSY
B40: FC 2-000-05N Citation (Apex Omega Sec.5.5)
B41: FC 2-000-05N 800 Series; version date 2025-03-31
B42: Source PDF: fc_2_000_05n_800series_03_31_2025.pdf
B43: Pages: [59]
B44: Engineering-study CCN per NAVFAC doctrine; 1 narrative section(s) captured
B45: e.g. 85122-1: DEFINITION. This category code represents surfaced areas for the

Sheet 85121
A1: BASIC FACILITY REQUIREMENTS WORKSHEET
A3: Installation: | F3: MCB CAMP BUTLER | M3: Tenant: | R3: CLB 4
A4: Installation UIC: | F4: M67400 | M4: Tenant UIC: | R4: M29030 | Y4: Planning Area: SW
A5: CCN: | C5: 851 21 | M5: Nomenclature: | R5: VEH. PARK, UNSURFACED
A6: SPACE REQUIREMENT ANALYSIS , CCN 851 21 , FC 2-000-05N (Series 100, 11 Feb 2026)
A7: VEH. PARK, UNSURFACED (Loading driver: Vehicular Parking Unsurfaced (SY); FAC 8522; calculated using 85210 criteria when used; CLB-4 sets to 0 because primary parking is paved per 85210) | V7: Factor | Y7: Count | AB7: GSY
A8: Primary loading row | V8: 1 | Y8: 0 | AB8: =V8*Y8*1.0
AB9: =V9*Y9*1.0
AB10: =V10*Y10*1.0
AB11: =V11*Y11*1.0
AB12: =V12*Y12*1.0
AB13: =V13*Y13*1.0
A15: Subtotal NSF | AB15: =SUM(AB8:AF13)
A16: Net to Gross multiplier (NTG = 1.0) | AB16: =AB15*1
A37: TOTAL REQUIREMENT: | H37: =AB16 | O37: GSY
B40: FC 2-000-05N Citation (Apex Omega Sec.5.5)
B41: FC 2-000-05N 800 Series; version date 2025-03-31
B42: Source PDF: fc_2_000_05n_800series_03_31_2025.pdf
B43: Pages: [59]
B44: Engineering-study CCN per NAVFAC doctrine; 1 narrative section(s) captured
B45: e.g. 85121-1: DEFINITION. An unpaved surface for parking and/or staging private

Sheet 87210
A1: BASIC FACILITY REQUIREMENTS WORKSHEET
A3: Installation: | F3: MCB CAMP BUTLER | M3: Tenant: | R3: CLB 4
A4: Installation UIC: | F4: M67400 | M4: Tenant UIC: | R4: M29030 | Y4: Planning Area: SW
A5: CCN: | C5: 872 10 | M5: Nomenclature: | R5: SECURTY/PERIMTR FENCE/WALL
A6: SPACE REQUIREMENT ANALYSIS , CCN 872 10 , FC 2-000-05N (Series 100, 11 Feb 2026)
A7: SECURTY/PERIMTR FENCE/WALL (Loading driver: Station Security and Perimeter Fencing (LF); FAC 8721; standard 7-ft chain link with 1.5-ft outriggers and 3 strands BB; min 50-150 ft from buildings/critical supplies; SRC I/II ammo fence per DoDM 5100.76 + UFC 4-022-03; CLB-4 placeholder 2000 LF pending compound perimeter survey) | V7: Factor | Y7: Count | AB7: LF
A8: Primary loading row | V8: 1 | Y8: 2000 | AB8: =V8*Y8*1.0
AB9: =V9*Y9*1.0
AB10: =V10*Y10*1.0
AB11: =V11*Y11*1.0
AB12: =V12*Y12*1.0
AB13: =V13*Y13*1.0
A15: Subtotal NSF | AB15: =SUM(AB8:AF13)
A16: Net to Gross multiplier (NTG = 1.0) | AB16: =AB15*1
A37: TOTAL REQUIREMENT: | H37: =AB16 | O37: LF
B40: FC 2-000-05N Citation (Apex Omega Sec.5.5)
B41: FC 2-000-05N 800 Series; version date 2025-03-31
B42: Source PDF: fc_2_000_05n_800series_03_31_2025.pdf
B43: Pages: [70, 71, 72]
B44: Table 87210-1 (); loading driver: TBD
B45: Magazines storing SRC I & II A&E | Restricted Areas — as defined in DoDM 5100.76 | Fence fabric shall be chain link, i.e., galvanized, aluminized, or plastic- coated woven steel, 2-inch square mesh made from 9- gauge diameter wire, excluding coating that meets Federal Specification RR-F-191K. | Refer to DoDM 5100.76
B46: Non-metallic Security Fence Requirement | Where restrictions of visibility into activity is desired. | Wooden Security fence | Refer to OPNAVINST 5530.14E
B47: At radio direction-finder structures. | Wooden Security fence
B48: Where chain link materials are not available. | Wooden Security fence
B49: Protection of sports facilities, users and spectators | Athletic courts. | Chain link. | 10-12 | --
B50: Swimming pools. | Chain link or decorative wood. | 6 | --
B51: Playgrounds. | Chain link or decorative wood. | 5 | --
... B54: page_72_table_2 (); loading driver: TBD

Sheet 87250
A1: BASIC FACILITY REQUIREMENTS WORKSHEET
A3: Installation: | F3: MCB CAMP BUTLER | M3: Tenant: | R3: CLB 4
A4: Installation UIC: | F4: M67400 | M4: Tenant UIC: | R4: M29030 | Y4: Planning Area: SW
A5: CCN: | C5: 872 50 | M5: Nomenclature: | R5: ENTRY GATE
A6: SPACE REQUIREMENT ANALYSIS , CCN 872 50 , FC 2-000-05N (Series 100, 11 Feb 2026)
A7: ENTRY GATE (Loading driver: Entry Gate (LF); FAC 8721; CCN added Jan 2024; CLB-4 default 30 LF for 1-2 main gates pending site survey) | V7: Factor | Y7: Count | AB7: LF
A8: Primary loading row | V8: 1 | Y8: 30 | AB8: =V8*Y8*1.0
AB9: =V9*Y9*1.0
AB10: =V10*Y10*1.0
AB11: =V11*Y11*1.0
AB12: =V12*Y12*1.0
AB13: =V13*Y13*1.0
A15: Subtotal NSF | AB15: =SUM(AB8:AF13)
A16: Net to Gross multiplier (NTG = 1.0) | AB16: =AB15*1
A37: TOTAL REQUIREMENT: | H37: =AB16 | O37: LF
B40: FC 2-000-05N Citation (Apex Omega Sec.5.5)
B41: FC 2-000-05N 800 Series; version date 2025-03-31
B42: Source PDF: fc_2_000_05n_800series_03_31_2025.pdf
B43: Pages: [73]
B44: Engineering-study CCN per NAVFAC doctrine; 1 narrative section(s) captured
B45: e.g. 87250-1: ENTRY GATE. An entry gate is the frame, gate, or other apparatus that

Sheet 87230
A1: BASIC FACILITY REQUIREMENTS WORKSHEET
A3: Installation: | F3: MCB CAMP BUTLER | M3: Tenant: | R3: CLB 4
A4: Installation UIC: | F4: M67400 | M4: Tenant UIC: | R4: M29030 | Y4: Planning Area: SW
A5: CCN: | C5: 872 30 | M5: Nomenclature: | R5: MECH SEC BARRICADE
A6: SPACE REQUIREMENT ANALYSIS , CCN 872 30 , FC 2-000-05N (Series 100, 11 Feb 2026)
A7: MECH SEC BARRICADE (Loading driver: Mechanical Security Barricade (EA); FAC 1458; drop arm barriers at gates; CLB-4 default 2 EA (one per gate)) | V7: Factor | Y7: Count | AB7: EA
A8: Primary loading row | V8: 1 | Y8: 2 | AB8: =V8*Y8*1.0
AB9: =V9*Y9*1.0
AB10: =V10*Y10*1.0
AB11: =V11*Y11*1.0
AB12: =V12*Y12*1.0
AB13: =V13*Y13*1.0
A15: Subtotal NSF | AB15: =SUM(AB8:AF13)
A16: Net to Gross multiplier (NTG = 1.0) | AB16: =AB15*1
A37: TOTAL REQUIREMENT: | H37: =AB16 | O37: EA
B40: FC 2-000-05N Citation (Apex Omega Sec.5.5)
B41: FC 2-000-05N 800 Series; version date 2025-03-31
B42: Source PDF: fc_2_000_05n_800series_03_31_2025.pdf
B43: Pages: [73]
B44: Engineering-study CCN per NAVFAC doctrine; 2 narrative section(s) captured
B45: e.g. 87230-1: DEFINITION. Mechanically operated barricade consisting of pop-up

Sheet 83143
A1: BASIC FACILITY REQUIREMENTS WORKSHEET
A3: Installation: | F3: MCB CAMP BUTLER | M3: Tenant: | R3: CLB 4
A4: Installation UIC: | F4: M67400 | M4: Tenant UIC: | R4: M29030 | Y4: Planning Area: SW
A5: CCN: | C5: 831 43 | M5: Nomenclature: | R5: HAZ WASTE BLDG
A6: SPACE REQUIREMENT ANALYSIS , CCN 831 43 , FC 2-000-05N (Series 100, 11 Feb 2026)
A7: HAZ WASTE BLDG (Loading driver: Hazardous Waste Storage Building (SF); FAC 4423; 150-meter buffer from inhabited areas, ammo, or POL stores; short-term <90 days vs long-term >90 days; CLB-4 placeholder 400 SF for unit HAZMAT point) | V7: Factor | Y7: Count | AB7: GSF
A8: Primary loading row | V8: 1 | Y8: 400 | AB8: =V8*Y8*1.0
AB9: =V9*Y9*1.0
AB10: =V10*Y10*1.0
AB11: =V11*Y11*1.0
AB12: =V12*Y12*1.0
AB13: =V13*Y13*1.0
A15: Subtotal NSF | AB15: =SUM(AB8:AF13)
A16: Net to Gross multiplier (NTG = 1.0) | AB16: =AB15*1
A37: TOTAL REQUIREMENT: | H37: =AB16 | O37: GSF
B40: FC 2-000-05N Citation (Apex Omega Sec.5.5)
B41: FC 2-000-05N 800 Series; version date 2025-03-31
B42: Source PDF: fc_2_000_05n_800series_03_31_2025.pdf
B43: Pages: [42]
B44: Engineering-study CCN per NAVFAC doctrine; 1 narrative section(s) captured
B45: e.g. 83143-1: DEFINITION. Use this category code for facilities that are buildings used

Sheet 83141
A1: BASIC FACILITY REQUIREMENTS WORKSHEET
A3: Installation: | F3: MCB CAMP BUTLER | M3: Tenant: | R3: CLB 4
A4: Installation UIC: | F4: M67400 | M4: Tenant UIC: | R4: M29030 | Y4: Planning Area: SW
A5: CCN: | C5: 831 41 | M5: Nomenclature: | R5: HAZARD WSTE STOR & TRANSFR
A6: SPACE REQUIREMENT ANALYSIS , CCN 831 41 , FC 2-000-05N (Series 100, 11 Feb 2026)
A7: HAZARD WSTE STOR & TRANSFR (Loading driver: Hazardous Waste Storage and Transfer Facility (EA); FAC 8926; non-building structures; same 150-meter buffer rule; CLB-4 default 1 EA) | V7: Factor | Y7: Count | AB7: GSF
A8: Primary loading row | V8: 1 | Y8: 1 | AB8: =V8*Y8*1.0
AB9: =V9*Y9*1.0
AB10: =V10*Y10*1.0
AB11: =V11*Y11*1.0
AB12: =V12*Y12*1.0
AB13: =V13*Y13*1.0
A15: Subtotal NSF | AB15: =SUM(AB8:AF13)
A16: Net to Gross multiplier (NTG = 1.0) | AB16: =AB15*1
A37: TOTAL REQUIREMENT: | H37: =AB16 | O37: GSF
B40: FC 2-000-05N Citation (Apex Omega Sec.5.5)
B41: FC 2-000-05N 800 Series; version date 2025-03-31
B42: Source PDF: fc_2_000_05n_800series_03_31_2025.pdf
B43: Pages: [40]
B44: Engineering-study CCN per NAVFAC doctrine; 3 narrative section(s) captured
B45: e.g. 83141-1: DEFINITION. Use this category code for facilities that are structures (non-

Sheet 81160
A1: BASIC FACILITY REQUIREMENTS WORKSHEET
A3: Installation: | F3: MCB CAMP BUTLER | M3: Tenant: | R3: CLB 4
A4: Installation UIC: | F4: M67400 | M4: Tenant UIC: | R4: M29030 | Y4: Planning Area: SW
A5: CCN: | C5: 811 60 | M5: Nomenclature: | R5: STANDBY GENERATOR PLANT
A6: SPACE REQUIREMENT ANALYSIS , CCN 811 60 , FC 2-000-05N (Series 100, 11 Feb 2026)
A7: STANDBY GENERATOR PLANT (Loading driver: Standby Generator Plant (KW); FAC 8112; mission-essential standby power; CLB-4 placeholder 150 KW pending engineering load study) | V7: Factor | Y7: Count | AB7: KW
A8: Primary loading row | V8: 1 | Y8: 150 | AB8: =V8*Y8*1.0
AB9: =V9*Y9*1.0
AB10: =V10*Y10*1.0
AB11: =V11*Y11*1.0
AB12: =V12*Y12*1.0
AB13: =V13*Y13*1.0
A15: Subtotal NSF | AB15: =SUM(AB8:AF13)
A16: Net to Gross multiplier (NTG = 1.0) | AB16: =AB15*1
A37: TOTAL REQUIREMENT: | H37: =AB16 | O37: KW
B40: FC 2-000-05N Citation (Apex Omega Sec.5.5)
B41: FC 2-000-05N 800 Series; version date 2025-03-31
B42: Source PDF: fc_2_000_05n_800series_03_31_2025.pdf
B43: Pages: [17]
B44: Engineering-study CCN per NAVFAC doctrine; 1 narrative section(s) captured
B45: e.g. 81160-1: DEFINITION. Standby generator plants include all necessary equipment
B46: UoM source: CCN_VOCABULARY.json (Appendix A 2019-06-27); Series PDF heading omitted UoM, ratifier should verify against current Series text

Sheet 88010
A1: BASIC FACILITY REQUIREMENTS WORKSHEET
A3: Installation: | F3: MCB CAMP BUTLER | M3: Tenant: | R3: CLB 4
A4: Installation UIC: | F4: M67400 | M4: Tenant UIC: | R4: M29030 | Y4: Planning Area: SW
A5: CCN: | C5: 880 10 | M5: Nomenclature: | R5: FIRE ALARM COMM LINES
A6: SPACE REQUIREMENT ANALYSIS , CCN 880 10 , FC 2-000-05N (Series 100, 11 Feb 2026)
A7: FIRE ALARM COMM LINES (Loading driver: Fire Alarm System (MI); FAC 1351; linear miles of fire-alarm wiring across CLB-4 compound; placeholder 1 MI pending site survey) | V7: Factor | Y7: Count | AB7: MI
A8: Primary loading row | V8: 1 | Y8: 1 | AB8: =V8*Y8*1.0
AB9: =V9*Y9*1.0
AB10: =V10*Y10*1.0
AB11: =V11*Y11*1.0
AB12: =V12*Y12*1.0
AB13: =V13*Y13*1.0
A15: Subtotal NSF | AB15: =SUM(AB8:AF13)
A16: Net to Gross multiplier (NTG = 1.0) | AB16: =AB15*1
A37: TOTAL REQUIREMENT: | H37: =AB16 | O37: MI
B40: FC 2-000-05N Citation (Apex Omega Sec.5.5)
B41: FC 2-000-05N 800 Series; version date 2025-03-31
B42: Source PDF: fc_2_000_05n_800series_03_31_2025.pdf
B43: Pages: [74]
B44: Engineering-study CCN per NAVFAC doctrine; 3 narrative section(s) captured
B45: e.g. 88010-1: FIRE ALARM SYSTEM. Fire alarm systems are of two general types:
B46: UoM source: CCN_VOCABULARY.json (Appendix A 2019-06-27); Series PDF heading omitted UoM, ratifier should verify against current Series text

Sheet 85235
A1: BASIC FACILITY REQUIREMENTS WORKSHEET
A3: Installation: | F3: MCB CAMP BUTLER | M3: Tenant: | R3: CLB 4
A4: Installation UIC: | F4: M67400 | M4: Tenant UIC: | R4: M29030 | Y4: Planning Area: SW
A5: CCN: | C5: 852 35 | M5: Nomenclature: | R5: OTHER PAVED AREA
A6: SPACE REQUIREMENT ANALYSIS , CCN 852 35 , FC 2-000-05N (Series 100, 11 Feb 2026)
A7: OTHER PAVED AREA (Loading driver: Other Paved Areas Not in 100/400 Series (SY); FAC 8526; miscellaneous hardstand; CLB-4 placeholder 1000 SY) | V7: Factor | Y7: Count | AB7: GSY
A8: Primary loading row | V8: 1 | Y8: 1000 | AB8: =V8*Y8*1.0
AB9: =V9*Y9*1.0
AB10: =V10*Y10*1.0
AB11: =V11*Y11*1.0
AB12: =V12*Y12*1.0
AB13: =V13*Y13*1.0
A15: Subtotal NSF | AB15: =SUM(AB8:AF13)
A16: Net to Gross multiplier (NTG = 1.0) | AB16: =AB15*1
A37: TOTAL REQUIREMENT: | H37: =AB16 | O37: GSY
B40: FC 2-000-05N Citation (Apex Omega Sec.5.5)
B41: FC 2-000-05N 800 Series; version date 2025-03-31
B42: Source PDF: fc_2_000_05n_800series_03_31_2025.pdf
B43: Pages: [9, 64]
B44: Engineering-study CCN per NAVFAC doctrine; 1 narrative section(s) captured
B45: e.g. 85235-1: OTHER PAVED AREAS NOT CODED IN THE 100 OR 400 SERIES.

Sheet 85240
A1: BASIC FACILITY REQUIREMENTS WORKSHEET
A3: Installation: | F3: MCB CAMP BUTLER | M3: Tenant: | R3: CLB 4
A4: Installation UIC: | F4: M67400 | M4: Tenant UIC: | R4: M29030 | Y4: Planning Area: SW
A5: CCN: | C5: 852 40 | M5: Nomenclature: | R5: MISC OPEN STRG/LAYDOWN
A6: SPACE REQUIREMENT ANALYSIS , CCN 852 40 , FC 2-000-05N (Series 100, 11 Feb 2026)
A7: MISC OPEN STRG/LAYDOWN (Loading driver: Misc Open Storage/Laydown Area Paved (SY); FAC 8526; PW open storage allowances per Table 85240-1; CLB-4 placeholder 2000 SY pending shop-type breakdown) | V7: Factor | Y7: Count | AB7: GSY
A8: Primary loading row | V8: 1 | Y8: 2000 | AB8: =V8*Y8*1.0
AB9: =V9*Y9*1.0
AB10: =V10*Y10*1.0
AB11: =V11*Y11*1.0
AB12: =V12*Y12*1.0
AB13: =V13*Y13*1.0
A15: Subtotal NSF | AB15: =SUM(AB8:AF13)
A16: Net to Gross multiplier (NTG = 1.0) | AB16: =AB15*1
A37: TOTAL REQUIREMENT: | H37: =AB16 | O37: GSY
B40: FC 2-000-05N Citation (Apex Omega Sec.5.5)
B41: FC 2-000-05N 800 Series; version date 2025-03-31
B42: Source PDF: fc_2_000_05n_800series_03_31_2025.pdf
B43: Pages: [9, 10, 11, 12, 65]
B44: page_12_table_1 (); loading driver: TBD
B45: 130 | Communication & Navigational Aid | SF | 13, 5
B46: Airfield Lighting | LF | 6
B47: 140 | Land Operations Facilities | SF | 7.5
B48: 150 | Waterfront Operational Facilities | SF FB | 5 5 x 103
B49: 170 | Training Facilities | SF | 7.5
B50: 210 | Maintenance. Shops & Facilities | SF | 7.5
B51: 220 | Production Buildings. & Plants | SF | 7.5
... B57: F | 1,180
